2025-08-14 16:02:07,872 - INFO - ==================================================
2025-08-14 16:02:07,872 - INFO - Instagram Telegram Bot Server
2025-08-14 16:02:07,872 - INFO - ==================================================
2025-08-14 16:02:07,944 - INFO - âœ… All dependencies are available
2025-08-14 16:02:07,944 - INFO - ðŸš€ Starting Instagram Telegram Bot...
2025-08-14 16:02:07,944 - INFO - ðŸ“± Bot is starting...
2025-08-14 16:02:07,976 - INFO - âœ… Bot started successfully!
2025-08-14 16:02:07,976 - INFO - ðŸ¤– Bot is now running and listening for messages...
2025-08-14 16:02:07,976 - INFO - ðŸ“‹ Use /start in Telegram to begin
2025-08-14 16:02:08,230 - ERROR - Infinity polling exception: A request to the Telegram API was unsuccessful. Error code: 401. Description: Unauthorized
2025-08-14 16:02:08,232 - ERROR - Exception traceback:
Traceback (most recent call last):
  File "/workspace/venv/lib/python3.13/site-packages/telebot/__init__.py", line 1110, in infinity_polling
    self.polling(non_stop=True, timeout=timeout, long_polling_timeout=long_polling_timeout,
    ~~~~~~~~~~~~^^^^^^^^^^^^^^^^^^^^^^^^^^^^^^^^^^^^^^^^^^^^^^^^^^^^^^^^^^^^^^^^^^^^^^^^^^^
                 logger_level=logger_level, allowed_updates=allowed_updates, restart_on_change=False,
                 ^^^^^^^^^^^^^^^^^^^^^^^^^^^^^^^^^^^^^^^^^^^^^^^^^^^^^^^^^^^^^^^^^^^^^^^^^^^^^^^^^^^^
                 *args, **kwargs)
                 ^^^^^^^^^^^^^^^^
  File "/workspace/venv/lib/python3.13/site-packages/telebot/__init__.py", line 1195, in polling
    logger.info('Starting your bot with username: [@%s]', self.user.username)
                                                          ^^^^^^^^^
  File "/workspace/venv/lib/python3.13/site-packages/telebot/__init__.py", line 306, in user
    self._user = self.get_me()
                 ~~~~~~~~~~~^^
  File "/workspace/venv/lib/python3.13/site-packages/telebot/__init__.py", line 1382, in get_me
    apihelper.get_me(self.token)
    ~~~~~~~~~~~~~~~~^^^^^^^^^^^^
  File "/workspace/venv/lib/python3.13/site-packages/telebot/apihelper.py", line 202, in get_me
    return _make_request(token, method_url)
  File "/workspace/venv/lib/python3.13/site-packages/telebot/apihelper.py", line 168, in _make_request
    json_result = _check_result(method_name, result)
  File "/workspace/venv/lib/python3.13/site-packages/telebot/apihelper.py", line 195, in _check_result
    raise ApiTelegramException(method_name, result, result_json)
telebot.apihelper.ApiTelegramException: A request to the Telegram API was unsuccessful. Error code: 401. Description: Unauthorized

2025-08-14 16:02:11,316 - ERROR - Infinity polling exception: A request to the Telegram API was unsuccessful. Error code: 401. Description: Unauthorized
2025-08-14 16:02:11,316 - ERROR - Exception traceback:
Traceback (most recent call last):
  File "/workspace/venv/lib/python3.13/site-packages/telebot/__init__.py", line 1110, in infinity_polling
    self.polling(non_stop=True, timeout=timeout, long_polling_timeout=long_polling_timeout,
    ~~~~~~~~~~~~^^^^^^^^^^^^^^^^^^^^^^^^^^^^^^^^^^^^^^^^^^^^^^^^^^^^^^^^^^^^^^^^^^^^^^^^^^^
                 logger_level=logger_level, allowed_updates=allowed_updates, restart_on_change=False,
                 ^^^^^^^^^^^^^^^^^^^^^^^^^^^^^^^^^^^^^^^^^^^^^^^^^^^^^^^^^^^^^^^^^^^^^^^^^^^^^^^^^^^^
                 *args, **kwargs)
                 ^^^^^^^^^^^^^^^^
  File "/workspace/venv/lib/python3.13/site-packages/telebot/__init__.py", line 1195, in polling
    logger.info('Starting your bot with username: [@%s]', self.user.username)
                                                          ^^^^^^^^^
  File "/workspace/venv/lib/python3.13/site-packages/telebot/__init__.py", line 306, in user
    self._user = self.get_me()
                 ~~~~~~~~~~~^^
  File "/workspace/venv/lib/python3.13/site-packages/telebot/__init__.py", line 1382, in get_me
    apihelper.get_me(self.token)
    ~~~~~~~~~~~~~~~~^^^^^^^^^^^^
  File "/workspace/venv/lib/python3.13/site-packages/telebot/apihelper.py", line 202, in get_me
    return _make_request(token, method_url)
  File "/workspace/venv/lib/python3.13/site-packages/telebot/apihelper.py", line 168, in _make_request
    json_result = _check_result(method_name, result)
  File "/workspace/venv/lib/python3.13/site-packages/telebot/apihelper.py", line 195, in _check_result
    raise ApiTelegramException(method_name, result, result_json)
telebot.apihelper.ApiTelegramException: A request to the Telegram API was unsuccessful. Error code: 401. Description: Unauthorized

2025-08-14 16:02:14,399 - ERROR - Infinity polling exception: A request to the Telegram API was unsuccessful. Error code: 401. Description: Unauthorized
2025-08-14 16:02:14,399 - ERROR - Exception traceback:
Traceback (most recent call last):
  File "/workspace/venv/lib/python3.13/site-packages/telebot/__init__.py", line 1110, in infinity_polling
    self.polling(non_stop=True, timeout=timeout, long_polling_timeout=long_polling_timeout,
    ~~~~~~~~~~~~^^^^^^^^^^^^^^^^^^^^^^^^^^^^^^^^^^^^^^^^^^^^^^^^^^^^^^^^^^^^^^^^^^^^^^^^^^^
                 logger_level=logger_level, allowed_updates=allowed_updates, restart_on_change=False,
                 ^^^^^^^^^^^^^^^^^^^^^^^^^^^^^^^^^^^^^^^^^^^^^^^^^^^^^^^^^^^^^^^^^^^^^^^^^^^^^^^^^^^^
                 *args, **kwargs)
                 ^^^^^^^^^^^^^^^^
  File "/workspace/venv/lib/python3.13/site-packages/telebot/__init__.py", line 1195, in polling
    logger.info('Starting your bot with username: [@%s]', self.user.username)
                                                          ^^^^^^^^^
  File "/workspace/venv/lib/python3.13/site-packages/telebot/__init__.py", line 306, in user
    self._user = self.get_me()
                 ~~~~~~~~~~~^^
  File "/workspace/venv/lib/python3.13/site-packages/telebot/__init__.py", line 1382, in get_me
    apihelper.get_me(self.token)
    ~~~~~~~~~~~~~~~~^^^^^^^^^^^^
  File "/workspace/venv/lib/python3.13/site-packages/telebot/apihelper.py", line 202, in get_me
    return _make_request(token, method_url)
  File "/workspace/venv/lib/python3.13/site-packages/telebot/apihelper.py", line 168, in _make_request
    json_result = _check_result(method_name, result)
  File "/workspace/venv/lib/python3.13/site-packages/telebot/apihelper.py", line 195, in _check_result
    raise ApiTelegramException(method_name, result, result_json)
telebot.apihelper.ApiTelegramException: A request to the Telegram API was unsuccessful. Error code: 401. Description: Unauthorized

2025-08-14 16:03:17,456 - INFO - ==================================================
2025-08-14 16:03:17,456 - INFO - Instagram Telegram Bot Server
2025-08-14 16:03:17,456 - INFO - ==================================================
2025-08-14 16:03:17,528 - INFO - âœ… All dependencies are available
2025-08-14 16:03:17,529 - INFO - ðŸš€ Starting Instagram Telegram Bot...
2025-08-14 16:03:17,529 - INFO - ðŸ“± Bot is starting...
2025-08-14 16:03:17,560 - INFO - âœ… Bot started successfully!
2025-08-14 16:03:17,560 - INFO - ðŸ¤– Bot is now running and listening for messages...
2025-08-14 16:03:17,560 - INFO - ðŸ“‹ Use /start in Telegram to begin
2025-08-14 16:03:17,820 - ERROR - Infinity polling exception: A request to the Telegram API was unsuccessful. Error code: 401. Description: Unauthorized
2025-08-14 16:03:17,823 - ERROR - Exception traceback:
Traceback (most recent call last):
  File "/workspace/venv/lib/python3.13/site-packages/telebot/__init__.py", line 1110, in infinity_polling
    self.polling(non_stop=True, timeout=timeout, long_polling_timeout=long_polling_timeout,
    ~~~~~~~~~~~~^^^^^^^^^^^^^^^^^^^^^^^^^^^^^^^^^^^^^^^^^^^^^^^^^^^^^^^^^^^^^^^^^^^^^^^^^^^
                 logger_level=logger_level, allowed_updates=allowed_updates, restart_on_change=False,
                 ^^^^^^^^^^^^^^^^^^^^^^^^^^^^^^^^^^^^^^^^^^^^^^^^^^^^^^^^^^^^^^^^^^^^^^^^^^^^^^^^^^^^
                 *args, **kwargs)
                 ^^^^^^^^^^^^^^^^
  File "/workspace/venv/lib/python3.13/site-packages/telebot/__init__.py", line 1195, in polling
    logger.info('Starting your bot with username: [@%s]', self.user.username)
                                                          ^^^^^^^^^
  File "/workspace/venv/lib/python3.13/site-packages/telebot/__init__.py", line 306, in user
    self._user = self.get_me()
                 ~~~~~~~~~~~^^
  File "/workspace/venv/lib/python3.13/site-packages/telebot/__init__.py", line 1382, in get_me
    apihelper.get_me(self.token)
    ~~~~~~~~~~~~~~~~^^^^^^^^^^^^
  File "/workspace/venv/lib/python3.13/site-packages/telebot/apihelper.py", line 202, in get_me
    return _make_request(token, method_url)
  File "/workspace/venv/lib/python3.13/site-packages/telebot/apihelper.py", line 168, in _make_request
    json_result = _check_result(method_name, result)
  File "/workspace/venv/lib/python3.13/site-packages/telebot/apihelper.py", line 195, in _check_result
    raise ApiTelegramException(method_name, result, result_json)
telebot.apihelper.ApiTelegramException: A request to the Telegram API was unsuccessful. Error code: 401. Description: Unauthorized

2025-08-14 16:03:20,908 - ERROR - Infinity polling exception: A request to the Telegram API was unsuccessful. Error code: 401. Description: Unauthorized
2025-08-14 16:03:20,909 - ERROR - Exception traceback:
Traceback (most recent call last):
  File "/workspace/venv/lib/python3.13/site-packages/telebot/__init__.py", line 1110, in infinity_polling
    self.polling(non_stop=True, timeout=timeout, long_polling_timeout=long_polling_timeout,
    ~~~~~~~~~~~~^^^^^^^^^^^^^^^^^^^^^^^^^^^^^^^^^^^^^^^^^^^^^^^^^^^^^^^^^^^^^^^^^^^^^^^^^^^
                 logger_level=logger_level, allowed_updates=allowed_updates, restart_on_change=False,
                 ^^^^^^^^^^^^^^^^^^^^^^^^^^^^^^^^^^^^^^^^^^^^^^^^^^^^^^^^^^^^^^^^^^^^^^^^^^^^^^^^^^^^
                 *args, **kwargs)
                 ^^^^^^^^^^^^^^^^
  File "/workspace/venv/lib/python3.13/site-packages/telebot/__init__.py", line 1195, in polling
    logger.info('Starting your bot with username: [@%s]', self.user.username)
                                                          ^^^^^^^^^
  File "/workspace/venv/lib/python3.13/site-packages/telebot/__init__.py", line 306, in user
    self._user = self.get_me()
                 ~~~~~~~~~~~^^
  File "/workspace/venv/lib/python3.13/site-packages/telebot/__init__.py", line 1382, in get_me
    apihelper.get_me(self.token)
    ~~~~~~~~~~~~~~~~^^^^^^^^^^^^
  File "/workspace/venv/lib/python3.13/site-packages/telebot/apihelper.py", line 202, in get_me
    return _make_request(token, method_url)
  File "/workspace/venv/lib/python3.13/site-packages/telebot/apihelper.py", line 168, in _make_request
    json_result = _check_result(method_name, result)
  File "/workspace/venv/lib/python3.13/site-packages/telebot/apihelper.py", line 195, in _check_result
    raise ApiTelegramException(method_name, result, result_json)
telebot.apihelper.ApiTelegramException: A request to the Telegram API was unsuccessful. Error code: 401. Description: Unauthorized

2025-08-14 16:03:23,994 - ERROR - Infinity polling exception: A request to the Telegram API was unsuccessful. Error code: 401. Description: Unauthorized
2025-08-14 16:03:23,995 - ERROR - Exception traceback:
Traceback (most recent call last):
  File "/workspace/venv/lib/python3.13/site-packages/telebot/__init__.py", line 1110, in infinity_polling
    self.polling(non_stop=True, timeout=timeout, long_polling_timeout=long_polling_timeout,
    ~~~~~~~~~~~~^^^^^^^^^^^^^^^^^^^^^^^^^^^^^^^^^^^^^^^^^^^^^^^^^^^^^^^^^^^^^^^^^^^^^^^^^^^
                 logger_level=logger_level, allowed_updates=allowed_updates, restart_on_change=False,
                 ^^^^^^^^^^^^^^^^^^^^^^^^^^^^^^^^^^^^^^^^^^^^^^^^^^^^^^^^^^^^^^^^^^^^^^^^^^^^^^^^^^^^
                 *args, **kwargs)
                 ^^^^^^^^^^^^^^^^
  File "/workspace/venv/lib/python3.13/site-packages/telebot/__init__.py", line 1195, in polling
    logger.info('Starting your bot with username: [@%s]', self.user.username)
                                                          ^^^^^^^^^
  File "/workspace/venv/lib/python3.13/site-packages/telebot/__init__.py", line 306, in user
    self._user = self.get_me()
                 ~~~~~~~~~~~^^
  File "/workspace/venv/lib/python3.13/site-packages/telebot/__init__.py", line 1382, in get_me
    apihelper.get_me(self.token)
    ~~~~~~~~~~~~~~~~^^^^^^^^^^^^
  File "/workspace/venv/lib/python3.13/site-packages/telebot/apihelper.py", line 202, in get_me
    return _make_request(token, method_url)
  File "/workspace/venv/lib/python3.13/site-packages/telebot/apihelper.py", line 168, in _make_request
    json_result = _check_result(method_name, result)
  File "/workspace/venv/lib/python3.13/site-packages/telebot/apihelper.py", line 195, in _check_result
    raise ApiTelegramException(method_name, result, result_json)
telebot.apihelper.ApiTelegramException: A request to the Telegram API was unsuccessful. Error code: 401. Description: Unauthorized

2025-08-14 16:03:27,084 - ERROR - Infinity polling exception: A request to the Telegram API was unsuccessful. Error code: 401. Description: Unauthorized
2025-08-14 16:03:27,085 - ERROR - Exception traceback:
Traceback (most recent call last):
  File "/workspace/venv/lib/python3.13/site-packages/telebot/__init__.py", line 1110, in infinity_polling
    self.polling(non_stop=True, timeout=timeout, long_polling_timeout=long_polling_timeout,
    ~~~~~~~~~~~~^^^^^^^^^^^^^^^^^^^^^^^^^^^^^^^^^^^^^^^^^^^^^^^^^^^^^^^^^^^^^^^^^^^^^^^^^^^
                 logger_level=logger_level, allowed_updates=allowed_updates, restart_on_change=False,
                 ^^^^^^^^^^^^^^^^^^^^^^^^^^^^^^^^^^^^^^^^^^^^^^^^^^^^^^^^^^^^^^^^^^^^^^^^^^^^^^^^^^^^
                 *args, **kwargs)
                 ^^^^^^^^^^^^^^^^
  File "/workspace/venv/lib/python3.13/site-packages/telebot/__init__.py", line 1195, in polling
    logger.info('Starting your bot with username: [@%s]', self.user.username)
                                                          ^^^^^^^^^
  File "/workspace/venv/lib/python3.13/site-packages/telebot/__init__.py", line 306, in user
    self._user = self.get_me()
                 ~~~~~~~~~~~^^
  File "/workspace/venv/lib/python3.13/site-packages/telebot/__init__.py", line 1382, in get_me
    apihelper.get_me(self.token)
    ~~~~~~~~~~~~~~~~^^^^^^^^^^^^
  File "/workspace/venv/lib/python3.13/site-packages/telebot/apihelper.py", line 202, in get_me
    return _make_request(token, method_url)
  File "/workspace/venv/lib/python3.13/site-packages/telebot/apihelper.py", line 168, in _make_request
    json_result = _check_result(method_name, result)
  File "/workspace/venv/lib/python3.13/site-packages/telebot/apihelper.py", line 195, in _check_result
    raise ApiTelegramException(method_name, result, result_json)
telebot.apihelper.ApiTelegramException: A request to the Telegram API was unsuccessful. Error code: 401. Description: Unauthorized

2025-08-14 16:03:30,171 - ERROR - Infinity polling exception: A request to the Telegram API was unsuccessful. Error code: 401. Description: Unauthorized
2025-08-14 16:03:30,172 - ERROR - Exception traceback:
Traceback (most recent call last):
  File "/workspace/venv/lib/python3.13/site-packages/telebot/__init__.py", line 1110, in infinity_polling
    self.polling(non_stop=True, timeout=timeout, long_polling_timeout=long_polling_timeout,
    ~~~~~~~~~~~~^^^^^^^^^^^^^^^^^^^^^^^^^^^^^^^^^^^^^^^^^^^^^^^^^^^^^^^^^^^^^^^^^^^^^^^^^^^
                 logger_level=logger_level, allowed_updates=allowed_updates, restart_on_change=False,
                 ^^^^^^^^^^^^^^^^^^^^^^^^^^^^^^^^^^^^^^^^^^^^^^^^^^^^^^^^^^^^^^^^^^^^^^^^^^^^^^^^^^^^
                 *args, **kwargs)
                 ^^^^^^^^^^^^^^^^
  File "/workspace/venv/lib/python3.13/site-packages/telebot/__init__.py", line 1195, in polling
    logger.info('Starting your bot with username: [@%s]', self.user.username)
                                                          ^^^^^^^^^
  File "/workspace/venv/lib/python3.13/site-packages/telebot/__init__.py", line 306, in user
    self._user = self.get_me()
                 ~~~~~~~~~~~^^
  File "/workspace/venv/lib/python3.13/site-packages/telebot/__init__.py", line 1382, in get_me
    apihelper.get_me(self.token)
    ~~~~~~~~~~~~~~~~^^^^^^^^^^^^
  File "/workspace/venv/lib/python3.13/site-packages/telebot/apihelper.py", line 202, in get_me
    return _make_request(token, method_url)
  File "/workspace/venv/lib/python3.13/site-packages/telebot/apihelper.py", line 168, in _make_request
    json_result = _check_result(method_name, result)
  File "/workspace/venv/lib/python3.13/site-packages/telebot/apihelper.py", line 195, in _check_result
    raise ApiTelegramException(method_name, result, result_json)
telebot.apihelper.ApiTelegramException: A request to the Telegram API was unsuccessful. Error code: 401. Description: Unauthorized

2025-08-14 16:03:33,259 - ERROR - Infinity polling exception: A request to the Telegram API was unsuccessful. Error code: 401. Description: Unauthorized
2025-08-14 16:03:33,260 - ERROR - Exception traceback:
Traceback (most recent call last):
  File "/workspace/venv/lib/python3.13/site-packages/telebot/__init__.py", line 1110, in infinity_polling
    self.polling(non_stop=True, timeout=timeout, long_polling_timeout=long_polling_timeout,
    ~~~~~~~~~~~~^^^^^^^^^^^^^^^^^^^^^^^^^^^^^^^^^^^^^^^^^^^^^^^^^^^^^^^^^^^^^^^^^^^^^^^^^^^
                 logger_level=logger_level, allowed_updates=allowed_updates, restart_on_change=False,
                 ^^^^^^^^^^^^^^^^^^^^^^^^^^^^^^^^^^^^^^^^^^^^^^^^^^^^^^^^^^^^^^^^^^^^^^^^^^^^^^^^^^^^
                 *args, **kwargs)
                 ^^^^^^^^^^^^^^^^
  File "/workspace/venv/lib/python3.13/site-packages/telebot/__init__.py", line 1195, in polling
    logger.info('Starting your bot with username: [@%s]', self.user.username)
                                                          ^^^^^^^^^
  File "/workspace/venv/lib/python3.13/site-packages/telebot/__init__.py", line 306, in user
    self._user = self.get_me()
                 ~~~~~~~~~~~^^
  File "/workspace/venv/lib/python3.13/site-packages/telebot/__init__.py", line 1382, in get_me
    apihelper.get_me(self.token)
    ~~~~~~~~~~~~~~~~^^^^^^^^^^^^
  File "/workspace/venv/lib/python3.13/site-packages/telebot/apihelper.py", line 202, in get_me
    return _make_request(token, method_url)
  File "/workspace/venv/lib/python3.13/site-packages/telebot/apihelper.py", line 168, in _make_request
    json_result = _check_result(method_name, result)
  File "/workspace/venv/lib/python3.13/site-packages/telebot/apihelper.py", line 195, in _check_result
    raise ApiTelegramException(method_name, result, result_json)
telebot.apihelper.ApiTelegramException: A request to the Telegram API was unsuccessful. Error code: 401. Description: Unauthorized

2025-08-14 16:03:36,345 - ERROR - Infinity polling exception: A request to the Telegram API was unsuccessful. Error code: 401. Description: Unauthorized
2025-08-14 16:03:36,346 - ERROR - Exception traceback:
Traceback (most recent call last):
  File "/workspace/venv/lib/python3.13/site-packages/telebot/__init__.py", line 1110, in infinity_polling
    self.polling(non_stop=True, timeout=timeout, long_polling_timeout=long_polling_timeout,
    ~~~~~~~~~~~~^^^^^^^^^^^^^^^^^^^^^^^^^^^^^^^^^^^^^^^^^^^^^^^^^^^^^^^^^^^^^^^^^^^^^^^^^^^
                 logger_level=logger_level, allowed_updates=allowed_updates, restart_on_change=False,
                 ^^^^^^^^^^^^^^^^^^^^^^^^^^^^^^^^^^^^^^^^^^^^^^^^^^^^^^^^^^^^^^^^^^^^^^^^^^^^^^^^^^^^
                 *args, **kwargs)
                 ^^^^^^^^^^^^^^^^
  File "/workspace/venv/lib/python3.13/site-packages/telebot/__init__.py", line 1195, in polling
    logger.info('Starting your bot with username: [@%s]', self.user.username)
                                                          ^^^^^^^^^
  File "/workspace/venv/lib/python3.13/site-packages/telebot/__init__.py", line 306, in user
    self._user = self.get_me()
                 ~~~~~~~~~~~^^
  File "/workspace/venv/lib/python3.13/site-packages/telebot/__init__.py", line 1382, in get_me
    apihelper.get_me(self.token)
    ~~~~~~~~~~~~~~~~^^^^^^^^^^^^
  File "/workspace/venv/lib/python3.13/site-packages/telebot/apihelper.py", line 202, in get_me
    return _make_request(token, method_url)
  File "/workspace/venv/lib/python3.13/site-packages/telebot/apihelper.py", line 168, in _make_request
    json_result = _check_result(method_name, result)
  File "/workspace/venv/lib/python3.13/site-packages/telebot/apihelper.py", line 195, in _check_result
    raise ApiTelegramException(method_name, result, result_json)
telebot.apihelper.ApiTelegramException: A request to the Telegram API was unsuccessful. Error code: 401. Description: Unauthorized

2025-08-14 16:03:39,455 - ERROR - Infinity polling exception: A request to the Telegram API was unsuccessful. Error code: 401. Description: Unauthorized
2025-08-14 16:03:39,455 - ERROR - Exception traceback:
Traceback (most recent call last):
  File "/workspace/venv/lib/python3.13/site-packages/telebot/__init__.py", line 1110, in infinity_polling
    self.polling(non_stop=True, timeout=timeout, long_polling_timeout=long_polling_timeout,
    ~~~~~~~~~~~~^^^^^^^^^^^^^^^^^^^^^^^^^^^^^^^^^^^^^^^^^^^^^^^^^^^^^^^^^^^^^^^^^^^^^^^^^^^
                 logger_level=logger_level, allowed_updates=allowed_updates, restart_on_change=False,
                 ^^^^^^^^^^^^^^^^^^^^^^^^^^^^^^^^^^^^^^^^^^^^^^^^^^^^^^^^^^^^^^^^^^^^^^^^^^^^^^^^^^^^
                 *args, **kwargs)
                 ^^^^^^^^^^^^^^^^
  File "/workspace/venv/lib/python3.13/site-packages/telebot/__init__.py", line 1195, in polling
    logger.info('Starting your bot with username: [@%s]', self.user.username)
                                                          ^^^^^^^^^
  File "/workspace/venv/lib/python3.13/site-packages/telebot/__init__.py", line 306, in user
    self._user = self.get_me()
                 ~~~~~~~~~~~^^
  File "/workspace/venv/lib/python3.13/site-packages/telebot/__init__.py", line 1382, in get_me
    apihelper.get_me(self.token)
    ~~~~~~~~~~~~~~~~^^^^^^^^^^^^
  File "/workspace/venv/lib/python3.13/site-packages/telebot/apihelper.py", line 202, in get_me
    return _make_request(token, method_url)
  File "/workspace/venv/lib/python3.13/site-packages/telebot/apihelper.py", line 168, in _make_request
    json_result = _check_result(method_name, result)
  File "/workspace/venv/lib/python3.13/site-packages/telebot/apihelper.py", line 195, in _check_result
    raise ApiTelegramException(method_name, result, result_json)
telebot.apihelper.ApiTelegramException: A request to the Telegram API was unsuccessful. Error code: 401. Description: Unauthorized

2025-08-14 16:03:42,542 - ERROR - Infinity polling exception: A request to the Telegram API was unsuccessful. Error code: 401. Description: Unauthorized
2025-08-14 16:03:42,542 - ERROR - Exception traceback:
Traceback (most recent call last):
  File "/workspace/venv/lib/python3.13/site-packages/telebot/__init__.py", line 1110, in infinity_polling
    self.polling(non_stop=True, timeout=timeout, long_polling_timeout=long_polling_timeout,
    ~~~~~~~~~~~~^^^^^^^^^^^^^^^^^^^^^^^^^^^^^^^^^^^^^^^^^^^^^^^^^^^^^^^^^^^^^^^^^^^^^^^^^^^
                 logger_level=logger_level, allowed_updates=allowed_updates, restart_on_change=False,
                 ^^^^^^^^^^^^^^^^^^^^^^^^^^^^^^^^^^^^^^^^^^^^^^^^^^^^^^^^^^^^^^^^^^^^^^^^^^^^^^^^^^^^
                 *args, **kwargs)
                 ^^^^^^^^^^^^^^^^
  File "/workspace/venv/lib/python3.13/site-packages/telebot/__init__.py", line 1195, in polling
    logger.info('Starting your bot with username: [@%s]', self.user.username)
                                                          ^^^^^^^^^
  File "/workspace/venv/lib/python3.13/site-packages/telebot/__init__.py", line 306, in user
    self._user = self.get_me()
                 ~~~~~~~~~~~^^
  File "/workspace/venv/lib/python3.13/site-packages/telebot/__init__.py", line 1382, in get_me
    apihelper.get_me(self.token)
    ~~~~~~~~~~~~~~~~^^^^^^^^^^^^
  File "/workspace/venv/lib/python3.13/site-packages/telebot/apihelper.py", line 202, in get_me
    return _make_request(token, method_url)
  File "/workspace/venv/lib/python3.13/site-packages/telebot/apihelper.py", line 168, in _make_request
    json_result = _check_result(method_name, result)
  File "/workspace/venv/lib/python3.13/site-packages/telebot/apihelper.py", line 195, in _check_result
    raise ApiTelegramException(method_name, result, result_json)
telebot.apihelper.ApiTelegramException: A request to the Telegram API was unsuccessful. Error code: 401. Description: Unauthorized

2025-08-14 16:03:45,628 - ERROR - Infinity polling exception: A request to the Telegram API was unsuccessful. Error code: 401. Description: Unauthorized
2025-08-14 16:03:45,629 - ERROR - Exception traceback:
Traceback (most recent call last):
  File "/workspace/venv/lib/python3.13/site-packages/telebot/__init__.py", line 1110, in infinity_polling
    self.polling(non_stop=True, timeout=timeout, long_polling_timeout=long_polling_timeout,
    ~~~~~~~~~~~~^^^^^^^^^^^^^^^^^^^^^^^^^^^^^^^^^^^^^^^^^^^^^^^^^^^^^^^^^^^^^^^^^^^^^^^^^^^
                 logger_level=logger_level, allowed_updates=allowed_updates, restart_on_change=False,
                 ^^^^^^^^^^^^^^^^^^^^^^^^^^^^^^^^^^^^^^^^^^^^^^^^^^^^^^^^^^^^^^^^^^^^^^^^^^^^^^^^^^^^
                 *args, **kwargs)
                 ^^^^^^^^^^^^^^^^
  File "/workspace/venv/lib/python3.13/site-packages/telebot/__init__.py", line 1195, in polling
    logger.info('Starting your bot with username: [@%s]', self.user.username)
                                                          ^^^^^^^^^
  File "/workspace/venv/lib/python3.13/site-packages/telebot/__init__.py", line 306, in user
    self._user = self.get_me()
                 ~~~~~~~~~~~^^
  File "/workspace/venv/lib/python3.13/site-packages/telebot/__init__.py", line 1382, in get_me
    apihelper.get_me(self.token)
    ~~~~~~~~~~~~~~~~^^^^^^^^^^^^
  File "/workspace/venv/lib/python3.13/site-packages/telebot/apihelper.py", line 202, in get_me
    return _make_request(token, method_url)
  File "/workspace/venv/lib/python3.13/site-packages/telebot/apihelper.py", line 168, in _make_request
    json_result = _check_result(method_name, result)
  File "/workspace/venv/lib/python3.13/site-packages/telebot/apihelper.py", line 195, in _check_result
    raise ApiTelegramException(method_name, result, result_json)
telebot.apihelper.ApiTelegramException: A request to the Telegram API was unsuccessful. Error code: 401. Description: Unauthorized

2025-08-14 16:03:48,716 - ERROR - Infinity polling exception: A request to the Telegram API was unsuccessful. Error code: 401. Description: Unauthorized
2025-08-14 16:03:48,716 - ERROR - Exception traceback:
Traceback (most recent call last):
  File "/workspace/venv/lib/python3.13/site-packages/telebot/__init__.py", line 1110, in infinity_polling
    self.polling(non_stop=True, timeout=timeout, long_polling_timeout=long_polling_timeout,
    ~~~~~~~~~~~~^^^^^^^^^^^^^^^^^^^^^^^^^^^^^^^^^^^^^^^^^^^^^^^^^^^^^^^^^^^^^^^^^^^^^^^^^^^
                 logger_level=logger_level, allowed_updates=allowed_updates, restart_on_change=False,
                 ^^^^^^^^^^^^^^^^^^^^^^^^^^^^^^^^^^^^^^^^^^^^^^^^^^^^^^^^^^^^^^^^^^^^^^^^^^^^^^^^^^^^
                 *args, **kwargs)
                 ^^^^^^^^^^^^^^^^
  File "/workspace/venv/lib/python3.13/site-packages/telebot/__init__.py", line 1195, in polling
    logger.info('Starting your bot with username: [@%s]', self.user.username)
                                                          ^^^^^^^^^
  File "/workspace/venv/lib/python3.13/site-packages/telebot/__init__.py", line 306, in user
    self._user = self.get_me()
                 ~~~~~~~~~~~^^
  File "/workspace/venv/lib/python3.13/site-packages/telebot/__init__.py", line 1382, in get_me
    apihelper.get_me(self.token)
    ~~~~~~~~~~~~~~~~^^^^^^^^^^^^
  File "/workspace/venv/lib/python3.13/site-packages/telebot/apihelper.py", line 202, in get_me
    return _make_request(token, method_url)
  File "/workspace/venv/lib/python3.13/site-packages/telebot/apihelper.py", line 168, in _make_request
    json_result = _check_result(method_name, result)
  File "/workspace/venv/lib/python3.13/site-packages/telebot/apihelper.py", line 195, in _check_result
    raise ApiTelegramException(method_name, result, result_json)
telebot.apihelper.ApiTelegramException: A request to the Telegram API was unsuccessful. Error code: 401. Description: Unauthorized

2025-08-14 16:03:51,802 - ERROR - Infinity polling exception: A request to the Telegram API was unsuccessful. Error code: 401. Description: Unauthorized
2025-08-14 16:03:51,802 - ERROR - Exception traceback:
Traceback (most recent call last):
  File "/workspace/venv/lib/python3.13/site-packages/telebot/__init__.py", line 1110, in infinity_polling
    self.polling(non_stop=True, timeout=timeout, long_polling_timeout=long_polling_timeout,
    ~~~~~~~~~~~~^^^^^^^^^^^^^^^^^^^^^^^^^^^^^^^^^^^^^^^^^^^^^^^^^^^^^^^^^^^^^^^^^^^^^^^^^^^
                 logger_level=logger_level, allowed_updates=allowed_updates, restart_on_change=False,
                 ^^^^^^^^^^^^^^^^^^^^^^^^^^^^^^^^^^^^^^^^^^^^^^^^^^^^^^^^^^^^^^^^^^^^^^^^^^^^^^^^^^^^
                 *args, **kwargs)
                 ^^^^^^^^^^^^^^^^
  File "/workspace/venv/lib/python3.13/site-packages/telebot/__init__.py", line 1195, in polling
    logger.info('Starting your bot with username: [@%s]', self.user.username)
                                                          ^^^^^^^^^
  File "/workspace/venv/lib/python3.13/site-packages/telebot/__init__.py", line 306, in user
    self._user = self.get_me()
                 ~~~~~~~~~~~^^
  File "/workspace/venv/lib/python3.13/site-packages/telebot/__init__.py", line 1382, in get_me
    apihelper.get_me(self.token)
    ~~~~~~~~~~~~~~~~^^^^^^^^^^^^
  File "/workspace/venv/lib/python3.13/site-packages/telebot/apihelper.py", line 202, in get_me
    return _make_request(token, method_url)
  File "/workspace/venv/lib/python3.13/site-packages/telebot/apihelper.py", line 168, in _make_request
    json_result = _check_result(method_name, result)
  File "/workspace/venv/lib/python3.13/site-packages/telebot/apihelper.py", line 195, in _check_result
    raise ApiTelegramException(method_name, result, result_json)
telebot.apihelper.ApiTelegramException: A request to the Telegram API was unsuccessful. Error code: 401. Description: Unauthorized

2025-08-14 16:03:54,888 - ERROR - Infinity polling exception: A request to the Telegram API was unsuccessful. Error code: 401. Description: Unauthorized
2025-08-14 16:03:54,889 - ERROR - Exception traceback:
Traceback (most recent call last):
  File "/workspace/venv/lib/python3.13/site-packages/telebot/__init__.py", line 1110, in infinity_polling
    self.polling(non_stop=True, timeout=timeout, long_polling_timeout=long_polling_timeout,
    ~~~~~~~~~~~~^^^^^^^^^^^^^^^^^^^^^^^^^^^^^^^^^^^^^^^^^^^^^^^^^^^^^^^^^^^^^^^^^^^^^^^^^^^
                 logger_level=logger_level, allowed_updates=allowed_updates, restart_on_change=False,
                 ^^^^^^^^^^^^^^^^^^^^^^^^^^^^^^^^^^^^^^^^^^^^^^^^^^^^^^^^^^^^^^^^^^^^^^^^^^^^^^^^^^^^
                 *args, **kwargs)
                 ^^^^^^^^^^^^^^^^
  File "/workspace/venv/lib/python3.13/site-packages/telebot/__init__.py", line 1195, in polling
    logger.info('Starting your bot with username: [@%s]', self.user.username)
                                                          ^^^^^^^^^
  File "/workspace/venv/lib/python3.13/site-packages/telebot/__init__.py", line 306, in user
    self._user = self.get_me()
                 ~~~~~~~~~~~^^
  File "/workspace/venv/lib/python3.13/site-packages/telebot/__init__.py", line 1382, in get_me
    apihelper.get_me(self.token)
    ~~~~~~~~~~~~~~~~^^^^^^^^^^^^
  File "/workspace/venv/lib/python3.13/site-packages/telebot/apihelper.py", line 202, in get_me
    return _make_request(token, method_url)
  File "/workspace/venv/lib/python3.13/site-packages/telebot/apihelper.py", line 168, in _make_request
    json_result = _check_result(method_name, result)
  File "/workspace/venv/lib/python3.13/site-packages/telebot/apihelper.py", line 195, in _check_result
    raise ApiTelegramException(method_name, result, result_json)
telebot.apihelper.ApiTelegramException: A request to the Telegram API was unsuccessful. Error code: 401. Description: Unauthorized

2025-08-14 16:03:57,974 - ERROR - Infinity polling exception: A request to the Telegram API was unsuccessful. Error code: 401. Description: Unauthorized
2025-08-14 16:03:57,975 - ERROR - Exception traceback:
Traceback (most recent call last):
  File "/workspace/venv/lib/python3.13/site-packages/telebot/__init__.py", line 1110, in infinity_polling
    self.polling(non_stop=True, timeout=timeout, long_polling_timeout=long_polling_timeout,
    ~~~~~~~~~~~~^^^^^^^^^^^^^^^^^^^^^^^^^^^^^^^^^^^^^^^^^^^^^^^^^^^^^^^^^^^^^^^^^^^^^^^^^^^
                 logger_level=logger_level, allowed_updates=allowed_updates, restart_on_change=False,
                 ^^^^^^^^^^^^^^^^^^^^^^^^^^^^^^^^^^^^^^^^^^^^^^^^^^^^^^^^^^^^^^^^^^^^^^^^^^^^^^^^^^^^
                 *args, **kwargs)
                 ^^^^^^^^^^^^^^^^
  File "/workspace/venv/lib/python3.13/site-packages/telebot/__init__.py", line 1195, in polling
    logger.info('Starting your bot with username: [@%s]', self.user.username)
                                                          ^^^^^^^^^
  File "/workspace/venv/lib/python3.13/site-packages/telebot/__init__.py", line 306, in user
    self._user = self.get_me()
                 ~~~~~~~~~~~^^
  File "/workspace/venv/lib/python3.13/site-packages/telebot/__init__.py", line 1382, in get_me
    apihelper.get_me(self.token)
    ~~~~~~~~~~~~~~~~^^^^^^^^^^^^
  File "/workspace/venv/lib/python3.13/site-packages/telebot/apihelper.py", line 202, in get_me
    return _make_request(token, method_url)
  File "/workspace/venv/lib/python3.13/site-packages/telebot/apihelper.py", line 168, in _make_request
    json_result = _check_result(method_name, result)
  File "/workspace/venv/lib/python3.13/site-packages/telebot/apihelper.py", line 195, in _check_result
    raise ApiTelegramException(method_name, result, result_json)
telebot.apihelper.ApiTelegramException: A request to the Telegram API was unsuccessful. Error code: 401. Description: Unauthorized

2025-08-14 16:04:01,061 - ERROR - Infinity polling exception: A request to the Telegram API was unsuccessful. Error code: 401. Description: Unauthorized
2025-08-14 16:04:01,061 - ERROR - Exception traceback:
Traceback (most recent call last):
  File "/workspace/venv/lib/python3.13/site-packages/telebot/__init__.py", line 1110, in infinity_polling
    self.polling(non_stop=True, timeout=timeout, long_polling_timeout=long_polling_timeout,
    ~~~~~~~~~~~~^^^^^^^^^^^^^^^^^^^^^^^^^^^^^^^^^^^^^^^^^^^^^^^^^^^^^^^^^^^^^^^^^^^^^^^^^^^
                 logger_level=logger_level, allowed_updates=allowed_updates, restart_on_change=False,
                 ^^^^^^^^^^^^^^^^^^^^^^^^^^^^^^^^^^^^^^^^^^^^^^^^^^^^^^^^^^^^^^^^^^^^^^^^^^^^^^^^^^^^
                 *args, **kwargs)
                 ^^^^^^^^^^^^^^^^
  File "/workspace/venv/lib/python3.13/site-packages/telebot/__init__.py", line 1195, in polling
    logger.info('Starting your bot with username: [@%s]', self.user.username)
                                                          ^^^^^^^^^
  File "/workspace/venv/lib/python3.13/site-packages/telebot/__init__.py", line 306, in user
    self._user = self.get_me()
                 ~~~~~~~~~~~^^
  File "/workspace/venv/lib/python3.13/site-packages/telebot/__init__.py", line 1382, in get_me
    apihelper.get_me(self.token)
    ~~~~~~~~~~~~~~~~^^^^^^^^^^^^
  File "/workspace/venv/lib/python3.13/site-packages/telebot/apihelper.py", line 202, in get_me
    return _make_request(token, method_url)
  File "/workspace/venv/lib/python3.13/site-packages/telebot/apihelper.py", line 168, in _make_request
    json_result = _check_result(method_name, result)
  File "/workspace/venv/lib/python3.13/site-packages/telebot/apihelper.py", line 195, in _check_result
    raise ApiTelegramException(method_name, result, result_json)
telebot.apihelper.ApiTelegramException: A request to the Telegram API was unsuccessful. Error code: 401. Description: Unauthorized

2025-08-14 16:04:04,147 - ERROR - Infinity polling exception: A request to the Telegram API was unsuccessful. Error code: 401. Description: Unauthorized
2025-08-14 16:04:04,147 - ERROR - Exception traceback:
Traceback (most recent call last):
  File "/workspace/venv/lib/python3.13/site-packages/telebot/__init__.py", line 1110, in infinity_polling
    self.polling(non_stop=True, timeout=timeout, long_polling_timeout=long_polling_timeout,
    ~~~~~~~~~~~~^^^^^^^^^^^^^^^^^^^^^^^^^^^^^^^^^^^^^^^^^^^^^^^^^^^^^^^^^^^^^^^^^^^^^^^^^^^
                 logger_level=logger_level, allowed_updates=allowed_updates, restart_on_change=False,
                 ^^^^^^^^^^^^^^^^^^^^^^^^^^^^^^^^^^^^^^^^^^^^^^^^^^^^^^^^^^^^^^^^^^^^^^^^^^^^^^^^^^^^
                 *args, **kwargs)
                 ^^^^^^^^^^^^^^^^
  File "/workspace/venv/lib/python3.13/site-packages/telebot/__init__.py", line 1195, in polling
    logger.info('Starting your bot with username: [@%s]', self.user.username)
                                                          ^^^^^^^^^
  File "/workspace/venv/lib/python3.13/site-packages/telebot/__init__.py", line 306, in user
    self._user = self.get_me()
                 ~~~~~~~~~~~^^
  File "/workspace/venv/lib/python3.13/site-packages/telebot/__init__.py", line 1382, in get_me
    apihelper.get_me(self.token)
    ~~~~~~~~~~~~~~~~^^^^^^^^^^^^
  File "/workspace/venv/lib/python3.13/site-packages/telebot/apihelper.py", line 202, in get_me
    return _make_request(token, method_url)
  File "/workspace/venv/lib/python3.13/site-packages/telebot/apihelper.py", line 168, in _make_request
    json_result = _check_result(method_name, result)
  File "/workspace/venv/lib/python3.13/site-packages/telebot/apihelper.py", line 195, in _check_result
    raise ApiTelegramException(method_name, result, result_json)
telebot.apihelper.ApiTelegramException: A request to the Telegram API was unsuccessful. Error code: 401. Description: Unauthorized

2025-08-14 16:04:07,233 - ERROR - Infinity polling exception: A request to the Telegram API was unsuccessful. Error code: 401. Description: Unauthorized
2025-08-14 16:04:07,234 - ERROR - Exception traceback:
Traceback (most recent call last):
  File "/workspace/venv/lib/python3.13/site-packages/telebot/__init__.py", line 1110, in infinity_polling
    self.polling(non_stop=True, timeout=timeout, long_polling_timeout=long_polling_timeout,
    ~~~~~~~~~~~~^^^^^^^^^^^^^^^^^^^^^^^^^^^^^^^^^^^^^^^^^^^^^^^^^^^^^^^^^^^^^^^^^^^^^^^^^^^
                 logger_level=logger_level, allowed_updates=allowed_updates, restart_on_change=False,
                 ^^^^^^^^^^^^^^^^^^^^^^^^^^^^^^^^^^^^^^^^^^^^^^^^^^^^^^^^^^^^^^^^^^^^^^^^^^^^^^^^^^^^
                 *args, **kwargs)
                 ^^^^^^^^^^^^^^^^
  File "/workspace/venv/lib/python3.13/site-packages/telebot/__init__.py", line 1195, in polling
    logger.info('Starting your bot with username: [@%s]', self.user.username)
                                                          ^^^^^^^^^
  File "/workspace/venv/lib/python3.13/site-packages/telebot/__init__.py", line 306, in user
    self._user = self.get_me()
                 ~~~~~~~~~~~^^
  File "/workspace/venv/lib/python3.13/site-packages/telebot/__init__.py", line 1382, in get_me
    apihelper.get_me(self.token)
    ~~~~~~~~~~~~~~~~^^^^^^^^^^^^
  File "/workspace/venv/lib/python3.13/site-packages/telebot/apihelper.py", line 202, in get_me
    return _make_request(token, method_url)
  File "/workspace/venv/lib/python3.13/site-packages/telebot/apihelper.py", line 168, in _make_request
    json_result = _check_result(method_name, result)
  File "/workspace/venv/lib/python3.13/site-packages/telebot/apihelper.py", line 195, in _check_result
    raise ApiTelegramException(method_name, result, result_json)
telebot.apihelper.ApiTelegramException: A request to the Telegram API was unsuccessful. Error code: 401. Description: Unauthorized

2025-08-14 16:04:10,319 - ERROR - Infinity polling exception: A request to the Telegram API was unsuccessful. Error code: 401. Description: Unauthorized
2025-08-14 16:04:10,320 - ERROR - Exception traceback:
Traceback (most recent call last):
  File "/workspace/venv/lib/python3.13/site-packages/telebot/__init__.py", line 1110, in infinity_polling
    self.polling(non_stop=True, timeout=timeout, long_polling_timeout=long_polling_timeout,
    ~~~~~~~~~~~~^^^^^^^^^^^^^^^^^^^^^^^^^^^^^^^^^^^^^^^^^^^^^^^^^^^^^^^^^^^^^^^^^^^^^^^^^^^
                 logger_level=logger_level, allowed_updates=allowed_updates, restart_on_change=False,
                 ^^^^^^^^^^^^^^^^^^^^^^^^^^^^^^^^^^^^^^^^^^^^^^^^^^^^^^^^^^^^^^^^^^^^^^^^^^^^^^^^^^^^
                 *args, **kwargs)
                 ^^^^^^^^^^^^^^^^
  File "/workspace/venv/lib/python3.13/site-packages/telebot/__init__.py", line 1195, in polling
    logger.info('Starting your bot with username: [@%s]', self.user.username)
                                                          ^^^^^^^^^
  File "/workspace/venv/lib/python3.13/site-packages/telebot/__init__.py", line 306, in user
    self._user = self.get_me()
                 ~~~~~~~~~~~^^
  File "/workspace/venv/lib/python3.13/site-packages/telebot/__init__.py", line 1382, in get_me
    apihelper.get_me(self.token)
    ~~~~~~~~~~~~~~~~^^^^^^^^^^^^
  File "/workspace/venv/lib/python3.13/site-packages/telebot/apihelper.py", line 202, in get_me
    return _make_request(token, method_url)
  File "/workspace/venv/lib/python3.13/site-packages/telebot/apihelper.py", line 168, in _make_request
    json_result = _check_result(method_name, result)
  File "/workspace/venv/lib/python3.13/site-packages/telebot/apihelper.py", line 195, in _check_result
    raise ApiTelegramException(method_name, result, result_json)
telebot.apihelper.ApiTelegramException: A request to the Telegram API was unsuccessful. Error code: 401. Description: Unauthorized

2025-08-14 16:04:13,405 - ERROR - Infinity polling exception: A request to the Telegram API was unsuccessful. Error code: 401. Description: Unauthorized
2025-08-14 16:04:13,406 - ERROR - Exception traceback:
Traceback (most recent call last):
  File "/workspace/venv/lib/python3.13/site-packages/telebot/__init__.py", line 1110, in infinity_polling
    self.polling(non_stop=True, timeout=timeout, long_polling_timeout=long_polling_timeout,
    ~~~~~~~~~~~~^^^^^^^^^^^^^^^^^^^^^^^^^^^^^^^^^^^^^^^^^^^^^^^^^^^^^^^^^^^^^^^^^^^^^^^^^^^
                 logger_level=logger_level, allowed_updates=allowed_updates, restart_on_change=False,
                 ^^^^^^^^^^^^^^^^^^^^^^^^^^^^^^^^^^^^^^^^^^^^^^^^^^^^^^^^^^^^^^^^^^^^^^^^^^^^^^^^^^^^
                 *args, **kwargs)
                 ^^^^^^^^^^^^^^^^
  File "/workspace/venv/lib/python3.13/site-packages/telebot/__init__.py", line 1195, in polling
    logger.info('Starting your bot with username: [@%s]', self.user.username)
                                                          ^^^^^^^^^
  File "/workspace/venv/lib/python3.13/site-packages/telebot/__init__.py", line 306, in user
    self._user = self.get_me()
                 ~~~~~~~~~~~^^
  File "/workspace/venv/lib/python3.13/site-packages/telebot/__init__.py", line 1382, in get_me
    apihelper.get_me(self.token)
    ~~~~~~~~~~~~~~~~^^^^^^^^^^^^
  File "/workspace/venv/lib/python3.13/site-packages/telebot/apihelper.py", line 202, in get_me
    return _make_request(token, method_url)
  File "/workspace/venv/lib/python3.13/site-packages/telebot/apihelper.py", line 168, in _make_request
    json_result = _check_result(method_name, result)
  File "/workspace/venv/lib/python3.13/site-packages/telebot/apihelper.py", line 195, in _check_result
    raise ApiTelegramException(method_name, result, result_json)
telebot.apihelper.ApiTelegramException: A request to the Telegram API was unsuccessful. Error code: 401. Description: Unauthorized

2025-08-14 16:04:16,492 - ERROR - Infinity polling exception: A request to the Telegram API was unsuccessful. Error code: 401. Description: Unauthorized
2025-08-14 16:04:16,492 - ERROR - Exception traceback:
Traceback (most recent call last):
  File "/workspace/venv/lib/python3.13/site-packages/telebot/__init__.py", line 1110, in infinity_polling
    self.polling(non_stop=True, timeout=timeout, long_polling_timeout=long_polling_timeout,
    ~~~~~~~~~~~~^^^^^^^^^^^^^^^^^^^^^^^^^^^^^^^^^^^^^^^^^^^^^^^^^^^^^^^^^^^^^^^^^^^^^^^^^^^
                 logger_level=logger_level, allowed_updates=allowed_updates, restart_on_change=False,
                 ^^^^^^^^^^^^^^^^^^^^^^^^^^^^^^^^^^^^^^^^^^^^^^^^^^^^^^^^^^^^^^^^^^^^^^^^^^^^^^^^^^^^
                 *args, **kwargs)
                 ^^^^^^^^^^^^^^^^
  File "/workspace/venv/lib/python3.13/site-packages/telebot/__init__.py", line 1195, in polling
    logger.info('Starting your bot with username: [@%s]', self.user.username)
                                                          ^^^^^^^^^
  File "/workspace/venv/lib/python3.13/site-packages/telebot/__init__.py", line 306, in user
    self._user = self.get_me()
                 ~~~~~~~~~~~^^
  File "/workspace/venv/lib/python3.13/site-packages/telebot/__init__.py", line 1382, in get_me
    apihelper.get_me(self.token)
    ~~~~~~~~~~~~~~~~^^^^^^^^^^^^
  File "/workspace/venv/lib/python3.13/site-packages/telebot/apihelper.py", line 202, in get_me
    return _make_request(token, method_url)
  File "/workspace/venv/lib/python3.13/site-packages/telebot/apihelper.py", line 168, in _make_request
    json_result = _check_result(method_name, result)
  File "/workspace/venv/lib/python3.13/site-packages/telebot/apihelper.py", line 195, in _check_result
    raise ApiTelegramException(method_name, result, result_json)
telebot.apihelper.ApiTelegramException: A request to the Telegram API was unsuccessful. Error code: 401. Description: Unauthorized

2025-08-14 16:04:19,579 - ERROR - Infinity polling exception: A request to the Telegram API was unsuccessful. Error code: 401. Description: Unauthorized
2025-08-14 16:04:19,580 - ERROR - Exception traceback:
Traceback (most recent call last):
  File "/workspace/venv/lib/python3.13/site-packages/telebot/__init__.py", line 1110, in infinity_polling
    self.polling(non_stop=True, timeout=timeout, long_polling_timeout=long_polling_timeout,
    ~~~~~~~~~~~~^^^^^^^^^^^^^^^^^^^^^^^^^^^^^^^^^^^^^^^^^^^^^^^^^^^^^^^^^^^^^^^^^^^^^^^^^^^
                 logger_level=logger_level, allowed_updates=allowed_updates, restart_on_change=False,
                 ^^^^^^^^^^^^^^^^^^^^^^^^^^^^^^^^^^^^^^^^^^^^^^^^^^^^^^^^^^^^^^^^^^^^^^^^^^^^^^^^^^^^
                 *args, **kwargs)
                 ^^^^^^^^^^^^^^^^
  File "/workspace/venv/lib/python3.13/site-packages/telebot/__init__.py", line 1195, in polling
    logger.info('Starting your bot with username: [@%s]', self.user.username)
                                                          ^^^^^^^^^
  File "/workspace/venv/lib/python3.13/site-packages/telebot/__init__.py", line 306, in user
    self._user = self.get_me()
                 ~~~~~~~~~~~^^
  File "/workspace/venv/lib/python3.13/site-packages/telebot/__init__.py", line 1382, in get_me
    apihelper.get_me(self.token)
    ~~~~~~~~~~~~~~~~^^^^^^^^^^^^
  File "/workspace/venv/lib/python3.13/site-packages/telebot/apihelper.py", line 202, in get_me
    return _make_request(token, method_url)
  File "/workspace/venv/lib/python3.13/site-packages/telebot/apihelper.py", line 168, in _make_request
    json_result = _check_result(method_name, result)
  File "/workspace/venv/lib/python3.13/site-packages/telebot/apihelper.py", line 195, in _check_result
    raise ApiTelegramException(method_name, result, result_json)
telebot.apihelper.ApiTelegramException: A request to the Telegram API was unsuccessful. Error code: 401. Description: Unauthorized

2025-08-14 16:04:22,667 - ERROR - Infinity polling exception: A request to the Telegram API was unsuccessful. Error code: 401. Description: Unauthorized
2025-08-14 16:04:22,667 - ERROR - Exception traceback:
Traceback (most recent call last):
  File "/workspace/venv/lib/python3.13/site-packages/telebot/__init__.py", line 1110, in infinity_polling
    self.polling(non_stop=True, timeout=timeout, long_polling_timeout=long_polling_timeout,
    ~~~~~~~~~~~~^^^^^^^^^^^^^^^^^^^^^^^^^^^^^^^^^^^^^^^^^^^^^^^^^^^^^^^^^^^^^^^^^^^^^^^^^^^
                 logger_level=logger_level, allowed_updates=allowed_updates, restart_on_change=False,
                 ^^^^^^^^^^^^^^^^^^^^^^^^^^^^^^^^^^^^^^^^^^^^^^^^^^^^^^^^^^^^^^^^^^^^^^^^^^^^^^^^^^^^
                 *args, **kwargs)
                 ^^^^^^^^^^^^^^^^
  File "/workspace/venv/lib/python3.13/site-packages/telebot/__init__.py", line 1195, in polling
    logger.info('Starting your bot with username: [@%s]', self.user.username)
                                                          ^^^^^^^^^
  File "/workspace/venv/lib/python3.13/site-packages/telebot/__init__.py", line 306, in user
    self._user = self.get_me()
                 ~~~~~~~~~~~^^
  File "/workspace/venv/lib/python3.13/site-packages/telebot/__init__.py", line 1382, in get_me
    apihelper.get_me(self.token)
    ~~~~~~~~~~~~~~~~^^^^^^^^^^^^
  File "/workspace/venv/lib/python3.13/site-packages/telebot/apihelper.py", line 202, in get_me
    return _make_request(token, method_url)
  File "/workspace/venv/lib/python3.13/site-packages/telebot/apihelper.py", line 168, in _make_request
    json_result = _check_result(method_name, result)
  File "/workspace/venv/lib/python3.13/site-packages/telebot/apihelper.py", line 195, in _check_result
    raise ApiTelegramException(method_name, result, result_json)
telebot.apihelper.ApiTelegramException: A request to the Telegram API was unsuccessful. Error code: 401. Description: Unauthorized

2025-08-14 16:04:25,753 - ERROR - Infinity polling exception: A request to the Telegram API was unsuccessful. Error code: 401. Description: Unauthorized
2025-08-14 16:04:25,754 - ERROR - Exception traceback:
Traceback (most recent call last):
  File "/workspace/venv/lib/python3.13/site-packages/telebot/__init__.py", line 1110, in infinity_polling
    self.polling(non_stop=True, timeout=timeout, long_polling_timeout=long_polling_timeout,
    ~~~~~~~~~~~~^^^^^^^^^^^^^^^^^^^^^^^^^^^^^^^^^^^^^^^^^^^^^^^^^^^^^^^^^^^^^^^^^^^^^^^^^^^
                 logger_level=logger_level, allowed_updates=allowed_updates, restart_on_change=False,
                 ^^^^^^^^^^^^^^^^^^^^^^^^^^^^^^^^^^^^^^^^^^^^^^^^^^^^^^^^^^^^^^^^^^^^^^^^^^^^^^^^^^^^
                 *args, **kwargs)
                 ^^^^^^^^^^^^^^^^
  File "/workspace/venv/lib/python3.13/site-packages/telebot/__init__.py", line 1195, in polling
    logger.info('Starting your bot with username: [@%s]', self.user.username)
                                                          ^^^^^^^^^
  File "/workspace/venv/lib/python3.13/site-packages/telebot/__init__.py", line 306, in user
    self._user = self.get_me()
                 ~~~~~~~~~~~^^
  File "/workspace/venv/lib/python3.13/site-packages/telebot/__init__.py", line 1382, in get_me
    apihelper.get_me(self.token)
    ~~~~~~~~~~~~~~~~^^^^^^^^^^^^
  File "/workspace/venv/lib/python3.13/site-packages/telebot/apihelper.py", line 202, in get_me
    return _make_request(token, method_url)
  File "/workspace/venv/lib/python3.13/site-packages/telebot/apihelper.py", line 168, in _make_request
    json_result = _check_result(method_name, result)
  File "/workspace/venv/lib/python3.13/site-packages/telebot/apihelper.py", line 195, in _check_result
    raise ApiTelegramException(method_name, result, result_json)
telebot.apihelper.ApiTelegramException: A request to the Telegram API was unsuccessful. Error code: 401. Description: Unauthorized

2025-08-14 16:04:28,840 - ERROR - Infinity polling exception: A request to the Telegram API was unsuccessful. Error code: 401. Description: Unauthorized
2025-08-14 16:04:28,841 - ERROR - Exception traceback:
Traceback (most recent call last):
  File "/workspace/venv/lib/python3.13/site-packages/telebot/__init__.py", line 1110, in infinity_polling
    self.polling(non_stop=True, timeout=timeout, long_polling_timeout=long_polling_timeout,
    ~~~~~~~~~~~~^^^^^^^^^^^^^^^^^^^^^^^^^^^^^^^^^^^^^^^^^^^^^^^^^^^^^^^^^^^^^^^^^^^^^^^^^^^
                 logger_level=logger_level, allowed_updates=allowed_updates, restart_on_change=False,
                 ^^^^^^^^^^^^^^^^^^^^^^^^^^^^^^^^^^^^^^^^^^^^^^^^^^^^^^^^^^^^^^^^^^^^^^^^^^^^^^^^^^^^
                 *args, **kwargs)
                 ^^^^^^^^^^^^^^^^
  File "/workspace/venv/lib/python3.13/site-packages/telebot/__init__.py", line 1195, in polling
    logger.info('Starting your bot with username: [@%s]', self.user.username)
                                                          ^^^^^^^^^
  File "/workspace/venv/lib/python3.13/site-packages/telebot/__init__.py", line 306, in user
    self._user = self.get_me()
                 ~~~~~~~~~~~^^
  File "/workspace/venv/lib/python3.13/site-packages/telebot/__init__.py", line 1382, in get_me
    apihelper.get_me(self.token)
    ~~~~~~~~~~~~~~~~^^^^^^^^^^^^
  File "/workspace/venv/lib/python3.13/site-packages/telebot/apihelper.py", line 202, in get_me
    return _make_request(token, method_url)
  File "/workspace/venv/lib/python3.13/site-packages/telebot/apihelper.py", line 168, in _make_request
    json_result = _check_result(method_name, result)
  File "/workspace/venv/lib/python3.13/site-packages/telebot/apihelper.py", line 195, in _check_result
    raise ApiTelegramException(method_name, result, result_json)
telebot.apihelper.ApiTelegramException: A request to the Telegram API was unsuccessful. Error code: 401. Description: Unauthorized

2025-08-14 16:04:31,926 - ERROR - Infinity polling exception: A request to the Telegram API was unsuccessful. Error code: 401. Description: Unauthorized
2025-08-14 16:04:31,927 - ERROR - Exception traceback:
Traceback (most recent call last):
  File "/workspace/venv/lib/python3.13/site-packages/telebot/__init__.py", line 1110, in infinity_polling
    self.polling(non_stop=True, timeout=timeout, long_polling_timeout=long_polling_timeout,
    ~~~~~~~~~~~~^^^^^^^^^^^^^^^^^^^^^^^^^^^^^^^^^^^^^^^^^^^^^^^^^^^^^^^^^^^^^^^^^^^^^^^^^^^
                 logger_level=logger_level, allowed_updates=allowed_updates, restart_on_change=False,
                 ^^^^^^^^^^^^^^^^^^^^^^^^^^^^^^^^^^^^^^^^^^^^^^^^^^^^^^^^^^^^^^^^^^^^^^^^^^^^^^^^^^^^
                 *args, **kwargs)
                 ^^^^^^^^^^^^^^^^
  File "/workspace/venv/lib/python3.13/site-packages/telebot/__init__.py", line 1195, in polling
    logger.info('Starting your bot with username: [@%s]', self.user.username)
                                                          ^^^^^^^^^
  File "/workspace/venv/lib/python3.13/site-packages/telebot/__init__.py", line 306, in user
    self._user = self.get_me()
                 ~~~~~~~~~~~^^
  File "/workspace/venv/lib/python3.13/site-packages/telebot/__init__.py", line 1382, in get_me
    apihelper.get_me(self.token)
    ~~~~~~~~~~~~~~~~^^^^^^^^^^^^
  File "/workspace/venv/lib/python3.13/site-packages/telebot/apihelper.py", line 202, in get_me
    return _make_request(token, method_url)
  File "/workspace/venv/lib/python3.13/site-packages/telebot/apihelper.py", line 168, in _make_request
    json_result = _check_result(method_name, result)
  File "/workspace/venv/lib/python3.13/site-packages/telebot/apihelper.py", line 195, in _check_result
    raise ApiTelegramException(method_name, result, result_json)
telebot.apihelper.ApiTelegramException: A request to the Telegram API was unsuccessful. Error code: 401. Description: Unauthorized

2025-08-14 16:04:35,014 - ERROR - Infinity polling exception: A request to the Telegram API was unsuccessful. Error code: 401. Description: Unauthorized
2025-08-14 16:04:35,014 - ERROR - Exception traceback:
Traceback (most recent call last):
  File "/workspace/venv/lib/python3.13/site-packages/telebot/__init__.py", line 1110, in infinity_polling
    self.polling(non_stop=True, timeout=timeout, long_polling_timeout=long_polling_timeout,
    ~~~~~~~~~~~~^^^^^^^^^^^^^^^^^^^^^^^^^^^^^^^^^^^^^^^^^^^^^^^^^^^^^^^^^^^^^^^^^^^^^^^^^^^
                 logger_level=logger_level, allowed_updates=allowed_updates, restart_on_change=False,
                 ^^^^^^^^^^^^^^^^^^^^^^^^^^^^^^^^^^^^^^^^^^^^^^^^^^^^^^^^^^^^^^^^^^^^^^^^^^^^^^^^^^^^
                 *args, **kwargs)
                 ^^^^^^^^^^^^^^^^
  File "/workspace/venv/lib/python3.13/site-packages/telebot/__init__.py", line 1195, in polling
    logger.info('Starting your bot with username: [@%s]', self.user.username)
                                                          ^^^^^^^^^
  File "/workspace/venv/lib/python3.13/site-packages/telebot/__init__.py", line 306, in user
    self._user = self.get_me()
                 ~~~~~~~~~~~^^
  File "/workspace/venv/lib/python3.13/site-packages/telebot/__init__.py", line 1382, in get_me
    apihelper.get_me(self.token)
    ~~~~~~~~~~~~~~~~^^^^^^^^^^^^
  File "/workspace/venv/lib/python3.13/site-packages/telebot/apihelper.py", line 202, in get_me
    return _make_request(token, method_url)
  File "/workspace/venv/lib/python3.13/site-packages/telebot/apihelper.py", line 168, in _make_request
    json_result = _check_result(method_name, result)
  File "/workspace/venv/lib/python3.13/site-packages/telebot/apihelper.py", line 195, in _check_result
    raise ApiTelegramException(method_name, result, result_json)
telebot.apihelper.ApiTelegramException: A request to the Telegram API was unsuccessful. Error code: 401. Description: Unauthorized

2025-08-14 16:04:38,100 - ERROR - Infinity polling exception: A request to the Telegram API was unsuccessful. Error code: 401. Description: Unauthorized
2025-08-14 16:04:38,101 - ERROR - Exception traceback:
Traceback (most recent call last):
  File "/workspace/venv/lib/python3.13/site-packages/telebot/__init__.py", line 1110, in infinity_polling
    self.polling(non_stop=True, timeout=timeout, long_polling_timeout=long_polling_timeout,
    ~~~~~~~~~~~~^^^^^^^^^^^^^^^^^^^^^^^^^^^^^^^^^^^^^^^^^^^^^^^^^^^^^^^^^^^^^^^^^^^^^^^^^^^
                 logger_level=logger_level, allowed_updates=allowed_updates, restart_on_change=False,
                 ^^^^^^^^^^^^^^^^^^^^^^^^^^^^^^^^^^^^^^^^^^^^^^^^^^^^^^^^^^^^^^^^^^^^^^^^^^^^^^^^^^^^
                 *args, **kwargs)
                 ^^^^^^^^^^^^^^^^
  File "/workspace/venv/lib/python3.13/site-packages/telebot/__init__.py", line 1195, in polling
    logger.info('Starting your bot with username: [@%s]', self.user.username)
                                                          ^^^^^^^^^
  File "/workspace/venv/lib/python3.13/site-packages/telebot/__init__.py", line 306, in user
    self._user = self.get_me()
                 ~~~~~~~~~~~^^
  File "/workspace/venv/lib/python3.13/site-packages/telebot/__init__.py", line 1382, in get_me
    apihelper.get_me(self.token)
    ~~~~~~~~~~~~~~~~^^^^^^^^^^^^
  File "/workspace/venv/lib/python3.13/site-packages/telebot/apihelper.py", line 202, in get_me
    return _make_request(token, method_url)
  File "/workspace/venv/lib/python3.13/site-packages/telebot/apihelper.py", line 168, in _make_request
    json_result = _check_result(method_name, result)
  File "/workspace/venv/lib/python3.13/site-packages/telebot/apihelper.py", line 195, in _check_result
    raise ApiTelegramException(method_name, result, result_json)
telebot.apihelper.ApiTelegramException: A request to the Telegram API was unsuccessful. Error code: 401. Description: Unauthorized

2025-08-14 16:04:41,186 - ERROR - Infinity polling exception: A request to the Telegram API was unsuccessful. Error code: 401. Description: Unauthorized
2025-08-14 16:04:41,187 - ERROR - Exception traceback:
Traceback (most recent call last):
  File "/workspace/venv/lib/python3.13/site-packages/telebot/__init__.py", line 1110, in infinity_polling
    self.polling(non_stop=True, timeout=timeout, long_polling_timeout=long_polling_timeout,
    ~~~~~~~~~~~~^^^^^^^^^^^^^^^^^^^^^^^^^^^^^^^^^^^^^^^^^^^^^^^^^^^^^^^^^^^^^^^^^^^^^^^^^^^
                 logger_level=logger_level, allowed_updates=allowed_updates, restart_on_change=False,
                 ^^^^^^^^^^^^^^^^^^^^^^^^^^^^^^^^^^^^^^^^^^^^^^^^^^^^^^^^^^^^^^^^^^^^^^^^^^^^^^^^^^^^
                 *args, **kwargs)
                 ^^^^^^^^^^^^^^^^
  File "/workspace/venv/lib/python3.13/site-packages/telebot/__init__.py", line 1195, in polling
    logger.info('Starting your bot with username: [@%s]', self.user.username)
                                                          ^^^^^^^^^
  File "/workspace/venv/lib/python3.13/site-packages/telebot/__init__.py", line 306, in user
    self._user = self.get_me()
                 ~~~~~~~~~~~^^
  File "/workspace/venv/lib/python3.13/site-packages/telebot/__init__.py", line 1382, in get_me
    apihelper.get_me(self.token)
    ~~~~~~~~~~~~~~~~^^^^^^^^^^^^
  File "/workspace/venv/lib/python3.13/site-packages/telebot/apihelper.py", line 202, in get_me
    return _make_request(token, method_url)
  File "/workspace/venv/lib/python3.13/site-packages/telebot/apihelper.py", line 168, in _make_request
    json_result = _check_result(method_name, result)
  File "/workspace/venv/lib/python3.13/site-packages/telebot/apihelper.py", line 195, in _check_result
    raise ApiTelegramException(method_name, result, result_json)
telebot.apihelper.ApiTelegramException: A request to the Telegram API was unsuccessful. Error code: 401. Description: Unauthorized

2025-08-14 16:04:44,272 - ERROR - Infinity polling exception: A request to the Telegram API was unsuccessful. Error code: 401. Description: Unauthorized
2025-08-14 16:04:44,273 - ERROR - Exception traceback:
Traceback (most recent call last):
  File "/workspace/venv/lib/python3.13/site-packages/telebot/__init__.py", line 1110, in infinity_polling
    self.polling(non_stop=True, timeout=timeout, long_polling_timeout=long_polling_timeout,
    ~~~~~~~~~~~~^^^^^^^^^^^^^^^^^^^^^^^^^^^^^^^^^^^^^^^^^^^^^^^^^^^^^^^^^^^^^^^^^^^^^^^^^^^
                 logger_level=logger_level, allowed_updates=allowed_updates, restart_on_change=False,
                 ^^^^^^^^^^^^^^^^^^^^^^^^^^^^^^^^^^^^^^^^^^^^^^^^^^^^^^^^^^^^^^^^^^^^^^^^^^^^^^^^^^^^
                 *args, **kwargs)
                 ^^^^^^^^^^^^^^^^
  File "/workspace/venv/lib/python3.13/site-packages/telebot/__init__.py", line 1195, in polling
    logger.info('Starting your bot with username: [@%s]', self.user.username)
                                                          ^^^^^^^^^
  File "/workspace/venv/lib/python3.13/site-packages/telebot/__init__.py", line 306, in user
    self._user = self.get_me()
                 ~~~~~~~~~~~^^
  File "/workspace/venv/lib/python3.13/site-packages/telebot/__init__.py", line 1382, in get_me
    apihelper.get_me(self.token)
    ~~~~~~~~~~~~~~~~^^^^^^^^^^^^
  File "/workspace/venv/lib/python3.13/site-packages/telebot/apihelper.py", line 202, in get_me
    return _make_request(token, method_url)
  File "/workspace/venv/lib/python3.13/site-packages/telebot/apihelper.py", line 168, in _make_request
    json_result = _check_result(method_name, result)
  File "/workspace/venv/lib/python3.13/site-packages/telebot/apihelper.py", line 195, in _check_result
    raise ApiTelegramException(method_name, result, result_json)
telebot.apihelper.ApiTelegramException: A request to the Telegram API was unsuccessful. Error code: 401. Description: Unauthorized

2025-08-14 16:04:47,359 - ERROR - Infinity polling exception: A request to the Telegram API was unsuccessful. Error code: 401. Description: Unauthorized
2025-08-14 16:04:47,360 - ERROR - Exception traceback:
Traceback (most recent call last):
  File "/workspace/venv/lib/python3.13/site-packages/telebot/__init__.py", line 1110, in infinity_polling
    self.polling(non_stop=True, timeout=timeout, long_polling_timeout=long_polling_timeout,
    ~~~~~~~~~~~~^^^^^^^^^^^^^^^^^^^^^^^^^^^^^^^^^^^^^^^^^^^^^^^^^^^^^^^^^^^^^^^^^^^^^^^^^^^
                 logger_level=logger_level, allowed_updates=allowed_updates, restart_on_change=False,
                 ^^^^^^^^^^^^^^^^^^^^^^^^^^^^^^^^^^^^^^^^^^^^^^^^^^^^^^^^^^^^^^^^^^^^^^^^^^^^^^^^^^^^
                 *args, **kwargs)
                 ^^^^^^^^^^^^^^^^
  File "/workspace/venv/lib/python3.13/site-packages/telebot/__init__.py", line 1195, in polling
    logger.info('Starting your bot with username: [@%s]', self.user.username)
                                                          ^^^^^^^^^
  File "/workspace/venv/lib/python3.13/site-packages/telebot/__init__.py", line 306, in user
    self._user = self.get_me()
                 ~~~~~~~~~~~^^
  File "/workspace/venv/lib/python3.13/site-packages/telebot/__init__.py", line 1382, in get_me
    apihelper.get_me(self.token)
    ~~~~~~~~~~~~~~~~^^^^^^^^^^^^
  File "/workspace/venv/lib/python3.13/site-packages/telebot/apihelper.py", line 202, in get_me
    return _make_request(token, method_url)
  File "/workspace/venv/lib/python3.13/site-packages/telebot/apihelper.py", line 168, in _make_request
    json_result = _check_result(method_name, result)
  File "/workspace/venv/lib/python3.13/site-packages/telebot/apihelper.py", line 195, in _check_result
    raise ApiTelegramException(method_name, result, result_json)
telebot.apihelper.ApiTelegramException: A request to the Telegram API was unsuccessful. Error code: 401. Description: Unauthorized

2025-08-14 16:04:50,446 - ERROR - Infinity polling exception: A request to the Telegram API was unsuccessful. Error code: 401. Description: Unauthorized
2025-08-14 16:04:50,447 - ERROR - Exception traceback:
Traceback (most recent call last):
  File "/workspace/venv/lib/python3.13/site-packages/telebot/__init__.py", line 1110, in infinity_polling
    self.polling(non_stop=True, timeout=timeout, long_polling_timeout=long_polling_timeout,
    ~~~~~~~~~~~~^^^^^^^^^^^^^^^^^^^^^^^^^^^^^^^^^^^^^^^^^^^^^^^^^^^^^^^^^^^^^^^^^^^^^^^^^^^
                 logger_level=logger_level, allowed_updates=allowed_updates, restart_on_change=False,
                 ^^^^^^^^^^^^^^^^^^^^^^^^^^^^^^^^^^^^^^^^^^^^^^^^^^^^^^^^^^^^^^^^^^^^^^^^^^^^^^^^^^^^
                 *args, **kwargs)
                 ^^^^^^^^^^^^^^^^
  File "/workspace/venv/lib/python3.13/site-packages/telebot/__init__.py", line 1195, in polling
    logger.info('Starting your bot with username: [@%s]', self.user.username)
                                                          ^^^^^^^^^
  File "/workspace/venv/lib/python3.13/site-packages/telebot/__init__.py", line 306, in user
    self._user = self.get_me()
                 ~~~~~~~~~~~^^
  File "/workspace/venv/lib/python3.13/site-packages/telebot/__init__.py", line 1382, in get_me
    apihelper.get_me(self.token)
    ~~~~~~~~~~~~~~~~^^^^^^^^^^^^
  File "/workspace/venv/lib/python3.13/site-packages/telebot/apihelper.py", line 202, in get_me
    return _make_request(token, method_url)
  File "/workspace/venv/lib/python3.13/site-packages/telebot/apihelper.py", line 168, in _make_request
    json_result = _check_result(method_name, result)
  File "/workspace/venv/lib/python3.13/site-packages/telebot/apihelper.py", line 195, in _check_result
    raise ApiTelegramException(method_name, result, result_json)
telebot.apihelper.ApiTelegramException: A request to the Telegram API was unsuccessful. Error code: 401. Description: Unauthorized

2025-08-14 16:04:53,532 - ERROR - Infinity polling exception: A request to the Telegram API was unsuccessful. Error code: 401. Description: Unauthorized
2025-08-14 16:04:53,533 - ERROR - Exception traceback:
Traceback (most recent call last):
  File "/workspace/venv/lib/python3.13/site-packages/telebot/__init__.py", line 1110, in infinity_polling
    self.polling(non_stop=True, timeout=timeout, long_polling_timeout=long_polling_timeout,
    ~~~~~~~~~~~~^^^^^^^^^^^^^^^^^^^^^^^^^^^^^^^^^^^^^^^^^^^^^^^^^^^^^^^^^^^^^^^^^^^^^^^^^^^
                 logger_level=logger_level, allowed_updates=allowed_updates, restart_on_change=False,
                 ^^^^^^^^^^^^^^^^^^^^^^^^^^^^^^^^^^^^^^^^^^^^^^^^^^^^^^^^^^^^^^^^^^^^^^^^^^^^^^^^^^^^
                 *args, **kwargs)
                 ^^^^^^^^^^^^^^^^
  File "/workspace/venv/lib/python3.13/site-packages/telebot/__init__.py", line 1195, in polling
    logger.info('Starting your bot with username: [@%s]', self.user.username)
                                                          ^^^^^^^^^
  File "/workspace/venv/lib/python3.13/site-packages/telebot/__init__.py", line 306, in user
    self._user = self.get_me()
                 ~~~~~~~~~~~^^
  File "/workspace/venv/lib/python3.13/site-packages/telebot/__init__.py", line 1382, in get_me
    apihelper.get_me(self.token)
    ~~~~~~~~~~~~~~~~^^^^^^^^^^^^
  File "/workspace/venv/lib/python3.13/site-packages/telebot/apihelper.py", line 202, in get_me
    return _make_request(token, method_url)
  File "/workspace/venv/lib/python3.13/site-packages/telebot/apihelper.py", line 168, in _make_request
    json_result = _check_result(method_name, result)
  File "/workspace/venv/lib/python3.13/site-packages/telebot/apihelper.py", line 195, in _check_result
    raise ApiTelegramException(method_name, result, result_json)
telebot.apihelper.ApiTelegramException: A request to the Telegram API was unsuccessful. Error code: 401. Description: Unauthorized

2025-08-14 16:04:56,619 - ERROR - Infinity polling exception: A request to the Telegram API was unsuccessful. Error code: 401. Description: Unauthorized
2025-08-14 16:04:56,619 - ERROR - Exception traceback:
Traceback (most recent call last):
  File "/workspace/venv/lib/python3.13/site-packages/telebot/__init__.py", line 1110, in infinity_polling
    self.polling(non_stop=True, timeout=timeout, long_polling_timeout=long_polling_timeout,
    ~~~~~~~~~~~~^^^^^^^^^^^^^^^^^^^^^^^^^^^^^^^^^^^^^^^^^^^^^^^^^^^^^^^^^^^^^^^^^^^^^^^^^^^
                 logger_level=logger_level, allowed_updates=allowed_updates, restart_on_change=False,
                 ^^^^^^^^^^^^^^^^^^^^^^^^^^^^^^^^^^^^^^^^^^^^^^^^^^^^^^^^^^^^^^^^^^^^^^^^^^^^^^^^^^^^
                 *args, **kwargs)
                 ^^^^^^^^^^^^^^^^
  File "/workspace/venv/lib/python3.13/site-packages/telebot/__init__.py", line 1195, in polling
    logger.info('Starting your bot with username: [@%s]', self.user.username)
                                                          ^^^^^^^^^
  File "/workspace/venv/lib/python3.13/site-packages/telebot/__init__.py", line 306, in user
    self._user = self.get_me()
                 ~~~~~~~~~~~^^
  File "/workspace/venv/lib/python3.13/site-packages/telebot/__init__.py", line 1382, in get_me
    apihelper.get_me(self.token)
    ~~~~~~~~~~~~~~~~^^^^^^^^^^^^
  File "/workspace/venv/lib/python3.13/site-packages/telebot/apihelper.py", line 202, in get_me
    return _make_request(token, method_url)
  File "/workspace/venv/lib/python3.13/site-packages/telebot/apihelper.py", line 168, in _make_request
    json_result = _check_result(method_name, result)
  File "/workspace/venv/lib/python3.13/site-packages/telebot/apihelper.py", line 195, in _check_result
    raise ApiTelegramException(method_name, result, result_json)
telebot.apihelper.ApiTelegramException: A request to the Telegram API was unsuccessful. Error code: 401. Description: Unauthorized

2025-08-14 16:04:59,705 - ERROR - Infinity polling exception: A request to the Telegram API was unsuccessful. Error code: 401. Description: Unauthorized
2025-08-14 16:04:59,706 - ERROR - Exception traceback:
Traceback (most recent call last):
  File "/workspace/venv/lib/python3.13/site-packages/telebot/__init__.py", line 1110, in infinity_polling
    self.polling(non_stop=True, timeout=timeout, long_polling_timeout=long_polling_timeout,
    ~~~~~~~~~~~~^^^^^^^^^^^^^^^^^^^^^^^^^^^^^^^^^^^^^^^^^^^^^^^^^^^^^^^^^^^^^^^^^^^^^^^^^^^
                 logger_level=logger_level, allowed_updates=allowed_updates, restart_on_change=False,
                 ^^^^^^^^^^^^^^^^^^^^^^^^^^^^^^^^^^^^^^^^^^^^^^^^^^^^^^^^^^^^^^^^^^^^^^^^^^^^^^^^^^^^
                 *args, **kwargs)
                 ^^^^^^^^^^^^^^^^
  File "/workspace/venv/lib/python3.13/site-packages/telebot/__init__.py", line 1195, in polling
    logger.info('Starting your bot with username: [@%s]', self.user.username)
                                                          ^^^^^^^^^
  File "/workspace/venv/lib/python3.13/site-packages/telebot/__init__.py", line 306, in user
    self._user = self.get_me()
                 ~~~~~~~~~~~^^
  File "/workspace/venv/lib/python3.13/site-packages/telebot/__init__.py", line 1382, in get_me
    apihelper.get_me(self.token)
    ~~~~~~~~~~~~~~~~^^^^^^^^^^^^
  File "/workspace/venv/lib/python3.13/site-packages/telebot/apihelper.py", line 202, in get_me
    return _make_request(token, method_url)
  File "/workspace/venv/lib/python3.13/site-packages/telebot/apihelper.py", line 168, in _make_request
    json_result = _check_result(method_name, result)
  File "/workspace/venv/lib/python3.13/site-packages/telebot/apihelper.py", line 195, in _check_result
    raise ApiTelegramException(method_name, result, result_json)
telebot.apihelper.ApiTelegramException: A request to the Telegram API was unsuccessful. Error code: 401. Description: Unauthorized

2025-08-14 16:05:02,792 - ERROR - Infinity polling exception: A request to the Telegram API was unsuccessful. Error code: 401. Description: Unauthorized
2025-08-14 16:05:02,793 - ERROR - Exception traceback:
Traceback (most recent call last):
  File "/workspace/venv/lib/python3.13/site-packages/telebot/__init__.py", line 1110, in infinity_polling
    self.polling(non_stop=True, timeout=timeout, long_polling_timeout=long_polling_timeout,
    ~~~~~~~~~~~~^^^^^^^^^^^^^^^^^^^^^^^^^^^^^^^^^^^^^^^^^^^^^^^^^^^^^^^^^^^^^^^^^^^^^^^^^^^
                 logger_level=logger_level, allowed_updates=allowed_updates, restart_on_change=False,
                 ^^^^^^^^^^^^^^^^^^^^^^^^^^^^^^^^^^^^^^^^^^^^^^^^^^^^^^^^^^^^^^^^^^^^^^^^^^^^^^^^^^^^
                 *args, **kwargs)
                 ^^^^^^^^^^^^^^^^
  File "/workspace/venv/lib/python3.13/site-packages/telebot/__init__.py", line 1195, in polling
    logger.info('Starting your bot with username: [@%s]', self.user.username)
                                                          ^^^^^^^^^
  File "/workspace/venv/lib/python3.13/site-packages/telebot/__init__.py", line 306, in user
    self._user = self.get_me()
                 ~~~~~~~~~~~^^
  File "/workspace/venv/lib/python3.13/site-packages/telebot/__init__.py", line 1382, in get_me
    apihelper.get_me(self.token)
    ~~~~~~~~~~~~~~~~^^^^^^^^^^^^
  File "/workspace/venv/lib/python3.13/site-packages/telebot/apihelper.py", line 202, in get_me
    return _make_request(token, method_url)
  File "/workspace/venv/lib/python3.13/site-packages/telebot/apihelper.py", line 168, in _make_request
    json_result = _check_result(method_name, result)
  File "/workspace/venv/lib/python3.13/site-packages/telebot/apihelper.py", line 195, in _check_result
    raise ApiTelegramException(method_name, result, result_json)
telebot.apihelper.ApiTelegramException: A request to the Telegram API was unsuccessful. Error code: 401. Description: Unauthorized

2025-08-14 16:05:05,900 - ERROR - Infinity polling exception: A request to the Telegram API was unsuccessful. Error code: 401. Description: Unauthorized
2025-08-14 16:05:05,901 - ERROR - Exception traceback:
Traceback (most recent call last):
  File "/workspace/venv/lib/python3.13/site-packages/telebot/__init__.py", line 1110, in infinity_polling
    self.polling(non_stop=True, timeout=timeout, long_polling_timeout=long_polling_timeout,
    ~~~~~~~~~~~~^^^^^^^^^^^^^^^^^^^^^^^^^^^^^^^^^^^^^^^^^^^^^^^^^^^^^^^^^^^^^^^^^^^^^^^^^^^
                 logger_level=logger_level, allowed_updates=allowed_updates, restart_on_change=False,
                 ^^^^^^^^^^^^^^^^^^^^^^^^^^^^^^^^^^^^^^^^^^^^^^^^^^^^^^^^^^^^^^^^^^^^^^^^^^^^^^^^^^^^
                 *args, **kwargs)
                 ^^^^^^^^^^^^^^^^
  File "/workspace/venv/lib/python3.13/site-packages/telebot/__init__.py", line 1195, in polling
    logger.info('Starting your bot with username: [@%s]', self.user.username)
                                                          ^^^^^^^^^
  File "/workspace/venv/lib/python3.13/site-packages/telebot/__init__.py", line 306, in user
    self._user = self.get_me()
                 ~~~~~~~~~~~^^
  File "/workspace/venv/lib/python3.13/site-packages/telebot/__init__.py", line 1382, in get_me
    apihelper.get_me(self.token)
    ~~~~~~~~~~~~~~~~^^^^^^^^^^^^
  File "/workspace/venv/lib/python3.13/site-packages/telebot/apihelper.py", line 202, in get_me
    return _make_request(token, method_url)
  File "/workspace/venv/lib/python3.13/site-packages/telebot/apihelper.py", line 168, in _make_request
    json_result = _check_result(method_name, result)
  File "/workspace/venv/lib/python3.13/site-packages/telebot/apihelper.py", line 195, in _check_result
    raise ApiTelegramException(method_name, result, result_json)
telebot.apihelper.ApiTelegramException: A request to the Telegram API was unsuccessful. Error code: 401. Description: Unauthorized

2025-08-14 16:05:08,988 - ERROR - Infinity polling exception: A request to the Telegram API was unsuccessful. Error code: 401. Description: Unauthorized
2025-08-14 16:05:08,989 - ERROR - Exception traceback:
Traceback (most recent call last):
  File "/workspace/venv/lib/python3.13/site-packages/telebot/__init__.py", line 1110, in infinity_polling
    self.polling(non_stop=True, timeout=timeout, long_polling_timeout=long_polling_timeout,
    ~~~~~~~~~~~~^^^^^^^^^^^^^^^^^^^^^^^^^^^^^^^^^^^^^^^^^^^^^^^^^^^^^^^^^^^^^^^^^^^^^^^^^^^
                 logger_level=logger_level, allowed_updates=allowed_updates, restart_on_change=False,
                 ^^^^^^^^^^^^^^^^^^^^^^^^^^^^^^^^^^^^^^^^^^^^^^^^^^^^^^^^^^^^^^^^^^^^^^^^^^^^^^^^^^^^
                 *args, **kwargs)
                 ^^^^^^^^^^^^^^^^
  File "/workspace/venv/lib/python3.13/site-packages/telebot/__init__.py", line 1195, in polling
    logger.info('Starting your bot with username: [@%s]', self.user.username)
                                                          ^^^^^^^^^
  File "/workspace/venv/lib/python3.13/site-packages/telebot/__init__.py", line 306, in user
    self._user = self.get_me()
                 ~~~~~~~~~~~^^
  File "/workspace/venv/lib/python3.13/site-packages/telebot/__init__.py", line 1382, in get_me
    apihelper.get_me(self.token)
    ~~~~~~~~~~~~~~~~^^^^^^^^^^^^
  File "/workspace/venv/lib/python3.13/site-packages/telebot/apihelper.py", line 202, in get_me
    return _make_request(token, method_url)
  File "/workspace/venv/lib/python3.13/site-packages/telebot/apihelper.py", line 168, in _make_request
    json_result = _check_result(method_name, result)
  File "/workspace/venv/lib/python3.13/site-packages/telebot/apihelper.py", line 195, in _check_result
    raise ApiTelegramException(method_name, result, result_json)
telebot.apihelper.ApiTelegramException: A request to the Telegram API was unsuccessful. Error code: 401. Description: Unauthorized

2025-08-14 16:05:12,074 - ERROR - Infinity polling exception: A request to the Telegram API was unsuccessful. Error code: 401. Description: Unauthorized
2025-08-14 16:05:12,075 - ERROR - Exception traceback:
Traceback (most recent call last):
  File "/workspace/venv/lib/python3.13/site-packages/telebot/__init__.py", line 1110, in infinity_polling
    self.polling(non_stop=True, timeout=timeout, long_polling_timeout=long_polling_timeout,
    ~~~~~~~~~~~~^^^^^^^^^^^^^^^^^^^^^^^^^^^^^^^^^^^^^^^^^^^^^^^^^^^^^^^^^^^^^^^^^^^^^^^^^^^
                 logger_level=logger_level, allowed_updates=allowed_updates, restart_on_change=False,
                 ^^^^^^^^^^^^^^^^^^^^^^^^^^^^^^^^^^^^^^^^^^^^^^^^^^^^^^^^^^^^^^^^^^^^^^^^^^^^^^^^^^^^
                 *args, **kwargs)
                 ^^^^^^^^^^^^^^^^
  File "/workspace/venv/lib/python3.13/site-packages/telebot/__init__.py", line 1195, in polling
    logger.info('Starting your bot with username: [@%s]', self.user.username)
                                                          ^^^^^^^^^
  File "/workspace/venv/lib/python3.13/site-packages/telebot/__init__.py", line 306, in user
    self._user = self.get_me()
                 ~~~~~~~~~~~^^
  File "/workspace/venv/lib/python3.13/site-packages/telebot/__init__.py", line 1382, in get_me
    apihelper.get_me(self.token)
    ~~~~~~~~~~~~~~~~^^^^^^^^^^^^
  File "/workspace/venv/lib/python3.13/site-packages/telebot/apihelper.py", line 202, in get_me
    return _make_request(token, method_url)
  File "/workspace/venv/lib/python3.13/site-packages/telebot/apihelper.py", line 168, in _make_request
    json_result = _check_result(method_name, result)
  File "/workspace/venv/lib/python3.13/site-packages/telebot/apihelper.py", line 195, in _check_result
    raise ApiTelegramException(method_name, result, result_json)
telebot.apihelper.ApiTelegramException: A request to the Telegram API was unsuccessful. Error code: 401. Description: Unauthorized

2025-08-14 16:05:15,164 - ERROR - Infinity polling exception: A request to the Telegram API was unsuccessful. Error code: 401. Description: Unauthorized
2025-08-14 16:05:15,164 - ERROR - Exception traceback:
Traceback (most recent call last):
  File "/workspace/venv/lib/python3.13/site-packages/telebot/__init__.py", line 1110, in infinity_polling
    self.polling(non_stop=True, timeout=timeout, long_polling_timeout=long_polling_timeout,
    ~~~~~~~~~~~~^^^^^^^^^^^^^^^^^^^^^^^^^^^^^^^^^^^^^^^^^^^^^^^^^^^^^^^^^^^^^^^^^^^^^^^^^^^
                 logger_level=logger_level, allowed_updates=allowed_updates, restart_on_change=False,
                 ^^^^^^^^^^^^^^^^^^^^^^^^^^^^^^^^^^^^^^^^^^^^^^^^^^^^^^^^^^^^^^^^^^^^^^^^^^^^^^^^^^^^
                 *args, **kwargs)
                 ^^^^^^^^^^^^^^^^
  File "/workspace/venv/lib/python3.13/site-packages/telebot/__init__.py", line 1195, in polling
    logger.info('Starting your bot with username: [@%s]', self.user.username)
                                                          ^^^^^^^^^
  File "/workspace/venv/lib/python3.13/site-packages/telebot/__init__.py", line 306, in user
    self._user = self.get_me()
                 ~~~~~~~~~~~^^
  File "/workspace/venv/lib/python3.13/site-packages/telebot/__init__.py", line 1382, in get_me
    apihelper.get_me(self.token)
    ~~~~~~~~~~~~~~~~^^^^^^^^^^^^
  File "/workspace/venv/lib/python3.13/site-packages/telebot/apihelper.py", line 202, in get_me
    return _make_request(token, method_url)
  File "/workspace/venv/lib/python3.13/site-packages/telebot/apihelper.py", line 168, in _make_request
    json_result = _check_result(method_name, result)
  File "/workspace/venv/lib/python3.13/site-packages/telebot/apihelper.py", line 195, in _check_result
    raise ApiTelegramException(method_name, result, result_json)
telebot.apihelper.ApiTelegramException: A request to the Telegram API was unsuccessful. Error code: 401. Description: Unauthorized

2025-08-14 16:05:18,250 - ERROR - Infinity polling exception: A request to the Telegram API was unsuccessful. Error code: 401. Description: Unauthorized
2025-08-14 16:05:18,251 - ERROR - Exception traceback:
Traceback (most recent call last):
  File "/workspace/venv/lib/python3.13/site-packages/telebot/__init__.py", line 1110, in infinity_polling
    self.polling(non_stop=True, timeout=timeout, long_polling_timeout=long_polling_timeout,
    ~~~~~~~~~~~~^^^^^^^^^^^^^^^^^^^^^^^^^^^^^^^^^^^^^^^^^^^^^^^^^^^^^^^^^^^^^^^^^^^^^^^^^^^
                 logger_level=logger_level, allowed_updates=allowed_updates, restart_on_change=False,
                 ^^^^^^^^^^^^^^^^^^^^^^^^^^^^^^^^^^^^^^^^^^^^^^^^^^^^^^^^^^^^^^^^^^^^^^^^^^^^^^^^^^^^
                 *args, **kwargs)
                 ^^^^^^^^^^^^^^^^
  File "/workspace/venv/lib/python3.13/site-packages/telebot/__init__.py", line 1195, in polling
    logger.info('Starting your bot with username: [@%s]', self.user.username)
                                                          ^^^^^^^^^
  File "/workspace/venv/lib/python3.13/site-packages/telebot/__init__.py", line 306, in user
    self._user = self.get_me()
                 ~~~~~~~~~~~^^
  File "/workspace/venv/lib/python3.13/site-packages/telebot/__init__.py", line 1382, in get_me
    apihelper.get_me(self.token)
    ~~~~~~~~~~~~~~~~^^^^^^^^^^^^
  File "/workspace/venv/lib/python3.13/site-packages/telebot/apihelper.py", line 202, in get_me
    return _make_request(token, method_url)
  File "/workspace/venv/lib/python3.13/site-packages/telebot/apihelper.py", line 168, in _make_request
    json_result = _check_result(method_name, result)
  File "/workspace/venv/lib/python3.13/site-packages/telebot/apihelper.py", line 195, in _check_result
    raise ApiTelegramException(method_name, result, result_json)
telebot.apihelper.ApiTelegramException: A request to the Telegram API was unsuccessful. Error code: 401. Description: Unauthorized

2025-08-14 16:05:21,340 - ERROR - Infinity polling exception: A request to the Telegram API was unsuccessful. Error code: 401. Description: Unauthorized
2025-08-14 16:05:21,341 - ERROR - Exception traceback:
Traceback (most recent call last):
  File "/workspace/venv/lib/python3.13/site-packages/telebot/__init__.py", line 1110, in infinity_polling
    self.polling(non_stop=True, timeout=timeout, long_polling_timeout=long_polling_timeout,
    ~~~~~~~~~~~~^^^^^^^^^^^^^^^^^^^^^^^^^^^^^^^^^^^^^^^^^^^^^^^^^^^^^^^^^^^^^^^^^^^^^^^^^^^
                 logger_level=logger_level, allowed_updates=allowed_updates, restart_on_change=False,
                 ^^^^^^^^^^^^^^^^^^^^^^^^^^^^^^^^^^^^^^^^^^^^^^^^^^^^^^^^^^^^^^^^^^^^^^^^^^^^^^^^^^^^
                 *args, **kwargs)
                 ^^^^^^^^^^^^^^^^
  File "/workspace/venv/lib/python3.13/site-packages/telebot/__init__.py", line 1195, in polling
    logger.info('Starting your bot with username: [@%s]', self.user.username)
                                                          ^^^^^^^^^
  File "/workspace/venv/lib/python3.13/site-packages/telebot/__init__.py", line 306, in user
    self._user = self.get_me()
                 ~~~~~~~~~~~^^
  File "/workspace/venv/lib/python3.13/site-packages/telebot/__init__.py", line 1382, in get_me
    apihelper.get_me(self.token)
    ~~~~~~~~~~~~~~~~^^^^^^^^^^^^
  File "/workspace/venv/lib/python3.13/site-packages/telebot/apihelper.py", line 202, in get_me
    return _make_request(token, method_url)
  File "/workspace/venv/lib/python3.13/site-packages/telebot/apihelper.py", line 168, in _make_request
    json_result = _check_result(method_name, result)
  File "/workspace/venv/lib/python3.13/site-packages/telebot/apihelper.py", line 195, in _check_result
    raise ApiTelegramException(method_name, result, result_json)
telebot.apihelper.ApiTelegramException: A request to the Telegram API was unsuccessful. Error code: 401. Description: Unauthorized

2025-08-14 16:05:24,427 - ERROR - Infinity polling exception: A request to the Telegram API was unsuccessful. Error code: 401. Description: Unauthorized
2025-08-14 16:05:24,428 - ERROR - Exception traceback:
Traceback (most recent call last):
  File "/workspace/venv/lib/python3.13/site-packages/telebot/__init__.py", line 1110, in infinity_polling
    self.polling(non_stop=True, timeout=timeout, long_polling_timeout=long_polling_timeout,
    ~~~~~~~~~~~~^^^^^^^^^^^^^^^^^^^^^^^^^^^^^^^^^^^^^^^^^^^^^^^^^^^^^^^^^^^^^^^^^^^^^^^^^^^
                 logger_level=logger_level, allowed_updates=allowed_updates, restart_on_change=False,
                 ^^^^^^^^^^^^^^^^^^^^^^^^^^^^^^^^^^^^^^^^^^^^^^^^^^^^^^^^^^^^^^^^^^^^^^^^^^^^^^^^^^^^
                 *args, **kwargs)
                 ^^^^^^^^^^^^^^^^
  File "/workspace/venv/lib/python3.13/site-packages/telebot/__init__.py", line 1195, in polling
    logger.info('Starting your bot with username: [@%s]', self.user.username)
                                                          ^^^^^^^^^
  File "/workspace/venv/lib/python3.13/site-packages/telebot/__init__.py", line 306, in user
    self._user = self.get_me()
                 ~~~~~~~~~~~^^
  File "/workspace/venv/lib/python3.13/site-packages/telebot/__init__.py", line 1382, in get_me
    apihelper.get_me(self.token)
    ~~~~~~~~~~~~~~~~^^^^^^^^^^^^
  File "/workspace/venv/lib/python3.13/site-packages/telebot/apihelper.py", line 202, in get_me
    return _make_request(token, method_url)
  File "/workspace/venv/lib/python3.13/site-packages/telebot/apihelper.py", line 168, in _make_request
    json_result = _check_result(method_name, result)
  File "/workspace/venv/lib/python3.13/site-packages/telebot/apihelper.py", line 195, in _check_result
    raise ApiTelegramException(method_name, result, result_json)
telebot.apihelper.ApiTelegramException: A request to the Telegram API was unsuccessful. Error code: 401. Description: Unauthorized

2025-08-14 16:05:27,525 - ERROR - Infinity polling exception: A request to the Telegram API was unsuccessful. Error code: 401. Description: Unauthorized
2025-08-14 16:05:27,526 - ERROR - Exception traceback:
Traceback (most recent call last):
  File "/workspace/venv/lib/python3.13/site-packages/telebot/__init__.py", line 1110, in infinity_polling
    self.polling(non_stop=True, timeout=timeout, long_polling_timeout=long_polling_timeout,
    ~~~~~~~~~~~~^^^^^^^^^^^^^^^^^^^^^^^^^^^^^^^^^^^^^^^^^^^^^^^^^^^^^^^^^^^^^^^^^^^^^^^^^^^
                 logger_level=logger_level, allowed_updates=allowed_updates, restart_on_change=False,
                 ^^^^^^^^^^^^^^^^^^^^^^^^^^^^^^^^^^^^^^^^^^^^^^^^^^^^^^^^^^^^^^^^^^^^^^^^^^^^^^^^^^^^
                 *args, **kwargs)
                 ^^^^^^^^^^^^^^^^
  File "/workspace/venv/lib/python3.13/site-packages/telebot/__init__.py", line 1195, in polling
    logger.info('Starting your bot with username: [@%s]', self.user.username)
                                                          ^^^^^^^^^
  File "/workspace/venv/lib/python3.13/site-packages/telebot/__init__.py", line 306, in user
    self._user = self.get_me()
                 ~~~~~~~~~~~^^
  File "/workspace/venv/lib/python3.13/site-packages/telebot/__init__.py", line 1382, in get_me
    apihelper.get_me(self.token)
    ~~~~~~~~~~~~~~~~^^^^^^^^^^^^
  File "/workspace/venv/lib/python3.13/site-packages/telebot/apihelper.py", line 202, in get_me
    return _make_request(token, method_url)
  File "/workspace/venv/lib/python3.13/site-packages/telebot/apihelper.py", line 168, in _make_request
    json_result = _check_result(method_name, result)
  File "/workspace/venv/lib/python3.13/site-packages/telebot/apihelper.py", line 195, in _check_result
    raise ApiTelegramException(method_name, result, result_json)
telebot.apihelper.ApiTelegramException: A request to the Telegram API was unsuccessful. Error code: 401. Description: Unauthorized

2025-08-14 16:05:30,612 - ERROR - Infinity polling exception: A request to the Telegram API was unsuccessful. Error code: 401. Description: Unauthorized
2025-08-14 16:05:30,613 - ERROR - Exception traceback:
Traceback (most recent call last):
  File "/workspace/venv/lib/python3.13/site-packages/telebot/__init__.py", line 1110, in infinity_polling
    self.polling(non_stop=True, timeout=timeout, long_polling_timeout=long_polling_timeout,
    ~~~~~~~~~~~~^^^^^^^^^^^^^^^^^^^^^^^^^^^^^^^^^^^^^^^^^^^^^^^^^^^^^^^^^^^^^^^^^^^^^^^^^^^
                 logger_level=logger_level, allowed_updates=allowed_updates, restart_on_change=False,
                 ^^^^^^^^^^^^^^^^^^^^^^^^^^^^^^^^^^^^^^^^^^^^^^^^^^^^^^^^^^^^^^^^^^^^^^^^^^^^^^^^^^^^
                 *args, **kwargs)
                 ^^^^^^^^^^^^^^^^
  File "/workspace/venv/lib/python3.13/site-packages/telebot/__init__.py", line 1195, in polling
    logger.info('Starting your bot with username: [@%s]', self.user.username)
                                                          ^^^^^^^^^
  File "/workspace/venv/lib/python3.13/site-packages/telebot/__init__.py", line 306, in user
    self._user = self.get_me()
                 ~~~~~~~~~~~^^
  File "/workspace/venv/lib/python3.13/site-packages/telebot/__init__.py", line 1382, in get_me
    apihelper.get_me(self.token)
    ~~~~~~~~~~~~~~~~^^^^^^^^^^^^
  File "/workspace/venv/lib/python3.13/site-packages/telebot/apihelper.py", line 202, in get_me
    return _make_request(token, method_url)
  File "/workspace/venv/lib/python3.13/site-packages/telebot/apihelper.py", line 168, in _make_request
    json_result = _check_result(method_name, result)
  File "/workspace/venv/lib/python3.13/site-packages/telebot/apihelper.py", line 195, in _check_result
    raise ApiTelegramException(method_name, result, result_json)
telebot.apihelper.ApiTelegramException: A request to the Telegram API was unsuccessful. Error code: 401. Description: Unauthorized

2025-08-14 16:05:33,699 - ERROR - Infinity polling exception: A request to the Telegram API was unsuccessful. Error code: 401. Description: Unauthorized
2025-08-14 16:05:33,700 - ERROR - Exception traceback:
Traceback (most recent call last):
  File "/workspace/venv/lib/python3.13/site-packages/telebot/__init__.py", line 1110, in infinity_polling
    self.polling(non_stop=True, timeout=timeout, long_polling_timeout=long_polling_timeout,
    ~~~~~~~~~~~~^^^^^^^^^^^^^^^^^^^^^^^^^^^^^^^^^^^^^^^^^^^^^^^^^^^^^^^^^^^^^^^^^^^^^^^^^^^
                 logger_level=logger_level, allowed_updates=allowed_updates, restart_on_change=False,
                 ^^^^^^^^^^^^^^^^^^^^^^^^^^^^^^^^^^^^^^^^^^^^^^^^^^^^^^^^^^^^^^^^^^^^^^^^^^^^^^^^^^^^
                 *args, **kwargs)
                 ^^^^^^^^^^^^^^^^
  File "/workspace/venv/lib/python3.13/site-packages/telebot/__init__.py", line 1195, in polling
    logger.info('Starting your bot with username: [@%s]', self.user.username)
                                                          ^^^^^^^^^
  File "/workspace/venv/lib/python3.13/site-packages/telebot/__init__.py", line 306, in user
    self._user = self.get_me()
                 ~~~~~~~~~~~^^
  File "/workspace/venv/lib/python3.13/site-packages/telebot/__init__.py", line 1382, in get_me
    apihelper.get_me(self.token)
    ~~~~~~~~~~~~~~~~^^^^^^^^^^^^
  File "/workspace/venv/lib/python3.13/site-packages/telebot/apihelper.py", line 202, in get_me
    return _make_request(token, method_url)
  File "/workspace/venv/lib/python3.13/site-packages/telebot/apihelper.py", line 168, in _make_request
    json_result = _check_result(method_name, result)
  File "/workspace/venv/lib/python3.13/site-packages/telebot/apihelper.py", line 195, in _check_result
    raise ApiTelegramException(method_name, result, result_json)
telebot.apihelper.ApiTelegramException: A request to the Telegram API was unsuccessful. Error code: 401. Description: Unauthorized

2025-08-14 16:05:36,786 - ERROR - Infinity polling exception: A request to the Telegram API was unsuccessful. Error code: 401. Description: Unauthorized
2025-08-14 16:05:36,787 - ERROR - Exception traceback:
Traceback (most recent call last):
  File "/workspace/venv/lib/python3.13/site-packages/telebot/__init__.py", line 1110, in infinity_polling
    self.polling(non_stop=True, timeout=timeout, long_polling_timeout=long_polling_timeout,
    ~~~~~~~~~~~~^^^^^^^^^^^^^^^^^^^^^^^^^^^^^^^^^^^^^^^^^^^^^^^^^^^^^^^^^^^^^^^^^^^^^^^^^^^
                 logger_level=logger_level, allowed_updates=allowed_updates, restart_on_change=False,
                 ^^^^^^^^^^^^^^^^^^^^^^^^^^^^^^^^^^^^^^^^^^^^^^^^^^^^^^^^^^^^^^^^^^^^^^^^^^^^^^^^^^^^
                 *args, **kwargs)
                 ^^^^^^^^^^^^^^^^
  File "/workspace/venv/lib/python3.13/site-packages/telebot/__init__.py", line 1195, in polling
    logger.info('Starting your bot with username: [@%s]', self.user.username)
                                                          ^^^^^^^^^
  File "/workspace/venv/lib/python3.13/site-packages/telebot/__init__.py", line 306, in user
    self._user = self.get_me()
                 ~~~~~~~~~~~^^
  File "/workspace/venv/lib/python3.13/site-packages/telebot/__init__.py", line 1382, in get_me
    apihelper.get_me(self.token)
    ~~~~~~~~~~~~~~~~^^^^^^^^^^^^
  File "/workspace/venv/lib/python3.13/site-packages/telebot/apihelper.py", line 202, in get_me
    return _make_request(token, method_url)
  File "/workspace/venv/lib/python3.13/site-packages/telebot/apihelper.py", line 168, in _make_request
    json_result = _check_result(method_name, result)
  File "/workspace/venv/lib/python3.13/site-packages/telebot/apihelper.py", line 195, in _check_result
    raise ApiTelegramException(method_name, result, result_json)
telebot.apihelper.ApiTelegramException: A request to the Telegram API was unsuccessful. Error code: 401. Description: Unauthorized

2025-08-14 16:05:39,874 - ERROR - Infinity polling exception: A request to the Telegram API was unsuccessful. Error code: 401. Description: Unauthorized
2025-08-14 16:05:39,874 - ERROR - Exception traceback:
Traceback (most recent call last):
  File "/workspace/venv/lib/python3.13/site-packages/telebot/__init__.py", line 1110, in infinity_polling
    self.polling(non_stop=True, timeout=timeout, long_polling_timeout=long_polling_timeout,
    ~~~~~~~~~~~~^^^^^^^^^^^^^^^^^^^^^^^^^^^^^^^^^^^^^^^^^^^^^^^^^^^^^^^^^^^^^^^^^^^^^^^^^^^
                 logger_level=logger_level, allowed_updates=allowed_updates, restart_on_change=False,
                 ^^^^^^^^^^^^^^^^^^^^^^^^^^^^^^^^^^^^^^^^^^^^^^^^^^^^^^^^^^^^^^^^^^^^^^^^^^^^^^^^^^^^
                 *args, **kwargs)
                 ^^^^^^^^^^^^^^^^
  File "/workspace/venv/lib/python3.13/site-packages/telebot/__init__.py", line 1195, in polling
    logger.info('Starting your bot with username: [@%s]', self.user.username)
                                                          ^^^^^^^^^
  File "/workspace/venv/lib/python3.13/site-packages/telebot/__init__.py", line 306, in user
    self._user = self.get_me()
                 ~~~~~~~~~~~^^
  File "/workspace/venv/lib/python3.13/site-packages/telebot/__init__.py", line 1382, in get_me
    apihelper.get_me(self.token)
    ~~~~~~~~~~~~~~~~^^^^^^^^^^^^
  File "/workspace/venv/lib/python3.13/site-packages/telebot/apihelper.py", line 202, in get_me
    return _make_request(token, method_url)
  File "/workspace/venv/lib/python3.13/site-packages/telebot/apihelper.py", line 168, in _make_request
    json_result = _check_result(method_name, result)
  File "/workspace/venv/lib/python3.13/site-packages/telebot/apihelper.py", line 195, in _check_result
    raise ApiTelegramException(method_name, result, result_json)
telebot.apihelper.ApiTelegramException: A request to the Telegram API was unsuccessful. Error code: 401. Description: Unauthorized

2025-08-14 16:05:42,961 - ERROR - Infinity polling exception: A request to the Telegram API was unsuccessful. Error code: 401. Description: Unauthorized
2025-08-14 16:05:42,961 - ERROR - Exception traceback:
Traceback (most recent call last):
  File "/workspace/venv/lib/python3.13/site-packages/telebot/__init__.py", line 1110, in infinity_polling
    self.polling(non_stop=True, timeout=timeout, long_polling_timeout=long_polling_timeout,
    ~~~~~~~~~~~~^^^^^^^^^^^^^^^^^^^^^^^^^^^^^^^^^^^^^^^^^^^^^^^^^^^^^^^^^^^^^^^^^^^^^^^^^^^
                 logger_level=logger_level, allowed_updates=allowed_updates, restart_on_change=False,
                 ^^^^^^^^^^^^^^^^^^^^^^^^^^^^^^^^^^^^^^^^^^^^^^^^^^^^^^^^^^^^^^^^^^^^^^^^^^^^^^^^^^^^
                 *args, **kwargs)
                 ^^^^^^^^^^^^^^^^
  File "/workspace/venv/lib/python3.13/site-packages/telebot/__init__.py", line 1195, in polling
    logger.info('Starting your bot with username: [@%s]', self.user.username)
                                                          ^^^^^^^^^
  File "/workspace/venv/lib/python3.13/site-packages/telebot/__init__.py", line 306, in user
    self._user = self.get_me()
                 ~~~~~~~~~~~^^
  File "/workspace/venv/lib/python3.13/site-packages/telebot/__init__.py", line 1382, in get_me
    apihelper.get_me(self.token)
    ~~~~~~~~~~~~~~~~^^^^^^^^^^^^
  File "/workspace/venv/lib/python3.13/site-packages/telebot/apihelper.py", line 202, in get_me
    return _make_request(token, method_url)
  File "/workspace/venv/lib/python3.13/site-packages/telebot/apihelper.py", line 168, in _make_request
    json_result = _check_result(method_name, result)
  File "/workspace/venv/lib/python3.13/site-packages/telebot/apihelper.py", line 195, in _check_result
    raise ApiTelegramException(method_name, result, result_json)
telebot.apihelper.ApiTelegramException: A request to the Telegram API was unsuccessful. Error code: 401. Description: Unauthorized

2025-08-14 16:05:46,047 - ERROR - Infinity polling exception: A request to the Telegram API was unsuccessful. Error code: 401. Description: Unauthorized
2025-08-14 16:05:46,048 - ERROR - Exception traceback:
Traceback (most recent call last):
  File "/workspace/venv/lib/python3.13/site-packages/telebot/__init__.py", line 1110, in infinity_polling
    self.polling(non_stop=True, timeout=timeout, long_polling_timeout=long_polling_timeout,
    ~~~~~~~~~~~~^^^^^^^^^^^^^^^^^^^^^^^^^^^^^^^^^^^^^^^^^^^^^^^^^^^^^^^^^^^^^^^^^^^^^^^^^^^
                 logger_level=logger_level, allowed_updates=allowed_updates, restart_on_change=False,
                 ^^^^^^^^^^^^^^^^^^^^^^^^^^^^^^^^^^^^^^^^^^^^^^^^^^^^^^^^^^^^^^^^^^^^^^^^^^^^^^^^^^^^
                 *args, **kwargs)
                 ^^^^^^^^^^^^^^^^
  File "/workspace/venv/lib/python3.13/site-packages/telebot/__init__.py", line 1195, in polling
    logger.info('Starting your bot with username: [@%s]', self.user.username)
                                                          ^^^^^^^^^
  File "/workspace/venv/lib/python3.13/site-packages/telebot/__init__.py", line 306, in user
    self._user = self.get_me()
                 ~~~~~~~~~~~^^
  File "/workspace/venv/lib/python3.13/site-packages/telebot/__init__.py", line 1382, in get_me
    apihelper.get_me(self.token)
    ~~~~~~~~~~~~~~~~^^^^^^^^^^^^
  File "/workspace/venv/lib/python3.13/site-packages/telebot/apihelper.py", line 202, in get_me
    return _make_request(token, method_url)
  File "/workspace/venv/lib/python3.13/site-packages/telebot/apihelper.py", line 168, in _make_request
    json_result = _check_result(method_name, result)
  File "/workspace/venv/lib/python3.13/site-packages/telebot/apihelper.py", line 195, in _check_result
    raise ApiTelegramException(method_name, result, result_json)
telebot.apihelper.ApiTelegramException: A request to the Telegram API was unsuccessful. Error code: 401. Description: Unauthorized

2025-08-14 16:05:49,140 - ERROR - Infinity polling exception: A request to the Telegram API was unsuccessful. Error code: 401. Description: Unauthorized
2025-08-14 16:05:49,141 - ERROR - Exception traceback:
Traceback (most recent call last):
  File "/workspace/venv/lib/python3.13/site-packages/telebot/__init__.py", line 1110, in infinity_polling
    self.polling(non_stop=True, timeout=timeout, long_polling_timeout=long_polling_timeout,
    ~~~~~~~~~~~~^^^^^^^^^^^^^^^^^^^^^^^^^^^^^^^^^^^^^^^^^^^^^^^^^^^^^^^^^^^^^^^^^^^^^^^^^^^
                 logger_level=logger_level, allowed_updates=allowed_updates, restart_on_change=False,
                 ^^^^^^^^^^^^^^^^^^^^^^^^^^^^^^^^^^^^^^^^^^^^^^^^^^^^^^^^^^^^^^^^^^^^^^^^^^^^^^^^^^^^
                 *args, **kwargs)
                 ^^^^^^^^^^^^^^^^
  File "/workspace/venv/lib/python3.13/site-packages/telebot/__init__.py", line 1195, in polling
    logger.info('Starting your bot with username: [@%s]', self.user.username)
                                                          ^^^^^^^^^
  File "/workspace/venv/lib/python3.13/site-packages/telebot/__init__.py", line 306, in user
    self._user = self.get_me()
                 ~~~~~~~~~~~^^
  File "/workspace/venv/lib/python3.13/site-packages/telebot/__init__.py", line 1382, in get_me
    apihelper.get_me(self.token)
    ~~~~~~~~~~~~~~~~^^^^^^^^^^^^
  File "/workspace/venv/lib/python3.13/site-packages/telebot/apihelper.py", line 202, in get_me
    return _make_request(token, method_url)
  File "/workspace/venv/lib/python3.13/site-packages/telebot/apihelper.py", line 168, in _make_request
    json_result = _check_result(method_name, result)
  File "/workspace/venv/lib/python3.13/site-packages/telebot/apihelper.py", line 195, in _check_result
    raise ApiTelegramException(method_name, result, result_json)
telebot.apihelper.ApiTelegramException: A request to the Telegram API was unsuccessful. Error code: 401. Description: Unauthorized

2025-08-14 16:05:52,240 - ERROR - Infinity polling exception: A request to the Telegram API was unsuccessful. Error code: 401. Description: Unauthorized
2025-08-14 16:05:52,241 - ERROR - Exception traceback:
Traceback (most recent call last):
  File "/workspace/venv/lib/python3.13/site-packages/telebot/__init__.py", line 1110, in infinity_polling
    self.polling(non_stop=True, timeout=timeout, long_polling_timeout=long_polling_timeout,
    ~~~~~~~~~~~~^^^^^^^^^^^^^^^^^^^^^^^^^^^^^^^^^^^^^^^^^^^^^^^^^^^^^^^^^^^^^^^^^^^^^^^^^^^
                 logger_level=logger_level, allowed_updates=allowed_updates, restart_on_change=False,
                 ^^^^^^^^^^^^^^^^^^^^^^^^^^^^^^^^^^^^^^^^^^^^^^^^^^^^^^^^^^^^^^^^^^^^^^^^^^^^^^^^^^^^
                 *args, **kwargs)
                 ^^^^^^^^^^^^^^^^
  File "/workspace/venv/lib/python3.13/site-packages/telebot/__init__.py", line 1195, in polling
    logger.info('Starting your bot with username: [@%s]', self.user.username)
                                                          ^^^^^^^^^
  File "/workspace/venv/lib/python3.13/site-packages/telebot/__init__.py", line 306, in user
    self._user = self.get_me()
                 ~~~~~~~~~~~^^
  File "/workspace/venv/lib/python3.13/site-packages/telebot/__init__.py", line 1382, in get_me
    apihelper.get_me(self.token)
    ~~~~~~~~~~~~~~~~^^^^^^^^^^^^
  File "/workspace/venv/lib/python3.13/site-packages/telebot/apihelper.py", line 202, in get_me
    return _make_request(token, method_url)
  File "/workspace/venv/lib/python3.13/site-packages/telebot/apihelper.py", line 168, in _make_request
    json_result = _check_result(method_name, result)
  File "/workspace/venv/lib/python3.13/site-packages/telebot/apihelper.py", line 195, in _check_result
    raise ApiTelegramException(method_name, result, result_json)
telebot.apihelper.ApiTelegramException: A request to the Telegram API was unsuccessful. Error code: 401. Description: Unauthorized

2025-08-14 16:05:55,327 - ERROR - Infinity polling exception: A request to the Telegram API was unsuccessful. Error code: 401. Description: Unauthorized
2025-08-14 16:05:55,328 - ERROR - Exception traceback:
Traceback (most recent call last):
  File "/workspace/venv/lib/python3.13/site-packages/telebot/__init__.py", line 1110, in infinity_polling
    self.polling(non_stop=True, timeout=timeout, long_polling_timeout=long_polling_timeout,
    ~~~~~~~~~~~~^^^^^^^^^^^^^^^^^^^^^^^^^^^^^^^^^^^^^^^^^^^^^^^^^^^^^^^^^^^^^^^^^^^^^^^^^^^
                 logger_level=logger_level, allowed_updates=allowed_updates, restart_on_change=False,
                 ^^^^^^^^^^^^^^^^^^^^^^^^^^^^^^^^^^^^^^^^^^^^^^^^^^^^^^^^^^^^^^^^^^^^^^^^^^^^^^^^^^^^
                 *args, **kwargs)
                 ^^^^^^^^^^^^^^^^
  File "/workspace/venv/lib/python3.13/site-packages/telebot/__init__.py", line 1195, in polling
    logger.info('Starting your bot with username: [@%s]', self.user.username)
                                                          ^^^^^^^^^
  File "/workspace/venv/lib/python3.13/site-packages/telebot/__init__.py", line 306, in user
    self._user = self.get_me()
                 ~~~~~~~~~~~^^
  File "/workspace/venv/lib/python3.13/site-packages/telebot/__init__.py", line 1382, in get_me
    apihelper.get_me(self.token)
    ~~~~~~~~~~~~~~~~^^^^^^^^^^^^
  File "/workspace/venv/lib/python3.13/site-packages/telebot/apihelper.py", line 202, in get_me
    return _make_request(token, method_url)
  File "/workspace/venv/lib/python3.13/site-packages/telebot/apihelper.py", line 168, in _make_request
    json_result = _check_result(method_name, result)
  File "/workspace/venv/lib/python3.13/site-packages/telebot/apihelper.py", line 195, in _check_result
    raise ApiTelegramException(method_name, result, result_json)
telebot.apihelper.ApiTelegramException: A request to the Telegram API was unsuccessful. Error code: 401. Description: Unauthorized

2025-08-14 16:05:58,415 - ERROR - Infinity polling exception: A request to the Telegram API was unsuccessful. Error code: 401. Description: Unauthorized
2025-08-14 16:05:58,416 - ERROR - Exception traceback:
Traceback (most recent call last):
  File "/workspace/venv/lib/python3.13/site-packages/telebot/__init__.py", line 1110, in infinity_polling
    self.polling(non_stop=True, timeout=timeout, long_polling_timeout=long_polling_timeout,
    ~~~~~~~~~~~~^^^^^^^^^^^^^^^^^^^^^^^^^^^^^^^^^^^^^^^^^^^^^^^^^^^^^^^^^^^^^^^^^^^^^^^^^^^
                 logger_level=logger_level, allowed_updates=allowed_updates, restart_on_change=False,
                 ^^^^^^^^^^^^^^^^^^^^^^^^^^^^^^^^^^^^^^^^^^^^^^^^^^^^^^^^^^^^^^^^^^^^^^^^^^^^^^^^^^^^
                 *args, **kwargs)
                 ^^^^^^^^^^^^^^^^
  File "/workspace/venv/lib/python3.13/site-packages/telebot/__init__.py", line 1195, in polling
    logger.info('Starting your bot with username: [@%s]', self.user.username)
                                                          ^^^^^^^^^
  File "/workspace/venv/lib/python3.13/site-packages/telebot/__init__.py", line 306, in user
    self._user = self.get_me()
                 ~~~~~~~~~~~^^
  File "/workspace/venv/lib/python3.13/site-packages/telebot/__init__.py", line 1382, in get_me
    apihelper.get_me(self.token)
    ~~~~~~~~~~~~~~~~^^^^^^^^^^^^
  File "/workspace/venv/lib/python3.13/site-packages/telebot/apihelper.py", line 202, in get_me
    return _make_request(token, method_url)
  File "/workspace/venv/lib/python3.13/site-packages/telebot/apihelper.py", line 168, in _make_request
    json_result = _check_result(method_name, result)
  File "/workspace/venv/lib/python3.13/site-packages/telebot/apihelper.py", line 195, in _check_result
    raise ApiTelegramException(method_name, result, result_json)
telebot.apihelper.ApiTelegramException: A request to the Telegram API was unsuccessful. Error code: 401. Description: Unauthorized

2025-08-14 16:06:01,504 - ERROR - Infinity polling exception: A request to the Telegram API was unsuccessful. Error code: 401. Description: Unauthorized
2025-08-14 16:06:01,505 - ERROR - Exception traceback:
Traceback (most recent call last):
  File "/workspace/venv/lib/python3.13/site-packages/telebot/__init__.py", line 1110, in infinity_polling
    self.polling(non_stop=True, timeout=timeout, long_polling_timeout=long_polling_timeout,
    ~~~~~~~~~~~~^^^^^^^^^^^^^^^^^^^^^^^^^^^^^^^^^^^^^^^^^^^^^^^^^^^^^^^^^^^^^^^^^^^^^^^^^^^
                 logger_level=logger_level, allowed_updates=allowed_updates, restart_on_change=False,
                 ^^^^^^^^^^^^^^^^^^^^^^^^^^^^^^^^^^^^^^^^^^^^^^^^^^^^^^^^^^^^^^^^^^^^^^^^^^^^^^^^^^^^
                 *args, **kwargs)
                 ^^^^^^^^^^^^^^^^
  File "/workspace/venv/lib/python3.13/site-packages/telebot/__init__.py", line 1195, in polling
    logger.info('Starting your bot with username: [@%s]', self.user.username)
                                                          ^^^^^^^^^
  File "/workspace/venv/lib/python3.13/site-packages/telebot/__init__.py", line 306, in user
    self._user = self.get_me()
                 ~~~~~~~~~~~^^
  File "/workspace/venv/lib/python3.13/site-packages/telebot/__init__.py", line 1382, in get_me
    apihelper.get_me(self.token)
    ~~~~~~~~~~~~~~~~^^^^^^^^^^^^
  File "/workspace/venv/lib/python3.13/site-packages/telebot/apihelper.py", line 202, in get_me
    return _make_request(token, method_url)
  File "/workspace/venv/lib/python3.13/site-packages/telebot/apihelper.py", line 168, in _make_request
    json_result = _check_result(method_name, result)
  File "/workspace/venv/lib/python3.13/site-packages/telebot/apihelper.py", line 195, in _check_result
    raise ApiTelegramException(method_name, result, result_json)
telebot.apihelper.ApiTelegramException: A request to the Telegram API was unsuccessful. Error code: 401. Description: Unauthorized

2025-08-14 16:06:04,590 - ERROR - Infinity polling exception: A request to the Telegram API was unsuccessful. Error code: 401. Description: Unauthorized
2025-08-14 16:06:04,591 - ERROR - Exception traceback:
Traceback (most recent call last):
  File "/workspace/venv/lib/python3.13/site-packages/telebot/__init__.py", line 1110, in infinity_polling
    self.polling(non_stop=True, timeout=timeout, long_polling_timeout=long_polling_timeout,
    ~~~~~~~~~~~~^^^^^^^^^^^^^^^^^^^^^^^^^^^^^^^^^^^^^^^^^^^^^^^^^^^^^^^^^^^^^^^^^^^^^^^^^^^
                 logger_level=logger_level, allowed_updates=allowed_updates, restart_on_change=False,
                 ^^^^^^^^^^^^^^^^^^^^^^^^^^^^^^^^^^^^^^^^^^^^^^^^^^^^^^^^^^^^^^^^^^^^^^^^^^^^^^^^^^^^
                 *args, **kwargs)
                 ^^^^^^^^^^^^^^^^
  File "/workspace/venv/lib/python3.13/site-packages/telebot/__init__.py", line 1195, in polling
    logger.info('Starting your bot with username: [@%s]', self.user.username)
                                                          ^^^^^^^^^
  File "/workspace/venv/lib/python3.13/site-packages/telebot/__init__.py", line 306, in user
    self._user = self.get_me()
                 ~~~~~~~~~~~^^
  File "/workspace/venv/lib/python3.13/site-packages/telebot/__init__.py", line 1382, in get_me
    apihelper.get_me(self.token)
    ~~~~~~~~~~~~~~~~^^^^^^^^^^^^
  File "/workspace/venv/lib/python3.13/site-packages/telebot/apihelper.py", line 202, in get_me
    return _make_request(token, method_url)
  File "/workspace/venv/lib/python3.13/site-packages/telebot/apihelper.py", line 168, in _make_request
    json_result = _check_result(method_name, result)
  File "/workspace/venv/lib/python3.13/site-packages/telebot/apihelper.py", line 195, in _check_result
    raise ApiTelegramException(method_name, result, result_json)
telebot.apihelper.ApiTelegramException: A request to the Telegram API was unsuccessful. Error code: 401. Description: Unauthorized

2025-08-14 16:06:07,676 - ERROR - Infinity polling exception: A request to the Telegram API was unsuccessful. Error code: 401. Description: Unauthorized
2025-08-14 16:06:07,677 - ERROR - Exception traceback:
Traceback (most recent call last):
  File "/workspace/venv/lib/python3.13/site-packages/telebot/__init__.py", line 1110, in infinity_polling
    self.polling(non_stop=True, timeout=timeout, long_polling_timeout=long_polling_timeout,
    ~~~~~~~~~~~~^^^^^^^^^^^^^^^^^^^^^^^^^^^^^^^^^^^^^^^^^^^^^^^^^^^^^^^^^^^^^^^^^^^^^^^^^^^
                 logger_level=logger_level, allowed_updates=allowed_updates, restart_on_change=False,
                 ^^^^^^^^^^^^^^^^^^^^^^^^^^^^^^^^^^^^^^^^^^^^^^^^^^^^^^^^^^^^^^^^^^^^^^^^^^^^^^^^^^^^
                 *args, **kwargs)
                 ^^^^^^^^^^^^^^^^
  File "/workspace/venv/lib/python3.13/site-packages/telebot/__init__.py", line 1195, in polling
    logger.info('Starting your bot with username: [@%s]', self.user.username)
                                                          ^^^^^^^^^
  File "/workspace/venv/lib/python3.13/site-packages/telebot/__init__.py", line 306, in user
    self._user = self.get_me()
                 ~~~~~~~~~~~^^
  File "/workspace/venv/lib/python3.13/site-packages/telebot/__init__.py", line 1382, in get_me
    apihelper.get_me(self.token)
    ~~~~~~~~~~~~~~~~^^^^^^^^^^^^
  File "/workspace/venv/lib/python3.13/site-packages/telebot/apihelper.py", line 202, in get_me
    return _make_request(token, method_url)
  File "/workspace/venv/lib/python3.13/site-packages/telebot/apihelper.py", line 168, in _make_request
    json_result = _check_result(method_name, result)
  File "/workspace/venv/lib/python3.13/site-packages/telebot/apihelper.py", line 195, in _check_result
    raise ApiTelegramException(method_name, result, result_json)
telebot.apihelper.ApiTelegramException: A request to the Telegram API was unsuccessful. Error code: 401. Description: Unauthorized

2025-08-14 16:06:10,763 - ERROR - Infinity polling exception: A request to the Telegram API was unsuccessful. Error code: 401. Description: Unauthorized
2025-08-14 16:06:10,764 - ERROR - Exception traceback:
Traceback (most recent call last):
  File "/workspace/venv/lib/python3.13/site-packages/telebot/__init__.py", line 1110, in infinity_polling
    self.polling(non_stop=True, timeout=timeout, long_polling_timeout=long_polling_timeout,
    ~~~~~~~~~~~~^^^^^^^^^^^^^^^^^^^^^^^^^^^^^^^^^^^^^^^^^^^^^^^^^^^^^^^^^^^^^^^^^^^^^^^^^^^
                 logger_level=logger_level, allowed_updates=allowed_updates, restart_on_change=False,
                 ^^^^^^^^^^^^^^^^^^^^^^^^^^^^^^^^^^^^^^^^^^^^^^^^^^^^^^^^^^^^^^^^^^^^^^^^^^^^^^^^^^^^
                 *args, **kwargs)
                 ^^^^^^^^^^^^^^^^
  File "/workspace/venv/lib/python3.13/site-packages/telebot/__init__.py", line 1195, in polling
    logger.info('Starting your bot with username: [@%s]', self.user.username)
                                                          ^^^^^^^^^
  File "/workspace/venv/lib/python3.13/site-packages/telebot/__init__.py", line 306, in user
    self._user = self.get_me()
                 ~~~~~~~~~~~^^
  File "/workspace/venv/lib/python3.13/site-packages/telebot/__init__.py", line 1382, in get_me
    apihelper.get_me(self.token)
    ~~~~~~~~~~~~~~~~^^^^^^^^^^^^
  File "/workspace/venv/lib/python3.13/site-packages/telebot/apihelper.py", line 202, in get_me
    return _make_request(token, method_url)
  File "/workspace/venv/lib/python3.13/site-packages/telebot/apihelper.py", line 168, in _make_request
    json_result = _check_result(method_name, result)
  File "/workspace/venv/lib/python3.13/site-packages/telebot/apihelper.py", line 195, in _check_result
    raise ApiTelegramException(method_name, result, result_json)
telebot.apihelper.ApiTelegramException: A request to the Telegram API was unsuccessful. Error code: 401. Description: Unauthorized

2025-08-14 16:06:13,870 - ERROR - Infinity polling exception: A request to the Telegram API was unsuccessful. Error code: 401. Description: Unauthorized
2025-08-14 16:06:13,870 - ERROR - Exception traceback:
Traceback (most recent call last):
  File "/workspace/venv/lib/python3.13/site-packages/telebot/__init__.py", line 1110, in infinity_polling
    self.polling(non_stop=True, timeout=timeout, long_polling_timeout=long_polling_timeout,
    ~~~~~~~~~~~~^^^^^^^^^^^^^^^^^^^^^^^^^^^^^^^^^^^^^^^^^^^^^^^^^^^^^^^^^^^^^^^^^^^^^^^^^^^
                 logger_level=logger_level, allowed_updates=allowed_updates, restart_on_change=False,
                 ^^^^^^^^^^^^^^^^^^^^^^^^^^^^^^^^^^^^^^^^^^^^^^^^^^^^^^^^^^^^^^^^^^^^^^^^^^^^^^^^^^^^
                 *args, **kwargs)
                 ^^^^^^^^^^^^^^^^
  File "/workspace/venv/lib/python3.13/site-packages/telebot/__init__.py", line 1195, in polling
    logger.info('Starting your bot with username: [@%s]', self.user.username)
                                                          ^^^^^^^^^
  File "/workspace/venv/lib/python3.13/site-packages/telebot/__init__.py", line 306, in user
    self._user = self.get_me()
                 ~~~~~~~~~~~^^
  File "/workspace/venv/lib/python3.13/site-packages/telebot/__init__.py", line 1382, in get_me
    apihelper.get_me(self.token)
    ~~~~~~~~~~~~~~~~^^^^^^^^^^^^
  File "/workspace/venv/lib/python3.13/site-packages/telebot/apihelper.py", line 202, in get_me
    return _make_request(token, method_url)
  File "/workspace/venv/lib/python3.13/site-packages/telebot/apihelper.py", line 168, in _make_request
    json_result = _check_result(method_name, result)
  File "/workspace/venv/lib/python3.13/site-packages/telebot/apihelper.py", line 195, in _check_result
    raise ApiTelegramException(method_name, result, result_json)
telebot.apihelper.ApiTelegramException: A request to the Telegram API was unsuccessful. Error code: 401. Description: Unauthorized

2025-08-14 16:06:16,957 - ERROR - Infinity polling exception: A request to the Telegram API was unsuccessful. Error code: 401. Description: Unauthorized
2025-08-14 16:06:16,957 - ERROR - Exception traceback:
Traceback (most recent call last):
  File "/workspace/venv/lib/python3.13/site-packages/telebot/__init__.py", line 1110, in infinity_polling
    self.polling(non_stop=True, timeout=timeout, long_polling_timeout=long_polling_timeout,
    ~~~~~~~~~~~~^^^^^^^^^^^^^^^^^^^^^^^^^^^^^^^^^^^^^^^^^^^^^^^^^^^^^^^^^^^^^^^^^^^^^^^^^^^
                 logger_level=logger_level, allowed_updates=allowed_updates, restart_on_change=False,
                 ^^^^^^^^^^^^^^^^^^^^^^^^^^^^^^^^^^^^^^^^^^^^^^^^^^^^^^^^^^^^^^^^^^^^^^^^^^^^^^^^^^^^
                 *args, **kwargs)
                 ^^^^^^^^^^^^^^^^
  File "/workspace/venv/lib/python3.13/site-packages/telebot/__init__.py", line 1195, in polling
    logger.info('Starting your bot with username: [@%s]', self.user.username)
                                                          ^^^^^^^^^
  File "/workspace/venv/lib/python3.13/site-packages/telebot/__init__.py", line 306, in user
    self._user = self.get_me()
                 ~~~~~~~~~~~^^
  File "/workspace/venv/lib/python3.13/site-packages/telebot/__init__.py", line 1382, in get_me
    apihelper.get_me(self.token)
    ~~~~~~~~~~~~~~~~^^^^^^^^^^^^
  File "/workspace/venv/lib/python3.13/site-packages/telebot/apihelper.py", line 202, in get_me
    return _make_request(token, method_url)
  File "/workspace/venv/lib/python3.13/site-packages/telebot/apihelper.py", line 168, in _make_request
    json_result = _check_result(method_name, result)
  File "/workspace/venv/lib/python3.13/site-packages/telebot/apihelper.py", line 195, in _check_result
    raise ApiTelegramException(method_name, result, result_json)
telebot.apihelper.ApiTelegramException: A request to the Telegram API was unsuccessful. Error code: 401. Description: Unauthorized

2025-08-14 16:06:20,052 - ERROR - Infinity polling exception: A request to the Telegram API was unsuccessful. Error code: 401. Description: Unauthorized
2025-08-14 16:06:20,053 - ERROR - Exception traceback:
Traceback (most recent call last):
  File "/workspace/venv/lib/python3.13/site-packages/telebot/__init__.py", line 1110, in infinity_polling
    self.polling(non_stop=True, timeout=timeout, long_polling_timeout=long_polling_timeout,
    ~~~~~~~~~~~~^^^^^^^^^^^^^^^^^^^^^^^^^^^^^^^^^^^^^^^^^^^^^^^^^^^^^^^^^^^^^^^^^^^^^^^^^^^
                 logger_level=logger_level, allowed_updates=allowed_updates, restart_on_change=False,
                 ^^^^^^^^^^^^^^^^^^^^^^^^^^^^^^^^^^^^^^^^^^^^^^^^^^^^^^^^^^^^^^^^^^^^^^^^^^^^^^^^^^^^
                 *args, **kwargs)
                 ^^^^^^^^^^^^^^^^
  File "/workspace/venv/lib/python3.13/site-packages/telebot/__init__.py", line 1195, in polling
    logger.info('Starting your bot with username: [@%s]', self.user.username)
                                                          ^^^^^^^^^
  File "/workspace/venv/lib/python3.13/site-packages/telebot/__init__.py", line 306, in user
    self._user = self.get_me()
                 ~~~~~~~~~~~^^
  File "/workspace/venv/lib/python3.13/site-packages/telebot/__init__.py", line 1382, in get_me
    apihelper.get_me(self.token)
    ~~~~~~~~~~~~~~~~^^^^^^^^^^^^
  File "/workspace/venv/lib/python3.13/site-packages/telebot/apihelper.py", line 202, in get_me
    return _make_request(token, method_url)
  File "/workspace/venv/lib/python3.13/site-packages/telebot/apihelper.py", line 168, in _make_request
    json_result = _check_result(method_name, result)
  File "/workspace/venv/lib/python3.13/site-packages/telebot/apihelper.py", line 195, in _check_result
    raise ApiTelegramException(method_name, result, result_json)
telebot.apihelper.ApiTelegramException: A request to the Telegram API was unsuccessful. Error code: 401. Description: Unauthorized

2025-08-14 16:06:24,704 - ERROR - Infinity polling exception: A request to the Telegram API was unsuccessful. Error code: 401. Description: Unauthorized
2025-08-14 16:06:24,705 - ERROR - Exception traceback:
Traceback (most recent call last):
  File "/workspace/venv/lib/python3.13/site-packages/telebot/__init__.py", line 1110, in infinity_polling
    self.polling(non_stop=True, timeout=timeout, long_polling_timeout=long_polling_timeout,
    ~~~~~~~~~~~~^^^^^^^^^^^^^^^^^^^^^^^^^^^^^^^^^^^^^^^^^^^^^^^^^^^^^^^^^^^^^^^^^^^^^^^^^^^
                 logger_level=logger_level, allowed_updates=allowed_updates, restart_on_change=False,
                 ^^^^^^^^^^^^^^^^^^^^^^^^^^^^^^^^^^^^^^^^^^^^^^^^^^^^^^^^^^^^^^^^^^^^^^^^^^^^^^^^^^^^
                 *args, **kwargs)
                 ^^^^^^^^^^^^^^^^
  File "/workspace/venv/lib/python3.13/site-packages/telebot/__init__.py", line 1195, in polling
    logger.info('Starting your bot with username: [@%s]', self.user.username)
                                                          ^^^^^^^^^
  File "/workspace/venv/lib/python3.13/site-packages/telebot/__init__.py", line 306, in user
    self._user = self.get_me()
                 ~~~~~~~~~~~^^
  File "/workspace/venv/lib/python3.13/site-packages/telebot/__init__.py", line 1382, in get_me
    apihelper.get_me(self.token)
    ~~~~~~~~~~~~~~~~^^^^^^^^^^^^
  File "/workspace/venv/lib/python3.13/site-packages/telebot/apihelper.py", line 202, in get_me
    return _make_request(token, method_url)
  File "/workspace/venv/lib/python3.13/site-packages/telebot/apihelper.py", line 168, in _make_request
    json_result = _check_result(method_name, result)
  File "/workspace/venv/lib/python3.13/site-packages/telebot/apihelper.py", line 195, in _check_result
    raise ApiTelegramException(method_name, result, result_json)
telebot.apihelper.ApiTelegramException: A request to the Telegram API was unsuccessful. Error code: 401. Description: Unauthorized

2025-08-14 16:06:27,804 - ERROR - Infinity polling exception: A request to the Telegram API was unsuccessful. Error code: 401. Description: Unauthorized
2025-08-14 16:06:27,805 - ERROR - Exception traceback:
Traceback (most recent call last):
  File "/workspace/venv/lib/python3.13/site-packages/telebot/__init__.py", line 1110, in infinity_polling
    self.polling(non_stop=True, timeout=timeout, long_polling_timeout=long_polling_timeout,
    ~~~~~~~~~~~~^^^^^^^^^^^^^^^^^^^^^^^^^^^^^^^^^^^^^^^^^^^^^^^^^^^^^^^^^^^^^^^^^^^^^^^^^^^
                 logger_level=logger_level, allowed_updates=allowed_updates, restart_on_change=False,
                 ^^^^^^^^^^^^^^^^^^^^^^^^^^^^^^^^^^^^^^^^^^^^^^^^^^^^^^^^^^^^^^^^^^^^^^^^^^^^^^^^^^^^
                 *args, **kwargs)
                 ^^^^^^^^^^^^^^^^
  File "/workspace/venv/lib/python3.13/site-packages/telebot/__init__.py", line 1195, in polling
    logger.info('Starting your bot with username: [@%s]', self.user.username)
                                                          ^^^^^^^^^
  File "/workspace/venv/lib/python3.13/site-packages/telebot/__init__.py", line 306, in user
    self._user = self.get_me()
                 ~~~~~~~~~~~^^
  File "/workspace/venv/lib/python3.13/site-packages/telebot/__init__.py", line 1382, in get_me
    apihelper.get_me(self.token)
    ~~~~~~~~~~~~~~~~^^^^^^^^^^^^
  File "/workspace/venv/lib/python3.13/site-packages/telebot/apihelper.py", line 202, in get_me
    return _make_request(token, method_url)
  File "/workspace/venv/lib/python3.13/site-packages/telebot/apihelper.py", line 168, in _make_request
    json_result = _check_result(method_name, result)
  File "/workspace/venv/lib/python3.13/site-packages/telebot/apihelper.py", line 195, in _check_result
    raise ApiTelegramException(method_name, result, result_json)
telebot.apihelper.ApiTelegramException: A request to the Telegram API was unsuccessful. Error code: 401. Description: Unauthorized

2025-08-14 16:06:30,890 - ERROR - Infinity polling exception: A request to the Telegram API was unsuccessful. Error code: 401. Description: Unauthorized
2025-08-14 16:06:30,891 - ERROR - Exception traceback:
Traceback (most recent call last):
  File "/workspace/venv/lib/python3.13/site-packages/telebot/__init__.py", line 1110, in infinity_polling
    self.polling(non_stop=True, timeout=timeout, long_polling_timeout=long_polling_timeout,
    ~~~~~~~~~~~~^^^^^^^^^^^^^^^^^^^^^^^^^^^^^^^^^^^^^^^^^^^^^^^^^^^^^^^^^^^^^^^^^^^^^^^^^^^
                 logger_level=logger_level, allowed_updates=allowed_updates, restart_on_change=False,
                 ^^^^^^^^^^^^^^^^^^^^^^^^^^^^^^^^^^^^^^^^^^^^^^^^^^^^^^^^^^^^^^^^^^^^^^^^^^^^^^^^^^^^
                 *args, **kwargs)
                 ^^^^^^^^^^^^^^^^
  File "/workspace/venv/lib/python3.13/site-packages/telebot/__init__.py", line 1195, in polling
    logger.info('Starting your bot with username: [@%s]', self.user.username)
                                                          ^^^^^^^^^
  File "/workspace/venv/lib/python3.13/site-packages/telebot/__init__.py", line 306, in user
    self._user = self.get_me()
                 ~~~~~~~~~~~^^
  File "/workspace/venv/lib/python3.13/site-packages/telebot/__init__.py", line 1382, in get_me
    apihelper.get_me(self.token)
    ~~~~~~~~~~~~~~~~^^^^^^^^^^^^
  File "/workspace/venv/lib/python3.13/site-packages/telebot/apihelper.py", line 202, in get_me
    return _make_request(token, method_url)
  File "/workspace/venv/lib/python3.13/site-packages/telebot/apihelper.py", line 168, in _make_request
    json_result = _check_result(method_name, result)
  File "/workspace/venv/lib/python3.13/site-packages/telebot/apihelper.py", line 195, in _check_result
    raise ApiTelegramException(method_name, result, result_json)
telebot.apihelper.ApiTelegramException: A request to the Telegram API was unsuccessful. Error code: 401. Description: Unauthorized

2025-08-14 16:06:33,981 - ERROR - Infinity polling exception: A request to the Telegram API was unsuccessful. Error code: 401. Description: Unauthorized
2025-08-14 16:06:33,981 - ERROR - Exception traceback:
Traceback (most recent call last):
  File "/workspace/venv/lib/python3.13/site-packages/telebot/__init__.py", line 1110, in infinity_polling
    self.polling(non_stop=True, timeout=timeout, long_polling_timeout=long_polling_timeout,
    ~~~~~~~~~~~~^^^^^^^^^^^^^^^^^^^^^^^^^^^^^^^^^^^^^^^^^^^^^^^^^^^^^^^^^^^^^^^^^^^^^^^^^^^
                 logger_level=logger_level, allowed_updates=allowed_updates, restart_on_change=False,
                 ^^^^^^^^^^^^^^^^^^^^^^^^^^^^^^^^^^^^^^^^^^^^^^^^^^^^^^^^^^^^^^^^^^^^^^^^^^^^^^^^^^^^
                 *args, **kwargs)
                 ^^^^^^^^^^^^^^^^
  File "/workspace/venv/lib/python3.13/site-packages/telebot/__init__.py", line 1195, in polling
    logger.info('Starting your bot with username: [@%s]', self.user.username)
                                                          ^^^^^^^^^
  File "/workspace/venv/lib/python3.13/site-packages/telebot/__init__.py", line 306, in user
    self._user = self.get_me()
                 ~~~~~~~~~~~^^
  File "/workspace/venv/lib/python3.13/site-packages/telebot/__init__.py", line 1382, in get_me
    apihelper.get_me(self.token)
    ~~~~~~~~~~~~~~~~^^^^^^^^^^^^
  File "/workspace/venv/lib/python3.13/site-packages/telebot/apihelper.py", line 202, in get_me
    return _make_request(token, method_url)
  File "/workspace/venv/lib/python3.13/site-packages/telebot/apihelper.py", line 168, in _make_request
    json_result = _check_result(method_name, result)
  File "/workspace/venv/lib/python3.13/site-packages/telebot/apihelper.py", line 195, in _check_result
    raise ApiTelegramException(method_name, result, result_json)
telebot.apihelper.ApiTelegramException: A request to the Telegram API was unsuccessful. Error code: 401. Description: Unauthorized

2025-08-14 16:06:37,069 - ERROR - Infinity polling exception: A request to the Telegram API was unsuccessful. Error code: 401. Description: Unauthorized
2025-08-14 16:06:37,070 - ERROR - Exception traceback:
Traceback (most recent call last):
  File "/workspace/venv/lib/python3.13/site-packages/telebot/__init__.py", line 1110, in infinity_polling
    self.polling(non_stop=True, timeout=timeout, long_polling_timeout=long_polling_timeout,
    ~~~~~~~~~~~~^^^^^^^^^^^^^^^^^^^^^^^^^^^^^^^^^^^^^^^^^^^^^^^^^^^^^^^^^^^^^^^^^^^^^^^^^^^
                 logger_level=logger_level, allowed_updates=allowed_updates, restart_on_change=False,
                 ^^^^^^^^^^^^^^^^^^^^^^^^^^^^^^^^^^^^^^^^^^^^^^^^^^^^^^^^^^^^^^^^^^^^^^^^^^^^^^^^^^^^
                 *args, **kwargs)
                 ^^^^^^^^^^^^^^^^
  File "/workspace/venv/lib/python3.13/site-packages/telebot/__init__.py", line 1195, in polling
    logger.info('Starting your bot with username: [@%s]', self.user.username)
                                                          ^^^^^^^^^
  File "/workspace/venv/lib/python3.13/site-packages/telebot/__init__.py", line 306, in user
    self._user = self.get_me()
                 ~~~~~~~~~~~^^
  File "/workspace/venv/lib/python3.13/site-packages/telebot/__init__.py", line 1382, in get_me
    apihelper.get_me(self.token)
    ~~~~~~~~~~~~~~~~^^^^^^^^^^^^
  File "/workspace/venv/lib/python3.13/site-packages/telebot/apihelper.py", line 202, in get_me
    return _make_request(token, method_url)
  File "/workspace/venv/lib/python3.13/site-packages/telebot/apihelper.py", line 168, in _make_request
    json_result = _check_result(method_name, result)
  File "/workspace/venv/lib/python3.13/site-packages/telebot/apihelper.py", line 195, in _check_result
    raise ApiTelegramException(method_name, result, result_json)
telebot.apihelper.ApiTelegramException: A request to the Telegram API was unsuccessful. Error code: 401. Description: Unauthorized

2025-08-14 16:06:40,156 - ERROR - Infinity polling exception: A request to the Telegram API was unsuccessful. Error code: 401. Description: Unauthorized
2025-08-14 16:06:40,156 - ERROR - Exception traceback:
Traceback (most recent call last):
  File "/workspace/venv/lib/python3.13/site-packages/telebot/__init__.py", line 1110, in infinity_polling
    self.polling(non_stop=True, timeout=timeout, long_polling_timeout=long_polling_timeout,
    ~~~~~~~~~~~~^^^^^^^^^^^^^^^^^^^^^^^^^^^^^^^^^^^^^^^^^^^^^^^^^^^^^^^^^^^^^^^^^^^^^^^^^^^
                 logger_level=logger_level, allowed_updates=allowed_updates, restart_on_change=False,
                 ^^^^^^^^^^^^^^^^^^^^^^^^^^^^^^^^^^^^^^^^^^^^^^^^^^^^^^^^^^^^^^^^^^^^^^^^^^^^^^^^^^^^
                 *args, **kwargs)
                 ^^^^^^^^^^^^^^^^
  File "/workspace/venv/lib/python3.13/site-packages/telebot/__init__.py", line 1195, in polling
    logger.info('Starting your bot with username: [@%s]', self.user.username)
                                                          ^^^^^^^^^
  File "/workspace/venv/lib/python3.13/site-packages/telebot/__init__.py", line 306, in user
    self._user = self.get_me()
                 ~~~~~~~~~~~^^
  File "/workspace/venv/lib/python3.13/site-packages/telebot/__init__.py", line 1382, in get_me
    apihelper.get_me(self.token)
    ~~~~~~~~~~~~~~~~^^^^^^^^^^^^
  File "/workspace/venv/lib/python3.13/site-packages/telebot/apihelper.py", line 202, in get_me
    return _make_request(token, method_url)
  File "/workspace/venv/lib/python3.13/site-packages/telebot/apihelper.py", line 168, in _make_request
    json_result = _check_result(method_name, result)
  File "/workspace/venv/lib/python3.13/site-packages/telebot/apihelper.py", line 195, in _check_result
    raise ApiTelegramException(method_name, result, result_json)
telebot.apihelper.ApiTelegramException: A request to the Telegram API was unsuccessful. Error code: 401. Description: Unauthorized

2025-08-14 16:06:43,242 - ERROR - Infinity polling exception: A request to the Telegram API was unsuccessful. Error code: 401. Description: Unauthorized
2025-08-14 16:06:43,242 - ERROR - Exception traceback:
Traceback (most recent call last):
  File "/workspace/venv/lib/python3.13/site-packages/telebot/__init__.py", line 1110, in infinity_polling
    self.polling(non_stop=True, timeout=timeout, long_polling_timeout=long_polling_timeout,
    ~~~~~~~~~~~~^^^^^^^^^^^^^^^^^^^^^^^^^^^^^^^^^^^^^^^^^^^^^^^^^^^^^^^^^^^^^^^^^^^^^^^^^^^
                 logger_level=logger_level, allowed_updates=allowed_updates, restart_on_change=False,
                 ^^^^^^^^^^^^^^^^^^^^^^^^^^^^^^^^^^^^^^^^^^^^^^^^^^^^^^^^^^^^^^^^^^^^^^^^^^^^^^^^^^^^
                 *args, **kwargs)
                 ^^^^^^^^^^^^^^^^
  File "/workspace/venv/lib/python3.13/site-packages/telebot/__init__.py", line 1195, in polling
    logger.info('Starting your bot with username: [@%s]', self.user.username)
                                                          ^^^^^^^^^
  File "/workspace/venv/lib/python3.13/site-packages/telebot/__init__.py", line 306, in user
    self._user = self.get_me()
                 ~~~~~~~~~~~^^
  File "/workspace/venv/lib/python3.13/site-packages/telebot/__init__.py", line 1382, in get_me
    apihelper.get_me(self.token)
    ~~~~~~~~~~~~~~~~^^^^^^^^^^^^
  File "/workspace/venv/lib/python3.13/site-packages/telebot/apihelper.py", line 202, in get_me
    return _make_request(token, method_url)
  File "/workspace/venv/lib/python3.13/site-packages/telebot/apihelper.py", line 168, in _make_request
    json_result = _check_result(method_name, result)
  File "/workspace/venv/lib/python3.13/site-packages/telebot/apihelper.py", line 195, in _check_result
    raise ApiTelegramException(method_name, result, result_json)
telebot.apihelper.ApiTelegramException: A request to the Telegram API was unsuccessful. Error code: 401. Description: Unauthorized

2025-08-14 16:06:46,329 - ERROR - Infinity polling exception: A request to the Telegram API was unsuccessful. Error code: 401. Description: Unauthorized
2025-08-14 16:06:46,330 - ERROR - Exception traceback:
Traceback (most recent call last):
  File "/workspace/venv/lib/python3.13/site-packages/telebot/__init__.py", line 1110, in infinity_polling
    self.polling(non_stop=True, timeout=timeout, long_polling_timeout=long_polling_timeout,
    ~~~~~~~~~~~~^^^^^^^^^^^^^^^^^^^^^^^^^^^^^^^^^^^^^^^^^^^^^^^^^^^^^^^^^^^^^^^^^^^^^^^^^^^
                 logger_level=logger_level, allowed_updates=allowed_updates, restart_on_change=False,
                 ^^^^^^^^^^^^^^^^^^^^^^^^^^^^^^^^^^^^^^^^^^^^^^^^^^^^^^^^^^^^^^^^^^^^^^^^^^^^^^^^^^^^
                 *args, **kwargs)
                 ^^^^^^^^^^^^^^^^
  File "/workspace/venv/lib/python3.13/site-packages/telebot/__init__.py", line 1195, in polling
    logger.info('Starting your bot with username: [@%s]', self.user.username)
                                                          ^^^^^^^^^
  File "/workspace/venv/lib/python3.13/site-packages/telebot/__init__.py", line 306, in user
    self._user = self.get_me()
                 ~~~~~~~~~~~^^
  File "/workspace/venv/lib/python3.13/site-packages/telebot/__init__.py", line 1382, in get_me
    apihelper.get_me(self.token)
    ~~~~~~~~~~~~~~~~^^^^^^^^^^^^
  File "/workspace/venv/lib/python3.13/site-packages/telebot/apihelper.py", line 202, in get_me
    return _make_request(token, method_url)
  File "/workspace/venv/lib/python3.13/site-packages/telebot/apihelper.py", line 168, in _make_request
    json_result = _check_result(method_name, result)
  File "/workspace/venv/lib/python3.13/site-packages/telebot/apihelper.py", line 195, in _check_result
    raise ApiTelegramException(method_name, result, result_json)
telebot.apihelper.ApiTelegramException: A request to the Telegram API was unsuccessful. Error code: 401. Description: Unauthorized

2025-08-14 16:06:49,416 - ERROR - Infinity polling exception: A request to the Telegram API was unsuccessful. Error code: 401. Description: Unauthorized
2025-08-14 16:06:49,416 - ERROR - Exception traceback:
Traceback (most recent call last):
  File "/workspace/venv/lib/python3.13/site-packages/telebot/__init__.py", line 1110, in infinity_polling
    self.polling(non_stop=True, timeout=timeout, long_polling_timeout=long_polling_timeout,
    ~~~~~~~~~~~~^^^^^^^^^^^^^^^^^^^^^^^^^^^^^^^^^^^^^^^^^^^^^^^^^^^^^^^^^^^^^^^^^^^^^^^^^^^
                 logger_level=logger_level, allowed_updates=allowed_updates, restart_on_change=False,
                 ^^^^^^^^^^^^^^^^^^^^^^^^^^^^^^^^^^^^^^^^^^^^^^^^^^^^^^^^^^^^^^^^^^^^^^^^^^^^^^^^^^^^
                 *args, **kwargs)
                 ^^^^^^^^^^^^^^^^
  File "/workspace/venv/lib/python3.13/site-packages/telebot/__init__.py", line 1195, in polling
    logger.info('Starting your bot with username: [@%s]', self.user.username)
                                                          ^^^^^^^^^
  File "/workspace/venv/lib/python3.13/site-packages/telebot/__init__.py", line 306, in user
    self._user = self.get_me()
                 ~~~~~~~~~~~^^
  File "/workspace/venv/lib/python3.13/site-packages/telebot/__init__.py", line 1382, in get_me
    apihelper.get_me(self.token)
    ~~~~~~~~~~~~~~~~^^^^^^^^^^^^
  File "/workspace/venv/lib/python3.13/site-packages/telebot/apihelper.py", line 202, in get_me
    return _make_request(token, method_url)
  File "/workspace/venv/lib/python3.13/site-packages/telebot/apihelper.py", line 168, in _make_request
    json_result = _check_result(method_name, result)
  File "/workspace/venv/lib/python3.13/site-packages/telebot/apihelper.py", line 195, in _check_result
    raise ApiTelegramException(method_name, result, result_json)
telebot.apihelper.ApiTelegramException: A request to the Telegram API was unsuccessful. Error code: 401. Description: Unauthorized

2025-08-14 16:06:52,502 - ERROR - Infinity polling exception: A request to the Telegram API was unsuccessful. Error code: 401. Description: Unauthorized
2025-08-14 16:06:52,502 - ERROR - Exception traceback:
Traceback (most recent call last):
  File "/workspace/venv/lib/python3.13/site-packages/telebot/__init__.py", line 1110, in infinity_polling
    self.polling(non_stop=True, timeout=timeout, long_polling_timeout=long_polling_timeout,
    ~~~~~~~~~~~~^^^^^^^^^^^^^^^^^^^^^^^^^^^^^^^^^^^^^^^^^^^^^^^^^^^^^^^^^^^^^^^^^^^^^^^^^^^
                 logger_level=logger_level, allowed_updates=allowed_updates, restart_on_change=False,
                 ^^^^^^^^^^^^^^^^^^^^^^^^^^^^^^^^^^^^^^^^^^^^^^^^^^^^^^^^^^^^^^^^^^^^^^^^^^^^^^^^^^^^
                 *args, **kwargs)
                 ^^^^^^^^^^^^^^^^
  File "/workspace/venv/lib/python3.13/site-packages/telebot/__init__.py", line 1195, in polling
    logger.info('Starting your bot with username: [@%s]', self.user.username)
                                                          ^^^^^^^^^
  File "/workspace/venv/lib/python3.13/site-packages/telebot/__init__.py", line 306, in user
    self._user = self.get_me()
                 ~~~~~~~~~~~^^
  File "/workspace/venv/lib/python3.13/site-packages/telebot/__init__.py", line 1382, in get_me
    apihelper.get_me(self.token)
    ~~~~~~~~~~~~~~~~^^^^^^^^^^^^
  File "/workspace/venv/lib/python3.13/site-packages/telebot/apihelper.py", line 202, in get_me
    return _make_request(token, method_url)
  File "/workspace/venv/lib/python3.13/site-packages/telebot/apihelper.py", line 168, in _make_request
    json_result = _check_result(method_name, result)
  File "/workspace/venv/lib/python3.13/site-packages/telebot/apihelper.py", line 195, in _check_result
    raise ApiTelegramException(method_name, result, result_json)
telebot.apihelper.ApiTelegramException: A request to the Telegram API was unsuccessful. Error code: 401. Description: Unauthorized

2025-08-14 16:06:55,590 - ERROR - Infinity polling exception: A request to the Telegram API was unsuccessful. Error code: 401. Description: Unauthorized
2025-08-14 16:06:55,591 - ERROR - Exception traceback:
Traceback (most recent call last):
  File "/workspace/venv/lib/python3.13/site-packages/telebot/__init__.py", line 1110, in infinity_polling
    self.polling(non_stop=True, timeout=timeout, long_polling_timeout=long_polling_timeout,
    ~~~~~~~~~~~~^^^^^^^^^^^^^^^^^^^^^^^^^^^^^^^^^^^^^^^^^^^^^^^^^^^^^^^^^^^^^^^^^^^^^^^^^^^
                 logger_level=logger_level, allowed_updates=allowed_updates, restart_on_change=False,
                 ^^^^^^^^^^^^^^^^^^^^^^^^^^^^^^^^^^^^^^^^^^^^^^^^^^^^^^^^^^^^^^^^^^^^^^^^^^^^^^^^^^^^
                 *args, **kwargs)
                 ^^^^^^^^^^^^^^^^
  File "/workspace/venv/lib/python3.13/site-packages/telebot/__init__.py", line 1195, in polling
    logger.info('Starting your bot with username: [@%s]', self.user.username)
                                                          ^^^^^^^^^
  File "/workspace/venv/lib/python3.13/site-packages/telebot/__init__.py", line 306, in user
    self._user = self.get_me()
                 ~~~~~~~~~~~^^
  File "/workspace/venv/lib/python3.13/site-packages/telebot/__init__.py", line 1382, in get_me
    apihelper.get_me(self.token)
    ~~~~~~~~~~~~~~~~^^^^^^^^^^^^
  File "/workspace/venv/lib/python3.13/site-packages/telebot/apihelper.py", line 202, in get_me
    return _make_request(token, method_url)
  File "/workspace/venv/lib/python3.13/site-packages/telebot/apihelper.py", line 168, in _make_request
    json_result = _check_result(method_name, result)
  File "/workspace/venv/lib/python3.13/site-packages/telebot/apihelper.py", line 195, in _check_result
    raise ApiTelegramException(method_name, result, result_json)
telebot.apihelper.ApiTelegramException: A request to the Telegram API was unsuccessful. Error code: 401. Description: Unauthorized

2025-08-14 16:06:58,676 - ERROR - Infinity polling exception: A request to the Telegram API was unsuccessful. Error code: 401. Description: Unauthorized
2025-08-14 16:06:58,677 - ERROR - Exception traceback:
Traceback (most recent call last):
  File "/workspace/venv/lib/python3.13/site-packages/telebot/__init__.py", line 1110, in infinity_polling
    self.polling(non_stop=True, timeout=timeout, long_polling_timeout=long_polling_timeout,
    ~~~~~~~~~~~~^^^^^^^^^^^^^^^^^^^^^^^^^^^^^^^^^^^^^^^^^^^^^^^^^^^^^^^^^^^^^^^^^^^^^^^^^^^
                 logger_level=logger_level, allowed_updates=allowed_updates, restart_on_change=False,
                 ^^^^^^^^^^^^^^^^^^^^^^^^^^^^^^^^^^^^^^^^^^^^^^^^^^^^^^^^^^^^^^^^^^^^^^^^^^^^^^^^^^^^
                 *args, **kwargs)
                 ^^^^^^^^^^^^^^^^
  File "/workspace/venv/lib/python3.13/site-packages/telebot/__init__.py", line 1195, in polling
    logger.info('Starting your bot with username: [@%s]', self.user.username)
                                                          ^^^^^^^^^
  File "/workspace/venv/lib/python3.13/site-packages/telebot/__init__.py", line 306, in user
    self._user = self.get_me()
                 ~~~~~~~~~~~^^
  File "/workspace/venv/lib/python3.13/site-packages/telebot/__init__.py", line 1382, in get_me
    apihelper.get_me(self.token)
    ~~~~~~~~~~~~~~~~^^^^^^^^^^^^
  File "/workspace/venv/lib/python3.13/site-packages/telebot/apihelper.py", line 202, in get_me
    return _make_request(token, method_url)
  File "/workspace/venv/lib/python3.13/site-packages/telebot/apihelper.py", line 168, in _make_request
    json_result = _check_result(method_name, result)
  File "/workspace/venv/lib/python3.13/site-packages/telebot/apihelper.py", line 195, in _check_result
    raise ApiTelegramException(method_name, result, result_json)
telebot.apihelper.ApiTelegramException: A request to the Telegram API was unsuccessful. Error code: 401. Description: Unauthorized

2025-08-14 16:07:01,762 - ERROR - Infinity polling exception: A request to the Telegram API was unsuccessful. Error code: 401. Description: Unauthorized
2025-08-14 16:07:01,763 - ERROR - Exception traceback:
Traceback (most recent call last):
  File "/workspace/venv/lib/python3.13/site-packages/telebot/__init__.py", line 1110, in infinity_polling
    self.polling(non_stop=True, timeout=timeout, long_polling_timeout=long_polling_timeout,
    ~~~~~~~~~~~~^^^^^^^^^^^^^^^^^^^^^^^^^^^^^^^^^^^^^^^^^^^^^^^^^^^^^^^^^^^^^^^^^^^^^^^^^^^
                 logger_level=logger_level, allowed_updates=allowed_updates, restart_on_change=False,
                 ^^^^^^^^^^^^^^^^^^^^^^^^^^^^^^^^^^^^^^^^^^^^^^^^^^^^^^^^^^^^^^^^^^^^^^^^^^^^^^^^^^^^
                 *args, **kwargs)
                 ^^^^^^^^^^^^^^^^
  File "/workspace/venv/lib/python3.13/site-packages/telebot/__init__.py", line 1195, in polling
    logger.info('Starting your bot with username: [@%s]', self.user.username)
                                                          ^^^^^^^^^
  File "/workspace/venv/lib/python3.13/site-packages/telebot/__init__.py", line 306, in user
    self._user = self.get_me()
                 ~~~~~~~~~~~^^
  File "/workspace/venv/lib/python3.13/site-packages/telebot/__init__.py", line 1382, in get_me
    apihelper.get_me(self.token)
    ~~~~~~~~~~~~~~~~^^^^^^^^^^^^
  File "/workspace/venv/lib/python3.13/site-packages/telebot/apihelper.py", line 202, in get_me
    return _make_request(token, method_url)
  File "/workspace/venv/lib/python3.13/site-packages/telebot/apihelper.py", line 168, in _make_request
    json_result = _check_result(method_name, result)
  File "/workspace/venv/lib/python3.13/site-packages/telebot/apihelper.py", line 195, in _check_result
    raise ApiTelegramException(method_name, result, result_json)
telebot.apihelper.ApiTelegramException: A request to the Telegram API was unsuccessful. Error code: 401. Description: Unauthorized

2025-08-14 16:07:04,849 - ERROR - Infinity polling exception: A request to the Telegram API was unsuccessful. Error code: 401. Description: Unauthorized
2025-08-14 16:07:04,850 - ERROR - Exception traceback:
Traceback (most recent call last):
  File "/workspace/venv/lib/python3.13/site-packages/telebot/__init__.py", line 1110, in infinity_polling
    self.polling(non_stop=True, timeout=timeout, long_polling_timeout=long_polling_timeout,
    ~~~~~~~~~~~~^^^^^^^^^^^^^^^^^^^^^^^^^^^^^^^^^^^^^^^^^^^^^^^^^^^^^^^^^^^^^^^^^^^^^^^^^^^
                 logger_level=logger_level, allowed_updates=allowed_updates, restart_on_change=False,
                 ^^^^^^^^^^^^^^^^^^^^^^^^^^^^^^^^^^^^^^^^^^^^^^^^^^^^^^^^^^^^^^^^^^^^^^^^^^^^^^^^^^^^
                 *args, **kwargs)
                 ^^^^^^^^^^^^^^^^
  File "/workspace/venv/lib/python3.13/site-packages/telebot/__init__.py", line 1195, in polling
    logger.info('Starting your bot with username: [@%s]', self.user.username)
                                                          ^^^^^^^^^
  File "/workspace/venv/lib/python3.13/site-packages/telebot/__init__.py", line 306, in user
    self._user = self.get_me()
                 ~~~~~~~~~~~^^
  File "/workspace/venv/lib/python3.13/site-packages/telebot/__init__.py", line 1382, in get_me
    apihelper.get_me(self.token)
    ~~~~~~~~~~~~~~~~^^^^^^^^^^^^
  File "/workspace/venv/lib/python3.13/site-packages/telebot/apihelper.py", line 202, in get_me
    return _make_request(token, method_url)
  File "/workspace/venv/lib/python3.13/site-packages/telebot/apihelper.py", line 168, in _make_request
    json_result = _check_result(method_name, result)
  File "/workspace/venv/lib/python3.13/site-packages/telebot/apihelper.py", line 195, in _check_result
    raise ApiTelegramException(method_name, result, result_json)
telebot.apihelper.ApiTelegramException: A request to the Telegram API was unsuccessful. Error code: 401. Description: Unauthorized

2025-08-14 16:07:07,935 - ERROR - Infinity polling exception: A request to the Telegram API was unsuccessful. Error code: 401. Description: Unauthorized
2025-08-14 16:07:07,936 - ERROR - Exception traceback:
Traceback (most recent call last):
  File "/workspace/venv/lib/python3.13/site-packages/telebot/__init__.py", line 1110, in infinity_polling
    self.polling(non_stop=True, timeout=timeout, long_polling_timeout=long_polling_timeout,
    ~~~~~~~~~~~~^^^^^^^^^^^^^^^^^^^^^^^^^^^^^^^^^^^^^^^^^^^^^^^^^^^^^^^^^^^^^^^^^^^^^^^^^^^
                 logger_level=logger_level, allowed_updates=allowed_updates, restart_on_change=False,
                 ^^^^^^^^^^^^^^^^^^^^^^^^^^^^^^^^^^^^^^^^^^^^^^^^^^^^^^^^^^^^^^^^^^^^^^^^^^^^^^^^^^^^
                 *args, **kwargs)
                 ^^^^^^^^^^^^^^^^
  File "/workspace/venv/lib/python3.13/site-packages/telebot/__init__.py", line 1195, in polling
    logger.info('Starting your bot with username: [@%s]', self.user.username)
                                                          ^^^^^^^^^
  File "/workspace/venv/lib/python3.13/site-packages/telebot/__init__.py", line 306, in user
    self._user = self.get_me()
                 ~~~~~~~~~~~^^
  File "/workspace/venv/lib/python3.13/site-packages/telebot/__init__.py", line 1382, in get_me
    apihelper.get_me(self.token)
    ~~~~~~~~~~~~~~~~^^^^^^^^^^^^
  File "/workspace/venv/lib/python3.13/site-packages/telebot/apihelper.py", line 202, in get_me
    return _make_request(token, method_url)
  File "/workspace/venv/lib/python3.13/site-packages/telebot/apihelper.py", line 168, in _make_request
    json_result = _check_result(method_name, result)
  File "/workspace/venv/lib/python3.13/site-packages/telebot/apihelper.py", line 195, in _check_result
    raise ApiTelegramException(method_name, result, result_json)
telebot.apihelper.ApiTelegramException: A request to the Telegram API was unsuccessful. Error code: 401. Description: Unauthorized

2025-08-14 16:07:11,022 - ERROR - Infinity polling exception: A request to the Telegram API was unsuccessful. Error code: 401. Description: Unauthorized
2025-08-14 16:07:11,023 - ERROR - Exception traceback:
Traceback (most recent call last):
  File "/workspace/venv/lib/python3.13/site-packages/telebot/__init__.py", line 1110, in infinity_polling
    self.polling(non_stop=True, timeout=timeout, long_polling_timeout=long_polling_timeout,
    ~~~~~~~~~~~~^^^^^^^^^^^^^^^^^^^^^^^^^^^^^^^^^^^^^^^^^^^^^^^^^^^^^^^^^^^^^^^^^^^^^^^^^^^
                 logger_level=logger_level, allowed_updates=allowed_updates, restart_on_change=False,
                 ^^^^^^^^^^^^^^^^^^^^^^^^^^^^^^^^^^^^^^^^^^^^^^^^^^^^^^^^^^^^^^^^^^^^^^^^^^^^^^^^^^^^
                 *args, **kwargs)
                 ^^^^^^^^^^^^^^^^
  File "/workspace/venv/lib/python3.13/site-packages/telebot/__init__.py", line 1195, in polling
    logger.info('Starting your bot with username: [@%s]', self.user.username)
                                                          ^^^^^^^^^
  File "/workspace/venv/lib/python3.13/site-packages/telebot/__init__.py", line 306, in user
    self._user = self.get_me()
                 ~~~~~~~~~~~^^
  File "/workspace/venv/lib/python3.13/site-packages/telebot/__init__.py", line 1382, in get_me
    apihelper.get_me(self.token)
    ~~~~~~~~~~~~~~~~^^^^^^^^^^^^
  File "/workspace/venv/lib/python3.13/site-packages/telebot/apihelper.py", line 202, in get_me
    return _make_request(token, method_url)
  File "/workspace/venv/lib/python3.13/site-packages/telebot/apihelper.py", line 168, in _make_request
    json_result = _check_result(method_name, result)
  File "/workspace/venv/lib/python3.13/site-packages/telebot/apihelper.py", line 195, in _check_result
    raise ApiTelegramException(method_name, result, result_json)
telebot.apihelper.ApiTelegramException: A request to the Telegram API was unsuccessful. Error code: 401. Description: Unauthorized

2025-08-14 16:07:14,109 - ERROR - Infinity polling exception: A request to the Telegram API was unsuccessful. Error code: 401. Description: Unauthorized
2025-08-14 16:07:14,109 - ERROR - Exception traceback:
Traceback (most recent call last):
  File "/workspace/venv/lib/python3.13/site-packages/telebot/__init__.py", line 1110, in infinity_polling
    self.polling(non_stop=True, timeout=timeout, long_polling_timeout=long_polling_timeout,
    ~~~~~~~~~~~~^^^^^^^^^^^^^^^^^^^^^^^^^^^^^^^^^^^^^^^^^^^^^^^^^^^^^^^^^^^^^^^^^^^^^^^^^^^
                 logger_level=logger_level, allowed_updates=allowed_updates, restart_on_change=False,
                 ^^^^^^^^^^^^^^^^^^^^^^^^^^^^^^^^^^^^^^^^^^^^^^^^^^^^^^^^^^^^^^^^^^^^^^^^^^^^^^^^^^^^
                 *args, **kwargs)
                 ^^^^^^^^^^^^^^^^
  File "/workspace/venv/lib/python3.13/site-packages/telebot/__init__.py", line 1195, in polling
    logger.info('Starting your bot with username: [@%s]', self.user.username)
                                                          ^^^^^^^^^
  File "/workspace/venv/lib/python3.13/site-packages/telebot/__init__.py", line 306, in user
    self._user = self.get_me()
                 ~~~~~~~~~~~^^
  File "/workspace/venv/lib/python3.13/site-packages/telebot/__init__.py", line 1382, in get_me
    apihelper.get_me(self.token)
    ~~~~~~~~~~~~~~~~^^^^^^^^^^^^
  File "/workspace/venv/lib/python3.13/site-packages/telebot/apihelper.py", line 202, in get_me
    return _make_request(token, method_url)
  File "/workspace/venv/lib/python3.13/site-packages/telebot/apihelper.py", line 168, in _make_request
    json_result = _check_result(method_name, result)
  File "/workspace/venv/lib/python3.13/site-packages/telebot/apihelper.py", line 195, in _check_result
    raise ApiTelegramException(method_name, result, result_json)
telebot.apihelper.ApiTelegramException: A request to the Telegram API was unsuccessful. Error code: 401. Description: Unauthorized

2025-08-14 16:07:17,196 - ERROR - Infinity polling exception: A request to the Telegram API was unsuccessful. Error code: 401. Description: Unauthorized
2025-08-14 16:07:17,196 - ERROR - Exception traceback:
Traceback (most recent call last):
  File "/workspace/venv/lib/python3.13/site-packages/telebot/__init__.py", line 1110, in infinity_polling
    self.polling(non_stop=True, timeout=timeout, long_polling_timeout=long_polling_timeout,
    ~~~~~~~~~~~~^^^^^^^^^^^^^^^^^^^^^^^^^^^^^^^^^^^^^^^^^^^^^^^^^^^^^^^^^^^^^^^^^^^^^^^^^^^
                 logger_level=logger_level, allowed_updates=allowed_updates, restart_on_change=False,
                 ^^^^^^^^^^^^^^^^^^^^^^^^^^^^^^^^^^^^^^^^^^^^^^^^^^^^^^^^^^^^^^^^^^^^^^^^^^^^^^^^^^^^
                 *args, **kwargs)
                 ^^^^^^^^^^^^^^^^
  File "/workspace/venv/lib/python3.13/site-packages/telebot/__init__.py", line 1195, in polling
    logger.info('Starting your bot with username: [@%s]', self.user.username)
                                                          ^^^^^^^^^
  File "/workspace/venv/lib/python3.13/site-packages/telebot/__init__.py", line 306, in user
    self._user = self.get_me()
                 ~~~~~~~~~~~^^
  File "/workspace/venv/lib/python3.13/site-packages/telebot/__init__.py", line 1382, in get_me
    apihelper.get_me(self.token)
    ~~~~~~~~~~~~~~~~^^^^^^^^^^^^
  File "/workspace/venv/lib/python3.13/site-packages/telebot/apihelper.py", line 202, in get_me
    return _make_request(token, method_url)
  File "/workspace/venv/lib/python3.13/site-packages/telebot/apihelper.py", line 168, in _make_request
    json_result = _check_result(method_name, result)
  File "/workspace/venv/lib/python3.13/site-packages/telebot/apihelper.py", line 195, in _check_result
    raise ApiTelegramException(method_name, result, result_json)
telebot.apihelper.ApiTelegramException: A request to the Telegram API was unsuccessful. Error code: 401. Description: Unauthorized

2025-08-14 16:07:20,282 - ERROR - Infinity polling exception: A request to the Telegram API was unsuccessful. Error code: 401. Description: Unauthorized
2025-08-14 16:07:20,283 - ERROR - Exception traceback:
Traceback (most recent call last):
  File "/workspace/venv/lib/python3.13/site-packages/telebot/__init__.py", line 1110, in infinity_polling
    self.polling(non_stop=True, timeout=timeout, long_polling_timeout=long_polling_timeout,
    ~~~~~~~~~~~~^^^^^^^^^^^^^^^^^^^^^^^^^^^^^^^^^^^^^^^^^^^^^^^^^^^^^^^^^^^^^^^^^^^^^^^^^^^
                 logger_level=logger_level, allowed_updates=allowed_updates, restart_on_change=False,
                 ^^^^^^^^^^^^^^^^^^^^^^^^^^^^^^^^^^^^^^^^^^^^^^^^^^^^^^^^^^^^^^^^^^^^^^^^^^^^^^^^^^^^
                 *args, **kwargs)
                 ^^^^^^^^^^^^^^^^
  File "/workspace/venv/lib/python3.13/site-packages/telebot/__init__.py", line 1195, in polling
    logger.info('Starting your bot with username: [@%s]', self.user.username)
                                                          ^^^^^^^^^
  File "/workspace/venv/lib/python3.13/site-packages/telebot/__init__.py", line 306, in user
    self._user = self.get_me()
                 ~~~~~~~~~~~^^
  File "/workspace/venv/lib/python3.13/site-packages/telebot/__init__.py", line 1382, in get_me
    apihelper.get_me(self.token)
    ~~~~~~~~~~~~~~~~^^^^^^^^^^^^
  File "/workspace/venv/lib/python3.13/site-packages/telebot/apihelper.py", line 202, in get_me
    return _make_request(token, method_url)
  File "/workspace/venv/lib/python3.13/site-packages/telebot/apihelper.py", line 168, in _make_request
    json_result = _check_result(method_name, result)
  File "/workspace/venv/lib/python3.13/site-packages/telebot/apihelper.py", line 195, in _check_result
    raise ApiTelegramException(method_name, result, result_json)
telebot.apihelper.ApiTelegramException: A request to the Telegram API was unsuccessful. Error code: 401. Description: Unauthorized

2025-08-14 16:07:23,370 - ERROR - Infinity polling exception: A request to the Telegram API was unsuccessful. Error code: 401. Description: Unauthorized
2025-08-14 16:07:23,371 - ERROR - Exception traceback:
Traceback (most recent call last):
  File "/workspace/venv/lib/python3.13/site-packages/telebot/__init__.py", line 1110, in infinity_polling
    self.polling(non_stop=True, timeout=timeout, long_polling_timeout=long_polling_timeout,
    ~~~~~~~~~~~~^^^^^^^^^^^^^^^^^^^^^^^^^^^^^^^^^^^^^^^^^^^^^^^^^^^^^^^^^^^^^^^^^^^^^^^^^^^
                 logger_level=logger_level, allowed_updates=allowed_updates, restart_on_change=False,
                 ^^^^^^^^^^^^^^^^^^^^^^^^^^^^^^^^^^^^^^^^^^^^^^^^^^^^^^^^^^^^^^^^^^^^^^^^^^^^^^^^^^^^
                 *args, **kwargs)
                 ^^^^^^^^^^^^^^^^
  File "/workspace/venv/lib/python3.13/site-packages/telebot/__init__.py", line 1195, in polling
    logger.info('Starting your bot with username: [@%s]', self.user.username)
                                                          ^^^^^^^^^
  File "/workspace/venv/lib/python3.13/site-packages/telebot/__init__.py", line 306, in user
    self._user = self.get_me()
                 ~~~~~~~~~~~^^
  File "/workspace/venv/lib/python3.13/site-packages/telebot/__init__.py", line 1382, in get_me
    apihelper.get_me(self.token)
    ~~~~~~~~~~~~~~~~^^^^^^^^^^^^
  File "/workspace/venv/lib/python3.13/site-packages/telebot/apihelper.py", line 202, in get_me
    return _make_request(token, method_url)
  File "/workspace/venv/lib/python3.13/site-packages/telebot/apihelper.py", line 168, in _make_request
    json_result = _check_result(method_name, result)
  File "/workspace/venv/lib/python3.13/site-packages/telebot/apihelper.py", line 195, in _check_result
    raise ApiTelegramException(method_name, result, result_json)
telebot.apihelper.ApiTelegramException: A request to the Telegram API was unsuccessful. Error code: 401. Description: Unauthorized

2025-08-14 16:07:26,457 - ERROR - Infinity polling exception: A request to the Telegram API was unsuccessful. Error code: 401. Description: Unauthorized
2025-08-14 16:07:26,457 - ERROR - Exception traceback:
Traceback (most recent call last):
  File "/workspace/venv/lib/python3.13/site-packages/telebot/__init__.py", line 1110, in infinity_polling
    self.polling(non_stop=True, timeout=timeout, long_polling_timeout=long_polling_timeout,
    ~~~~~~~~~~~~^^^^^^^^^^^^^^^^^^^^^^^^^^^^^^^^^^^^^^^^^^^^^^^^^^^^^^^^^^^^^^^^^^^^^^^^^^^
                 logger_level=logger_level, allowed_updates=allowed_updates, restart_on_change=False,
                 ^^^^^^^^^^^^^^^^^^^^^^^^^^^^^^^^^^^^^^^^^^^^^^^^^^^^^^^^^^^^^^^^^^^^^^^^^^^^^^^^^^^^
                 *args, **kwargs)
                 ^^^^^^^^^^^^^^^^
  File "/workspace/venv/lib/python3.13/site-packages/telebot/__init__.py", line 1195, in polling
    logger.info('Starting your bot with username: [@%s]', self.user.username)
                                                          ^^^^^^^^^
  File "/workspace/venv/lib/python3.13/site-packages/telebot/__init__.py", line 306, in user
    self._user = self.get_me()
                 ~~~~~~~~~~~^^
  File "/workspace/venv/lib/python3.13/site-packages/telebot/__init__.py", line 1382, in get_me
    apihelper.get_me(self.token)
    ~~~~~~~~~~~~~~~~^^^^^^^^^^^^
  File "/workspace/venv/lib/python3.13/site-packages/telebot/apihelper.py", line 202, in get_me
    return _make_request(token, method_url)
  File "/workspace/venv/lib/python3.13/site-packages/telebot/apihelper.py", line 168, in _make_request
    json_result = _check_result(method_name, result)
  File "/workspace/venv/lib/python3.13/site-packages/telebot/apihelper.py", line 195, in _check_result
    raise ApiTelegramException(method_name, result, result_json)
telebot.apihelper.ApiTelegramException: A request to the Telegram API was unsuccessful. Error code: 401. Description: Unauthorized

2025-08-14 16:07:29,543 - ERROR - Infinity polling exception: A request to the Telegram API was unsuccessful. Error code: 401. Description: Unauthorized
2025-08-14 16:07:29,544 - ERROR - Exception traceback:
Traceback (most recent call last):
  File "/workspace/venv/lib/python3.13/site-packages/telebot/__init__.py", line 1110, in infinity_polling
    self.polling(non_stop=True, timeout=timeout, long_polling_timeout=long_polling_timeout,
    ~~~~~~~~~~~~^^^^^^^^^^^^^^^^^^^^^^^^^^^^^^^^^^^^^^^^^^^^^^^^^^^^^^^^^^^^^^^^^^^^^^^^^^^
                 logger_level=logger_level, allowed_updates=allowed_updates, restart_on_change=False,
                 ^^^^^^^^^^^^^^^^^^^^^^^^^^^^^^^^^^^^^^^^^^^^^^^^^^^^^^^^^^^^^^^^^^^^^^^^^^^^^^^^^^^^
                 *args, **kwargs)
                 ^^^^^^^^^^^^^^^^
  File "/workspace/venv/lib/python3.13/site-packages/telebot/__init__.py", line 1195, in polling
    logger.info('Starting your bot with username: [@%s]', self.user.username)
                                                          ^^^^^^^^^
  File "/workspace/venv/lib/python3.13/site-packages/telebot/__init__.py", line 306, in user
    self._user = self.get_me()
                 ~~~~~~~~~~~^^
  File "/workspace/venv/lib/python3.13/site-packages/telebot/__init__.py", line 1382, in get_me
    apihelper.get_me(self.token)
    ~~~~~~~~~~~~~~~~^^^^^^^^^^^^
  File "/workspace/venv/lib/python3.13/site-packages/telebot/apihelper.py", line 202, in get_me
    return _make_request(token, method_url)
  File "/workspace/venv/lib/python3.13/site-packages/telebot/apihelper.py", line 168, in _make_request
    json_result = _check_result(method_name, result)
  File "/workspace/venv/lib/python3.13/site-packages/telebot/apihelper.py", line 195, in _check_result
    raise ApiTelegramException(method_name, result, result_json)
telebot.apihelper.ApiTelegramException: A request to the Telegram API was unsuccessful. Error code: 401. Description: Unauthorized

2025-08-14 16:07:32,630 - ERROR - Infinity polling exception: A request to the Telegram API was unsuccessful. Error code: 401. Description: Unauthorized
2025-08-14 16:07:32,630 - ERROR - Exception traceback:
Traceback (most recent call last):
  File "/workspace/venv/lib/python3.13/site-packages/telebot/__init__.py", line 1110, in infinity_polling
    self.polling(non_stop=True, timeout=timeout, long_polling_timeout=long_polling_timeout,
    ~~~~~~~~~~~~^^^^^^^^^^^^^^^^^^^^^^^^^^^^^^^^^^^^^^^^^^^^^^^^^^^^^^^^^^^^^^^^^^^^^^^^^^^
                 logger_level=logger_level, allowed_updates=allowed_updates, restart_on_change=False,
                 ^^^^^^^^^^^^^^^^^^^^^^^^^^^^^^^^^^^^^^^^^^^^^^^^^^^^^^^^^^^^^^^^^^^^^^^^^^^^^^^^^^^^
                 *args, **kwargs)
                 ^^^^^^^^^^^^^^^^
  File "/workspace/venv/lib/python3.13/site-packages/telebot/__init__.py", line 1195, in polling
    logger.info('Starting your bot with username: [@%s]', self.user.username)
                                                          ^^^^^^^^^
  File "/workspace/venv/lib/python3.13/site-packages/telebot/__init__.py", line 306, in user
    self._user = self.get_me()
                 ~~~~~~~~~~~^^
  File "/workspace/venv/lib/python3.13/site-packages/telebot/__init__.py", line 1382, in get_me
    apihelper.get_me(self.token)
    ~~~~~~~~~~~~~~~~^^^^^^^^^^^^
  File "/workspace/venv/lib/python3.13/site-packages/telebot/apihelper.py", line 202, in get_me
    return _make_request(token, method_url)
  File "/workspace/venv/lib/python3.13/site-packages/telebot/apihelper.py", line 168, in _make_request
    json_result = _check_result(method_name, result)
  File "/workspace/venv/lib/python3.13/site-packages/telebot/apihelper.py", line 195, in _check_result
    raise ApiTelegramException(method_name, result, result_json)
telebot.apihelper.ApiTelegramException: A request to the Telegram API was unsuccessful. Error code: 401. Description: Unauthorized

2025-08-14 16:07:35,716 - ERROR - Infinity polling exception: A request to the Telegram API was unsuccessful. Error code: 401. Description: Unauthorized
2025-08-14 16:07:35,716 - ERROR - Exception traceback:
Traceback (most recent call last):
  File "/workspace/venv/lib/python3.13/site-packages/telebot/__init__.py", line 1110, in infinity_polling
    self.polling(non_stop=True, timeout=timeout, long_polling_timeout=long_polling_timeout,
    ~~~~~~~~~~~~^^^^^^^^^^^^^^^^^^^^^^^^^^^^^^^^^^^^^^^^^^^^^^^^^^^^^^^^^^^^^^^^^^^^^^^^^^^
                 logger_level=logger_level, allowed_updates=allowed_updates, restart_on_change=False,
                 ^^^^^^^^^^^^^^^^^^^^^^^^^^^^^^^^^^^^^^^^^^^^^^^^^^^^^^^^^^^^^^^^^^^^^^^^^^^^^^^^^^^^
                 *args, **kwargs)
                 ^^^^^^^^^^^^^^^^
  File "/workspace/venv/lib/python3.13/site-packages/telebot/__init__.py", line 1195, in polling
    logger.info('Starting your bot with username: [@%s]', self.user.username)
                                                          ^^^^^^^^^
  File "/workspace/venv/lib/python3.13/site-packages/telebot/__init__.py", line 306, in user
    self._user = self.get_me()
                 ~~~~~~~~~~~^^
  File "/workspace/venv/lib/python3.13/site-packages/telebot/__init__.py", line 1382, in get_me
    apihelper.get_me(self.token)
    ~~~~~~~~~~~~~~~~^^^^^^^^^^^^
  File "/workspace/venv/lib/python3.13/site-packages/telebot/apihelper.py", line 202, in get_me
    return _make_request(token, method_url)
  File "/workspace/venv/lib/python3.13/site-packages/telebot/apihelper.py", line 168, in _make_request
    json_result = _check_result(method_name, result)
  File "/workspace/venv/lib/python3.13/site-packages/telebot/apihelper.py", line 195, in _check_result
    raise ApiTelegramException(method_name, result, result_json)
telebot.apihelper.ApiTelegramException: A request to the Telegram API was unsuccessful. Error code: 401. Description: Unauthorized

2025-08-14 16:07:38,812 - ERROR - Infinity polling exception: A request to the Telegram API was unsuccessful. Error code: 401. Description: Unauthorized
2025-08-14 16:07:38,813 - ERROR - Exception traceback:
Traceback (most recent call last):
  File "/workspace/venv/lib/python3.13/site-packages/telebot/__init__.py", line 1110, in infinity_polling
    self.polling(non_stop=True, timeout=timeout, long_polling_timeout=long_polling_timeout,
    ~~~~~~~~~~~~^^^^^^^^^^^^^^^^^^^^^^^^^^^^^^^^^^^^^^^^^^^^^^^^^^^^^^^^^^^^^^^^^^^^^^^^^^^
                 logger_level=logger_level, allowed_updates=allowed_updates, restart_on_change=False,
                 ^^^^^^^^^^^^^^^^^^^^^^^^^^^^^^^^^^^^^^^^^^^^^^^^^^^^^^^^^^^^^^^^^^^^^^^^^^^^^^^^^^^^
                 *args, **kwargs)
                 ^^^^^^^^^^^^^^^^
  File "/workspace/venv/lib/python3.13/site-packages/telebot/__init__.py", line 1195, in polling
    logger.info('Starting your bot with username: [@%s]', self.user.username)
                                                          ^^^^^^^^^
  File "/workspace/venv/lib/python3.13/site-packages/telebot/__init__.py", line 306, in user
    self._user = self.get_me()
                 ~~~~~~~~~~~^^
  File "/workspace/venv/lib/python3.13/site-packages/telebot/__init__.py", line 1382, in get_me
    apihelper.get_me(self.token)
    ~~~~~~~~~~~~~~~~^^^^^^^^^^^^
  File "/workspace/venv/lib/python3.13/site-packages/telebot/apihelper.py", line 202, in get_me
    return _make_request(token, method_url)
  File "/workspace/venv/lib/python3.13/site-packages/telebot/apihelper.py", line 168, in _make_request
    json_result = _check_result(method_name, result)
  File "/workspace/venv/lib/python3.13/site-packages/telebot/apihelper.py", line 195, in _check_result
    raise ApiTelegramException(method_name, result, result_json)
telebot.apihelper.ApiTelegramException: A request to the Telegram API was unsuccessful. Error code: 401. Description: Unauthorized

2025-08-14 16:07:41,899 - ERROR - Infinity polling exception: A request to the Telegram API was unsuccessful. Error code: 401. Description: Unauthorized
2025-08-14 16:07:41,899 - ERROR - Exception traceback:
Traceback (most recent call last):
  File "/workspace/venv/lib/python3.13/site-packages/telebot/__init__.py", line 1110, in infinity_polling
    self.polling(non_stop=True, timeout=timeout, long_polling_timeout=long_polling_timeout,
    ~~~~~~~~~~~~^^^^^^^^^^^^^^^^^^^^^^^^^^^^^^^^^^^^^^^^^^^^^^^^^^^^^^^^^^^^^^^^^^^^^^^^^^^
                 logger_level=logger_level, allowed_updates=allowed_updates, restart_on_change=False,
                 ^^^^^^^^^^^^^^^^^^^^^^^^^^^^^^^^^^^^^^^^^^^^^^^^^^^^^^^^^^^^^^^^^^^^^^^^^^^^^^^^^^^^
                 *args, **kwargs)
                 ^^^^^^^^^^^^^^^^
  File "/workspace/venv/lib/python3.13/site-packages/telebot/__init__.py", line 1195, in polling
    logger.info('Starting your bot with username: [@%s]', self.user.username)
                                                          ^^^^^^^^^
  File "/workspace/venv/lib/python3.13/site-packages/telebot/__init__.py", line 306, in user
    self._user = self.get_me()
                 ~~~~~~~~~~~^^
  File "/workspace/venv/lib/python3.13/site-packages/telebot/__init__.py", line 1382, in get_me
    apihelper.get_me(self.token)
    ~~~~~~~~~~~~~~~~^^^^^^^^^^^^
  File "/workspace/venv/lib/python3.13/site-packages/telebot/apihelper.py", line 202, in get_me
    return _make_request(token, method_url)
  File "/workspace/venv/lib/python3.13/site-packages/telebot/apihelper.py", line 168, in _make_request
    json_result = _check_result(method_name, result)
  File "/workspace/venv/lib/python3.13/site-packages/telebot/apihelper.py", line 195, in _check_result
    raise ApiTelegramException(method_name, result, result_json)
telebot.apihelper.ApiTelegramException: A request to the Telegram API was unsuccessful. Error code: 401. Description: Unauthorized

2025-08-14 16:07:44,986 - ERROR - Infinity polling exception: A request to the Telegram API was unsuccessful. Error code: 401. Description: Unauthorized
2025-08-14 16:07:44,987 - ERROR - Exception traceback:
Traceback (most recent call last):
  File "/workspace/venv/lib/python3.13/site-packages/telebot/__init__.py", line 1110, in infinity_polling
    self.polling(non_stop=True, timeout=timeout, long_polling_timeout=long_polling_timeout,
    ~~~~~~~~~~~~^^^^^^^^^^^^^^^^^^^^^^^^^^^^^^^^^^^^^^^^^^^^^^^^^^^^^^^^^^^^^^^^^^^^^^^^^^^
                 logger_level=logger_level, allowed_updates=allowed_updates, restart_on_change=False,
                 ^^^^^^^^^^^^^^^^^^^^^^^^^^^^^^^^^^^^^^^^^^^^^^^^^^^^^^^^^^^^^^^^^^^^^^^^^^^^^^^^^^^^
                 *args, **kwargs)
                 ^^^^^^^^^^^^^^^^
  File "/workspace/venv/lib/python3.13/site-packages/telebot/__init__.py", line 1195, in polling
    logger.info('Starting your bot with username: [@%s]', self.user.username)
                                                          ^^^^^^^^^
  File "/workspace/venv/lib/python3.13/site-packages/telebot/__init__.py", line 306, in user
    self._user = self.get_me()
                 ~~~~~~~~~~~^^
  File "/workspace/venv/lib/python3.13/site-packages/telebot/__init__.py", line 1382, in get_me
    apihelper.get_me(self.token)
    ~~~~~~~~~~~~~~~~^^^^^^^^^^^^
  File "/workspace/venv/lib/python3.13/site-packages/telebot/apihelper.py", line 202, in get_me
    return _make_request(token, method_url)
  File "/workspace/venv/lib/python3.13/site-packages/telebot/apihelper.py", line 168, in _make_request
    json_result = _check_result(method_name, result)
  File "/workspace/venv/lib/python3.13/site-packages/telebot/apihelper.py", line 195, in _check_result
    raise ApiTelegramException(method_name, result, result_json)
telebot.apihelper.ApiTelegramException: A request to the Telegram API was unsuccessful. Error code: 401. Description: Unauthorized

2025-08-14 16:07:48,074 - ERROR - Infinity polling exception: A request to the Telegram API was unsuccessful. Error code: 401. Description: Unauthorized
2025-08-14 16:07:48,075 - ERROR - Exception traceback:
Traceback (most recent call last):
  File "/workspace/venv/lib/python3.13/site-packages/telebot/__init__.py", line 1110, in infinity_polling
    self.polling(non_stop=True, timeout=timeout, long_polling_timeout=long_polling_timeout,
    ~~~~~~~~~~~~^^^^^^^^^^^^^^^^^^^^^^^^^^^^^^^^^^^^^^^^^^^^^^^^^^^^^^^^^^^^^^^^^^^^^^^^^^^
                 logger_level=logger_level, allowed_updates=allowed_updates, restart_on_change=False,
                 ^^^^^^^^^^^^^^^^^^^^^^^^^^^^^^^^^^^^^^^^^^^^^^^^^^^^^^^^^^^^^^^^^^^^^^^^^^^^^^^^^^^^
                 *args, **kwargs)
                 ^^^^^^^^^^^^^^^^
  File "/workspace/venv/lib/python3.13/site-packages/telebot/__init__.py", line 1195, in polling
    logger.info('Starting your bot with username: [@%s]', self.user.username)
                                                          ^^^^^^^^^
  File "/workspace/venv/lib/python3.13/site-packages/telebot/__init__.py", line 306, in user
    self._user = self.get_me()
                 ~~~~~~~~~~~^^
  File "/workspace/venv/lib/python3.13/site-packages/telebot/__init__.py", line 1382, in get_me
    apihelper.get_me(self.token)
    ~~~~~~~~~~~~~~~~^^^^^^^^^^^^
  File "/workspace/venv/lib/python3.13/site-packages/telebot/apihelper.py", line 202, in get_me
    return _make_request(token, method_url)
  File "/workspace/venv/lib/python3.13/site-packages/telebot/apihelper.py", line 168, in _make_request
    json_result = _check_result(method_name, result)
  File "/workspace/venv/lib/python3.13/site-packages/telebot/apihelper.py", line 195, in _check_result
    raise ApiTelegramException(method_name, result, result_json)
telebot.apihelper.ApiTelegramException: A request to the Telegram API was unsuccessful. Error code: 401. Description: Unauthorized

